<?xml version="1.0" encoding="utf-8"?>
<!-- This URDF was automatically created by SolidWorks to URDF Exporter! Originally created by Stephen Brawner (brawner@gmail.com) 
     Commit Version: 1.6.0-4-g7f85cfe  Build Version: 1.6.7995.38578
     For more information, please see http://wiki.ros.org/sw_urdf_exporter -->
<robot
  name="tripod3">
  <link
    name="base_link">
    <inertial>
      <origin
        xyz="-0.0027033521648196 0.0187131450927378 0.0427484175864133"
        rpy="0 0 0" />
      <mass
        value="4.94527215790382" />
      <inertia
        ixx="0.0216096734231236"
        ixy="1.89142009869065E-13"
        ixz="-3.17234256778446E-07"
        iyy="0.0216096734261006"
        iyz="-1.98329143923526E-17"
        izz="0.0356919850335974" />
    </inertial>
    <visual>
      <origin
        xyz="0 0 0"
        rpy="0 0 0" />
      <geometry>
        <mesh
          filename="package://tripod3/meshes/base_link.STL" />
      </geometry>
      <material
        name="">
        <color
          rgba="0.898039215686275 0.917647058823529 0.929411764705882 1" />
      </material>
    </visual>
    <collision>
      <origin
        xyz="0 0 0"
        rpy="0 0 0" />
      <geometry>
        <mesh
          filename="package://tripod3/meshes/base_link.STL" />
      </geometry>
    </collision>
  </link>
  <link
    name="sec01">
    <inertial>
      <origin
        xyz="-0.099146 -0.066135 -0.078805"
        rpy="0 0 0" />
      <mass
        value="2.7579" />
      <inertia
        ixx="0.014828"
        ixy="-2.6613E-06"
        ixz="7.2037E-06"
        iyy="0.0080221"
        iyz="-0.0050006"
        izz="0.0071497" />
    </inertial>
    <visual>
      <origin
        xyz="0 0 0"
        rpy="0 0 0" />
      <geometry>
        <mesh
          filename="package://tripod3/meshes/sec01.STL" />
      </geometry>
      <material
        name="">
        <color
          rgba="0.79216 0.81961 0.93333 1" />
      </material>
    </visual>
    <collision>
      <origin
        xyz="0 0 0"
        rpy="0 0 0" />
      <geometry>
        <mesh
          filename="package://tripod3/meshes/sec01.STL" />
      </geometry>
    </collision>
  </link>
  <joint
    name="joint01"
    type="revolute">
    <origin
      xyz="0.098298 -0.27841 0.029643"
      rpy="0 0 0" />
    <parent
      link="base_link" />
    <child
      link="sec01" />
    <axis
      xyz="-1 0 0" />
    <limit
      lower="-1.571"
      upper="1.571"
      effort="100"
      velocity="100" />
  </joint>
  <link
    name="sec02">
    <inertial>
      <origin
        xyz="-0.099146 -0.066135 -0.078805"
        rpy="0 0 0" />
      <mass
        value="2.7579" />
      <inertia
        ixx="0.014828"
        ixy="-2.6613E-06"
        ixz="7.2037E-06"
        iyy="0.0080221"
        iyz="-0.0050006"
        izz="0.0071497" />
    </inertial>
    <visual>
      <origin
        xyz="0 0 0"
        rpy="0 0 0" />
      <geometry>
        <mesh
          filename="package://tripod3/meshes/sec02.STL" />
      </geometry>
      <material
        name="">
        <color
          rgba="0.79216 0.81961 0.93333 1" />
      </material>
    </visual>
    <collision>
      <origin
        xyz="0 0 0"
        rpy="0 0 0" />
      <geometry>
        <mesh
          filename="package://tripod3/meshes/sec02.STL" />
      </geometry>
    </collision>
  </link>
  <joint
    name="joint02"
    type="revolute">
    <origin
      xyz="0.20411 0.25474 0.029643"
      rpy="0 0 2.0944" />
    <parent
      link="base_link" />
    <child
      link="sec02" />
    <axis
      xyz="-1 0 0" />
    <limit
      lower="-1.571"
      upper="1.571"
      effort="100"
      velocity="100" />
  </joint>
  <link
    name="sec03">
    <inertial>
      <origin
        xyz="-0.09912 -0.066106 -0.078761"
        rpy="0 0 0" />
      <mass
        value="2.7549" />
      <inertia
        ixx="0.014828"
        ixy="-2.6613E-06"
        ixz="7.2037E-06"
        iyy="0.008022"
        iyz="-0.0050006"
        izz="0.0071496" />
    </inertial>
    <visual>
      <origin
        xyz="0 0 0"
        rpy="0 0 0" />
      <geometry>
        <mesh
          filename="package://tripod3/meshes/sec03.STL" />
      </geometry>
      <material
        name="">
        <color
          rgba="0.79216 0.81961 0.93333 1" />
      </material>
    </visual>
    <collision>
      <origin
        xyz="0 0 0"
        rpy="0 0 0" />
      <geometry>
        <mesh
          filename="package://tripod3/meshes/sec03.STL" />
      </geometry>
    </collision>
  </link>
  <joint
    name="joint03"
    type="revolute">
    <origin
      xyz="-0.31052 0.079806 0.029643"
      rpy="0 0 -2.0944" />
    <parent
      link="base_link" />
    <child
      link="sec03" />
    <axis
      xyz="-1 0 0" />
    <limit
      lower="-1.571"
      upper="1.571"
      effort="100"
      velocity="100" />
  </joint>
</robot>