<?xml version="1.0" encoding="utf-8"?>
<!-- This URDF was automatically created by SolidWorks to URDF Exporter! Originally created by Stephen Brawner (brawner@gmail.com) 
     Commit Version: 1.6.0-4-g7f85cfe  Build Version: 1.6.7995.38578
     For more information, please see http://wiki.ros.org/sw_urdf_exporter -->
<robot
  name="tripod8">
  <link
    name="base_link">
    <inertial>
      <origin
        xyz="-0.0031291 0.020397 0.025785"
        rpy="0 0 0" />
      <mass
        value="11.372" />
      <inertia
        ixx="0.040607"
        ixy="0.010264"
        ixz="-4.0858E-07"
        iyy="0.052892"
        iyz="-5.2154E-08"
        izz="0.071045" />
    </inertial>
    <visual>
      <origin
        xyz="0 0 0"
        rpy="0 0 0" />
      <geometry>
        <mesh
          filename="package://tripod8/meshes/base_link.STL" />
      </geometry>
      <material
        name="">
        <color
          rgba="0.89804 0.91765 0.92941 1" />
      </material>
    </visual>
    <collision>
      <origin
        xyz="0 0 0"
        rpy="0 0 0" />
      <geometry>
        <mesh
          filename="package://tripod8/meshes/base_link.STL" />
      </geometry>
    </collision>
  </link>
  <link
    name="sec01">
    <inertial>
      <origin
        xyz="0.00048653 0.015913 -3.1489E-05"
        rpy="0 0 0" />
      <mass
        value="0.69712" />
      <inertia
        ixx="0.0011428"
        ixy="-9.0045E-05"
        ixz="-4.1383E-07"
        iyy="0.0011939"
        iyz="-4.927E-19"
        izz="0.00095487" />
    </inertial>
    <visual>
      <origin
        xyz="0 0 0"
        rpy="0 0 0" />
      <geometry>
        <mesh
          filename="package://tripod8/meshes/sec01.STL" />
      </geometry>
      <material
        name="">
        <color
          rgba="0.79216 0.81961 0.93333 1" />
      </material>
    </visual>
    <collision>
      <origin
        xyz="0 0 0"
        rpy="0 0 0" />
      <geometry>
        <mesh
          filename="package://tripod8/meshes/sec01.STL" />
      </geometry>
    </collision>
  </link>
  <joint
    name="leg01"
    type="revolute">
    <origin
      xyz="-0.0027021 -0.19892 0.029643"
      rpy="0 0 -1.5708" />
    <parent
      link="base_link" />
    <child
      link="sec01" />
    <axis
      xyz="1 0 0" />
    <limit
      lower="-1.571"
      upper="1.571"
      effort="10000"
      velocity="10000" />
  </joint>
  <link
    name="hsec01">
    <inertial>
      <origin
        xyz="-0.085802207284442 -0.0586652892981549 -0.00128195126910838"
        rpy="0 0 0" />
      <mass
        value="2.59385289729097" />
      <inertia
        ixx="0.0132813286063691"
        ixy="2.30713341803901E-07"
        ixz="7.37838868928084E-06"
        iyy="0.00186263080107763"
        iyz="1.88984474958546E-06"
        izz="0.0117381218254458" />
    </inertial>
    <visual>
      <origin
        xyz="0 0 0"
        rpy="0 0 0" />
      <geometry>
        <mesh
          filename="package://tripod8/meshes/hsec01.STL" />
      </geometry>
      <material
        name="">
        <color
          rgba="0.792156862745098 0.819607843137255 0.933333333333333 1" />
      </material>
    </visual>
    <collision>
      <origin
        xyz="0 0 0"
        rpy="0 0 0" />
      <geometry>
        <mesh
          filename="package://tripod8/meshes/hsec01.STL" />
      </geometry>
    </collision>
  </link>
  <joint
    name="high01"
    type="revolute">
    <origin
      xyz="0.078806 0.0895 0"
      rpy="0 0 1.5708" />
    <parent
      link="sec01" />
    <child
      link="hsec01" />
    <axis
      xyz="-1 0 0" />
    <limit
      lower="-1.571"
      upper="1.571"
      effort="10000"
      velocity="10000" />
  </joint>
  <link
    name="lsec01">
    <inertial>
      <origin
        xyz="-0.00741155948002789 -0.0534070820824173 -2.19114356152239E-07"
        rpy="0 0 0" />
      <mass
        value="0.292019066527945" />
      <inertia
        ixx="0.000681104991544854"
        ixy="3.0350485896022E-10"
        ixz="-6.21574685994639E-10"
        iyy="8.62621908768422E-05"
        iyz="-1.16761217824152E-09"
        izz="0.000615710465634299" />
    </inertial>
    <visual>
      <origin
        xyz="0 0 0"
        rpy="0 0 0" />
      <geometry>
        <mesh
          filename="package://tripod8/meshes/lsec01.STL" />
      </geometry>
      <material
        name="">
        <color
          rgba="0.792156862745098 0.819607843137255 0.933333333333333 1" />
      </material>
    </visual>
    <collision>
      <origin
        xyz="0 0 0"
        rpy="0 0 0" />
      <geometry>
        <mesh
          filename="package://tripod8/meshes/lsec01.STL" />
      </geometry>
    </collision>
  </link>
  <joint
    name="low01"
    type="revolute">
    <origin
      xyz="-0.10655 -0.26964 -0.0021"
      rpy="0 0 0" />
    <parent
      link="hsec01" />
    <child
      link="lsec01" />
    <axis
      xyz="-1 0 0" />
    <limit
      lower="-1.571"
      upper="1.571"
      effort="10000"
      velocity="10000" />
  </joint>
  <link
    name="sec02">
    <inertial>
      <origin
        xyz="0.00048653095865675 0.0159126224363777 -3.14892804915562E-05"
        rpy="0 0 0" />
      <mass
        value="0.697122142025587" />
      <inertia
        ixx="0.00114281706366662"
        ixy="-9.00446160794231E-05"
        ixz="-4.13827473961487E-07"
        iyy="0.00119389494778556"
        iyz="-6.26913266013083E-19"
        izz="0.000954871408355487" />
    </inertial>
    <visual>
      <origin
        xyz="0 0 0"
        rpy="0 0 0" />
      <geometry>
        <mesh
          filename="package://tripod8/meshes/sec02.STL" />
      </geometry>
      <material
        name="">
        <color
          rgba="0.792156862745098 0.819607843137255 0.933333333333333 1" />
      </material>
    </visual>
    <collision>
      <origin
        xyz="0 0 0"
        rpy="0 0 0" />
      <geometry>
        <mesh
          filename="package://tripod8/meshes/sec02.STL" />
      </geometry>
    </collision>
  </link>
  <joint
    name="leg02"
    type="revolute">
    <origin
      xyz="0.18577 0.12753 0.029643"
      rpy="0 0 0.5236" />
    <parent
      link="base_link" />
    <child
      link="sec02" />
    <axis
      xyz="1 0 0" />
    <limit
      lower="-1.571"
      upper="1.571"
      effort="10000"
      velocity="10000" />
  </joint>
  <link
    name="hsec02">
    <inertial>
      <origin
        xyz="-0.0936880803892596 0.0449324326469038 -0.00132320363478538"
        rpy="0 0 0" />
      <mass
        value="2.58967801426391" />
      <inertia
        ixx="0.00471738722941004"
        ixy="-0.00494456996283436"
        ixz="5.32584938980878E-06"
        iyy="0.0104263520174632"
        iyz="-5.44494872557975E-06"
        izz="0.0117379962530972" />
    </inertial>
    <visual>
      <origin
        xyz="0 0 0"
        rpy="0 0 0" />
      <geometry>
        <mesh
          filename="package://tripod8/meshes/hsec02.STL" />
      </geometry>
      <material
        name="">
        <color
          rgba="0.792156862745098 0.819607843137255 0.933333333333333 1" />
      </material>
    </visual>
    <collision>
      <origin
        xyz="0 0 0"
        rpy="0 0 0" />
      <geometry>
        <mesh
          filename="package://tripod8/meshes/hsec02.STL" />
      </geometry>
    </collision>
  </link>
  <joint
    name="high02"
    type="revolute">
    <origin
      xyz="0.078806 0.0895 0"
      rpy="0 0 2.618" />
    <parent
      link="sec02" />
    <child
      link="hsec02" />
    <axis
      xyz="-0.5 0.86603 0" />
    <limit
      lower="-1.571"
      upper="1.571"
      effort="10000"
      velocity="10000" />
  </joint>
  <link
    name="lsec02">
    <inertial>
      <origin
        xyz="-0.0499576697652945 -0.0202849427339908 -2.19055842926724E-07"
        rpy="0 0 0" />
      <mass
        value="0.292019079957839" />
      <inertia
        ixx="0.000234972541236232"
        ixy="-0.000257573690181133"
        ixz="-1.32698808812887E-09"
        iyy="0.000532392318918857"
        iyz="-3.6971385606356E-11"
        izz="0.000615708168370943" />
    </inertial>
    <visual>
      <origin
        xyz="0 0 0"
        rpy="0 0 0" />
      <geometry>
        <mesh
          filename="package://tripod8/meshes/lsec02.STL" />
      </geometry>
      <material
        name="">
        <color
          rgba="0.792156862745098 0.819607843137255 0.933333333333333 1" />
      </material>
    </visual>
    <collision>
      <origin
        xyz="0 0 0"
        rpy="0 0 0" />
      <geometry>
        <mesh
          filename="package://tripod8/meshes/lsec02.STL" />
      </geometry>
    </collision>
  </link>
  <joint
    name="low02"
    type="revolute">
    <origin
      xyz="-0.28679 -0.042547 -0.0021"
      rpy="0 0 0" />
    <parent
      link="hsec02" />
    <child
      link="lsec02" />
    <axis
      xyz="-0.5 0.86603 0" />
    <limit
      lower="-1.571"
      upper="1.571"
      effort="10000"
      velocity="10000" />
  </joint>
  <link
    name="sec03">
    <inertial>
      <origin
        xyz="0 0 0"
        rpy="0 0 0" />
      <mass
        value="0" />
      <inertia
        ixx="0"
        ixy="0"
        ixz="0"
        iyy="0"
        iyz="0"
        izz="0" />
    </inertial>
    <visual>
      <origin
        xyz="0 0 0"
        rpy="0 0 0" />
      <geometry>
        <mesh
          filename="package://tripod8/meshes/sec03.STL" />
      </geometry>
      <material
        name="">
        <color
          rgba="1 1 1 1" />
      </material>
    </visual>
    <collision>
      <origin
        xyz="0 0 0"
        rpy="0 0 0" />
      <geometry>
        <mesh
          filename="package://tripod8/meshes/sec03.STL" />
      </geometry>
    </collision>
  </link>
  <joint
    name="leg03"
    type="revolute">
    <origin
      xyz="-0.19118 0.12753 0.029643"
      rpy="0 0 2.618" />
    <parent
      link="base_link" />
    <child
      link="sec03" />
    <axis
      xyz="1 0 0" />
    <limit
      lower="-1.571"
      upper="1.571"
      effort="10000"
      velocity="10000" />
  </joint>
  <link
    name="hsec03">
    <inertial>
      <origin
        xyz="-0.00790452724722479 0.103639535857779 -0.0012819511920991"
        rpy="0 0 0" />
      <mass
        value="2.59385289637622" />
      <inertia
        ixx="0.00471710544810811"
        ixy="0.00494432583220453"
        ixz="-2.05253922379467E-06"
        iyy="0.010426853958564"
        iyz="-7.33479523115897E-06"
        izz="0.0117381218257232" />
    </inertial>
    <visual>
      <origin
        xyz="0 0 0"
        rpy="0 0 0" />
      <geometry>
        <mesh
          filename="package://tripod8/meshes/hsec03.STL" />
      </geometry>
      <material
        name="">
        <color
          rgba="0.792156862745098 0.819607843137255 0.933333333333333 1" />
      </material>
    </visual>
    <collision>
      <origin
        xyz="0 0 0"
        rpy="0 0 0" />
      <geometry>
        <mesh
          filename="package://tripod8/meshes/hsec03.STL" />
      </geometry>
    </collision>
  </link>
  <joint
    name="high03"
    type="revolute">
    <origin
      xyz="0.078806 0.0895 0"
      rpy="0 0 -2.618" />
    <parent
      link="sec03" />
    <child
      link="hsec03" />
    <axis
      xyz="0.5 0.86603 0" />
    <limit
      lower="-1.571"
      upper="1.571"
      effort="10000"
      velocity="10000" />
  </joint>
  <link
    name="lsec03">
    <inertial>
      <origin
        xyz="-0.0425461105280152 0.0331221400745612 -2.19054649374523E-07"
        rpy="0 0 0" />
      <mass
        value="0.292019079551133" />
      <inertia
        ixx="0.000234972015489013"
        ixy="0.000257573386670841"
        ixz="-6.95886932488568E-10"
        iyy="0.000532392844620643"
        iyz="1.13092032251536E-09"
        izz="0.000615708168399117" />
    </inertial>
    <visual>
      <origin
        xyz="0 0 0"
        rpy="0 0 0" />
      <geometry>
        <mesh
          filename="package://tripod8/meshes/lsec03.STL" />
      </geometry>
      <material
        name="">
        <color
          rgba="0.898039215686275 0.917647058823529 0.929411764705882 1" />
      </material>
    </visual>
    <collision>
      <origin
        xyz="0 0 0"
        rpy="0 0 0" />
      <geometry>
        <mesh
          filename="package://tripod8/meshes/lsec03.STL" />
      </geometry>
    </collision>
  </link>
  <joint
    name="low03"
    type="revolute">
    <origin
      xyz="-0.180243174572986 0.227096787723632 -0.00210000000002314"
      rpy="0 0 0" />
    <parent
      link="hsec03" />
    <child
      link="lsec03" />
    <axis
      xyz="0.500000000000065 0.866025403784401 0" />
    <limit
      lower="-1.571"
      upper="1.571"
      effort="10000"
      velocity="10000" />
  </joint>
</robot>