<?xml version="1.0" encoding="utf-8"?>
<!-- This URDF was automatically created by SolidWorks to URDF Exporter! Originally created by Stephen Brawner (brawner@gmail.com) 
     Commit Version: 1.6.0-4-g7f85cfe  Build Version: 1.6.7995.38578
     For more information, please see http://wiki.ros.org/sw_urdf_exporter -->
<robot
  name="try11">
  <link
    name="base_link">
    <inertial>
      <origin
        xyz="2.27682456221956E-18 -0.005 0"
        rpy="0 0 0" />
      <mass
        value="0.0002" />
      <inertia
        ixx="3.33333333333334E-09"
        ixy="1.72329294281881E-26"
        ixz="3.0309750528515E-26"
        iyy="1.73333333333333E-09"
        iyz="-8.32068698519475E-26"
        izz="1.73333333333333E-09" />
    </inertial>
    <visual>
      <origin
        xyz="0 0 0"
        rpy="0 0 0" />
      <geometry>
        <mesh
          filename="package://try11/meshes/base_link.STL" />
      </geometry>
      <material
        name="">
        <color
          rgba="0.792156862745098 0.819607843137255 0.933333333333333 1" />
      </material>
    </visual>
    <collision>
      <origin
        xyz="0 0 0"
        rpy="0 0 0" />
      <geometry>
        <mesh
          filename="package://try11/meshes/base_link.STL" />
      </geometry>
    </collision>
  </link>
  <link
    name="sec01">
    <inertial>
      <origin
        xyz="8.13151629364128E-19 0.0025 0"
        rpy="0 0 0" />
      <mass
        value="0.0015707963267949" />
      <inertia
        ixx="4.25424005173618E-08"
        ixy="4.73496022666977E-40"
        ixz="1.99136488891557E-56"
        iyy="7.85398163397449E-08"
        iyz="7.588784500269E-41"
        izz="4.25424005173618E-08" />
    </inertial>
    <visual>
      <origin
        xyz="0 0 0"
        rpy="0 0 0" />
      <geometry>
        <mesh
          filename="package://try11/meshes/sec01.STL" />
      </geometry>
      <material
        name="">
        <color
          rgba="0.792156862745098 0.819607843137255 0.933333333333333 1" />
      </material>
    </visual>
    <collision>
      <origin
        xyz="0 0 0"
        rpy="0 0 0" />
      <geometry>
        <mesh
          filename="package://try11/meshes/sec01.STL" />
      </geometry>
    </collision>
  </link>
  <joint
    name="joint01"
    type="revolute">
    <origin
      xyz="0 0 0"
      rpy="0 0 0" />
    <parent
      link="base_link" />
    <child
      link="sec01" />
    <axis
      xyz="0 0 0" />
    <limit
      lower="-1.571"
      upper="-1.571"
      effort="100"
      velocity="0" />
  </joint>
  <link
    name="sec02">
    <inertial>
      <origin
        xyz="4.33680868994202E-19 0.0025 0"
        rpy="0 0 0" />
      <mass
        value="0.0015707963267949" />
      <inertia
        ixx="4.25424005173618E-08"
        ixy="5.51453741702018E-25"
        ixz="-1.10290748340404E-24"
        iyy="7.85398163397448E-08"
        iyz="-1.37863435425504E-25"
        izz="4.25424005173618E-08" />
    </inertial>
    <visual>
      <origin
        xyz="0 0 0"
        rpy="0 0 0" />
      <geometry>
        <mesh
          filename="package://try11/meshes/sec02.STL" />
      </geometry>
      <material
        name="">
        <color
          rgba="0.792156862745098 0.819607843137255 0.933333333333333 1" />
      </material>
    </visual>
    <collision>
      <origin
        xyz="0 0 0"
        rpy="0 0 0" />
      <geometry>
        <mesh
          filename="package://try11/meshes/sec02.STL" />
      </geometry>
    </collision>
  </link>
  <joint
    name="joint02"
    type="revolute">
    <origin
      xyz="0 0.01 0"
      rpy="0 0 0" />
    <parent
      link="sec01" />
    <child
      link="sec02" />
    <axis
      xyz="0 0 0" />
    <limit
      lower="-1.571"
      upper="1.571"
      effort="100"
      velocity="0" />
  </joint>
  <link
    name="sec03">
    <inertial>
      <origin
        xyz="3.25260651745651E-19 0.0025 0"
        rpy="0 0 0" />
      <mass
        value="0.0015707963267949" />
      <inertia
        ixx="4.25424005173618E-08"
        ixy="-5.51453741702019E-25"
        ixz="-4.03250548619601E-24"
        iyy="7.85398163397448E-08"
        iyz="2.75726870851009E-25"
        izz="4.25424005173618E-08" />
    </inertial>
    <visual>
      <origin
        xyz="0 0 0"
        rpy="0 0 0" />
      <geometry>
        <mesh
          filename="package://try11/meshes/sec03.STL" />
      </geometry>
      <material
        name="">
        <color
          rgba="0.792156862745098 0.819607843137255 0.933333333333333 1" />
      </material>
    </visual>
    <collision>
      <origin
        xyz="0 0 0"
        rpy="0 0 0" />
      <geometry>
        <mesh
          filename="package://try11/meshes/sec03.STL" />
      </geometry>
    </collision>
  </link>
  <joint
    name="joint03"
    type="revolute">
    <origin
      xyz="0 0.01 0"
      rpy="0 0 0" />
    <parent
      link="sec02" />
    <child
      link="sec03" />
    <axis
      xyz="0 0 0" />
    <limit
      lower="-1.571"
      upper="1.571"
      effort="100"
      velocity="0" />
  </joint>
  <link
    name="sec04">
    <inertial>
      <origin
        xyz="-2.71050543121376E-19 0.0025 0"
        rpy="0 0 0" />
      <mass
        value="0.0015707963267949" />
      <inertia
        ixx="4.25424005173618E-08"
        ixy="5.5145374170202E-25"
        ixz="-5.51453741702019E-24"
        iyy="7.85398163397449E-08"
        iyz="-1.15493625579607E-39"
        izz="4.25424005173618E-08" />
    </inertial>
    <visual>
      <origin
        xyz="0 0 0"
        rpy="0 0 0" />
      <geometry>
        <mesh
          filename="package://try11/meshes/sec04.STL" />
      </geometry>
      <material
        name="">
        <color
          rgba="0.792156862745098 0.819607843137255 0.933333333333333 1" />
      </material>
    </visual>
    <collision>
      <origin
        xyz="0 0 0"
        rpy="0 0 0" />
      <geometry>
        <mesh
          filename="package://try11/meshes/sec04.STL" />
      </geometry>
    </collision>
  </link>
  <joint
    name="joint04"
    type="revolute">
    <origin
      xyz="0 0.01 0"
      rpy="0 0 0" />
    <parent
      link="sec03" />
    <child
      link="sec04" />
    <axis
      xyz="0 0 0" />
    <limit
      lower="-1.571"
      upper="1.571"
      effort="100"
      velocity="0" />
  </joint>
  <link
    name="sec05">
    <inertial>
      <origin
        xyz="-1.62630325872826E-19 0.0025 0"
        rpy="0 0 0" />
      <mass
        value="0.0015707963267949" />
      <inertia
        ixx="4.25424005173618E-08"
        ixy="-2.75726870851008E-25"
        ixz="-1.93008809595706E-24"
        iyy="7.85398163397448E-08"
        iyz="-4.72187784282387E-41"
        izz="4.25424005173618E-08" />
    </inertial>
    <visual>
      <origin
        xyz="0 0 0"
        rpy="0 0 0" />
      <geometry>
        <mesh
          filename="package://try11/meshes/sec05.STL" />
      </geometry>
      <material
        name="">
        <color
          rgba="0.792156862745098 0.819607843137255 0.933333333333333 1" />
      </material>
    </visual>
    <collision>
      <origin
        xyz="0 0 0"
        rpy="0 0 0" />
      <geometry>
        <mesh
          filename="package://try11/meshes/sec05.STL" />
      </geometry>
    </collision>
  </link>
  <joint
    name="joint05"
    type="revolute">
    <origin
      xyz="0 0.01 0"
      rpy="0 0 0" />
    <parent
      link="sec04" />
    <child
      link="sec05" />
    <axis
      xyz="0 0 0" />
    <limit
      lower="-1.571"
      upper="1.571"
      effort="100"
      velocity="0" />
  </joint>
  <link
    name="sec06">
    <inertial>
      <origin
        xyz="-2.00577401909818E-18 0.0025 -1.73472347597681E-18"
        rpy="0 0 0" />
      <mass
        value="0.0015707963267949" />
      <inertia
        ixx="4.25424005173618E-08"
        ixy="1.37863435425504E-25"
        ixz="-6.37618388842958E-25"
        iyy="7.85398163397448E-08"
        iyz="3.37934548137149E-39"
        izz="4.25424005173618E-08" />
    </inertial>
    <visual>
      <origin
        xyz="0 0 0"
        rpy="0 0 0" />
      <geometry>
        <mesh
          filename="package://try11/meshes/sec06.STL" />
      </geometry>
      <material
        name="">
        <color
          rgba="0.792156862745098 0.819607843137255 0.933333333333333 1" />
      </material>
    </visual>
    <collision>
      <origin
        xyz="0 0 0"
        rpy="0 0 0" />
      <geometry>
        <mesh
          filename="package://try11/meshes/sec06.STL" />
      </geometry>
    </collision>
  </link>
  <joint
    name="joint06"
    type="revolute">
    <origin
      xyz="0 0.01 0"
      rpy="0 0 0" />
    <parent
      link="sec05" />
    <child
      link="sec06" />
    <axis
      xyz="0 0 0" />
    <limit
      lower="-1.571"
      upper="1.571"
      effort="100"
      velocity="0" />
  </joint>
  <link
    name="sec07">
    <inertial>
      <origin
        xyz="-1.84314369322536E-18 0.0025 -1.73472347597681E-18"
        rpy="0 0 0" />
      <mass
        value="0.0015707963267949" />
      <inertia
        ixx="4.25424005173618E-08"
        ixy="-1.88326956163455E-39"
        ixz="2.35098870164457E-38"
        iyy="7.85398163397448E-08"
        iyz="1.88906772285313E-39"
        izz="4.25424005173618E-08" />
    </inertial>
    <visual>
      <origin
        xyz="0 0 0"
        rpy="0 0 0" />
      <geometry>
        <mesh
          filename="package://try11/meshes/sec07.STL" />
      </geometry>
      <material
        name="">
        <color
          rgba="0.792156862745098 0.819607843137255 0.933333333333333 1" />
      </material>
    </visual>
    <collision>
      <origin
        xyz="0 0 0"
        rpy="0 0 0" />
      <geometry>
        <mesh
          filename="package://try11/meshes/sec07.STL" />
      </geometry>
    </collision>
  </link>
  <joint
    name="joint07"
    type="revolute">
    <origin
      xyz="0 0.01 0"
      rpy="0 0 0" />
    <parent
      link="sec06" />
    <child
      link="sec07" />
    <axis
      xyz="0 0 0" />
    <limit
      lower="-1.571"
      upper="1.571"
      effort="100"
      velocity="0" />
  </joint>
  <link
    name="sec08">
    <inertial>
      <origin
        xyz="-1.62630325872826E-18 0.0025 0"
        rpy="0 0 0" />
      <mass
        value="0.0015707963267949" />
      <inertia
        ixx="4.25424005173618E-08"
        ixy="-2.75726870851008E-25"
        ixz="-9.91055745063802E-41"
        iyy="7.85398163397448E-08"
        iyz="1.65082098396703E-40"
        izz="4.25424005173618E-08" />
    </inertial>
    <visual>
      <origin
        xyz="0 0 0"
        rpy="0 0 0" />
      <geometry>
        <mesh
          filename="package://try11/meshes/sec08.STL" />
      </geometry>
      <material
        name="">
        <color
          rgba="0.792156862745098 0.819607843137255 0.933333333333333 1" />
      </material>
    </visual>
    <collision>
      <origin
        xyz="0 0 0"
        rpy="0 0 0" />
      <geometry>
        <mesh
          filename="package://try11/meshes/sec08.STL" />
      </geometry>
    </collision>
  </link>
  <joint
    name="joint08"
    type="revolute">
    <origin
      xyz="0 0.01 0"
      rpy="0 0 0" />
    <parent
      link="sec07" />
    <child
      link="sec08" />
    <axis
      xyz="0 0 0" />
    <limit
      lower="-1.571"
      upper="1.571"
      effort="100"
      velocity="0" />
  </joint>
  <link
    name="sec09">
    <inertial>
      <origin
        xyz="-1.68051336735253E-18 0.0025 0"
        rpy="0 0 0" />
      <mass
        value="0.0015707963267949" />
      <inertia
        ixx="4.25424005173619E-08"
        ixy="5.74790090871454E-41"
        ixz="4.41162993361615E-24"
        iyy="7.85398163397449E-08"
        iyz="-3.31855213692167E-41"
        izz="4.25424005173619E-08" />
    </inertial>
    <visual>
      <origin
        xyz="0 0 0"
        rpy="0 0 0" />
      <geometry>
        <mesh
          filename="package://try11/meshes/sec09.STL" />
      </geometry>
      <material
        name="">
        <color
          rgba="0.792156862745098 0.819607843137255 0.933333333333333 1" />
      </material>
    </visual>
    <collision>
      <origin
        xyz="0 0 0"
        rpy="0 0 0" />
      <geometry>
        <mesh
          filename="package://try11/meshes/sec09.STL" />
      </geometry>
    </collision>
  </link>
  <joint
    name="joint09"
    type="revolute">
    <origin
      xyz="0 0.01 0"
      rpy="0 0 0" />
    <parent
      link="sec08" />
    <child
      link="sec09" />
    <axis
      xyz="0 0 0" />
    <limit
      lower="-1.571"
      upper="1.571"
      effort="100"
      velocity="0" />
  </joint>
  <link
    name="sec10">
    <inertial>
      <origin
        xyz="-3.36102673470506E-18 0.00250000000000002 0"
        rpy="0 0 0" />
      <mass
        value="0.0015707963267949" />
      <inertia
        ixx="4.25424005173618E-08"
        ixy="1.10290748340404E-24"
        ixz="6.89317177127524E-24"
        iyy="7.85398163397449E-08"
        iyz="5.51453741702019E-25"
        izz="4.25424005173618E-08" />
    </inertial>
    <visual>
      <origin
        xyz="0 0 0"
        rpy="0 0 0" />
      <geometry>
        <mesh
          filename="package://try11/meshes/sec10.STL" />
      </geometry>
      <material
        name="">
        <color
          rgba="0.792156862745098 0.819607843137255 0.933333333333333 1" />
      </material>
    </visual>
    <collision>
      <origin
        xyz="0 0 0"
        rpy="0 0 0" />
      <geometry>
        <mesh
          filename="package://try11/meshes/sec10.STL" />
      </geometry>
    </collision>
  </link>
  <joint
    name="joint10"
    type="revolute">
    <origin
      xyz="0 0.01 0"
      rpy="0 0 0" />
    <parent
      link="sec09" />
    <child
      link="sec10" />
    <axis
      xyz="0 0 0" />
    <limit
      lower="-1.571"
      upper="1.571"
      effort="100"
      velocity="0" />
  </joint>
  <link
    name="sec11">
    <inertial>
      <origin
        xyz="0.0025 -1.73472347597681E-18 1.73472347597681E-18"
        rpy="0 0 0" />
      <mass
        value="0.0015707963267949" />
      <inertia
        ixx="7.85398163397448E-08"
        ixy="-1.43222477314754E-40"
        ixz="9.45378640676979E-40"
        iyy="4.25424005173618E-08"
        iyz="2.67110406136915E-24"
        izz="4.25424005173618E-08" />
    </inertial>
    <visual>
      <origin
        xyz="0 0 0"
        rpy="0 0 0" />
      <geometry>
        <mesh
          filename="package://try11/meshes/sec11.STL" />
      </geometry>
      <material
        name="">
        <color
          rgba="0.792156862745098 0.819607843137255 0.933333333333333 1" />
      </material>
    </visual>
    <collision>
      <origin
        xyz="0 0 0"
        rpy="0 0 0" />
      <geometry>
        <mesh
          filename="package://try11/meshes/sec11.STL" />
      </geometry>
    </collision>
  </link>
  <joint
    name="joint11"
    type="revolute">
    <origin
      xyz="0.011 -0.005 0"
      rpy="0 0 0" />
    <parent
      link="base_link" />
    <child
      link="sec11" />
    <axis
      xyz="1 0 0" />
    <limit
      lower="-1.571"
      upper="1.571"
      effort="100"
      velocity="0" />
  </joint>
  <link
    name="sec12">
    <inertial>
      <origin
        xyz="0.0025 0 1.73472347597681E-18"
        rpy="0 0 0" />
      <mass
        value="0.0015707963267949" />
      <inertia
        ixx="7.85398163397449E-08"
        ixy="2.7572687085101E-25"
        ixz="1.10290748340404E-24"
        iyy="4.25424005173618E-08"
        iyz="1.37863435425505E-24"
        izz="4.25424005173618E-08" />
    </inertial>
    <visual>
      <origin
        xyz="0 0 0"
        rpy="0 0 0" />
      <geometry>
        <mesh
          filename="package://try11/meshes/sec12.STL" />
      </geometry>
      <material
        name="">
        <color
          rgba="0.792156862745098 0.819607843137255 0.933333333333333 1" />
      </material>
    </visual>
    <collision>
      <origin
        xyz="0 0 0"
        rpy="0 0 0" />
      <geometry>
        <mesh
          filename="package://try11/meshes/sec12.STL" />
      </geometry>
    </collision>
  </link>
  <joint
    name="joint12"
    type="revolute">
    <origin
      xyz="0.01 0 0"
      rpy="0 0 0" />
    <parent
      link="sec11" />
    <child
      link="sec12" />
    <axis
      xyz="0 0 0" />
    <limit
      lower="-1.571"
      upper="1.571"
      effort="100"
      velocity="0" />
  </joint>
  <link
    name="sec13">
    <inertial>
      <origin
        xyz="0.0025 0 0"
        rpy="0 0 0" />
      <mass
        value="0.0015707963267949" />
      <inertia
        ixx="7.85398163397448E-08"
        ixy="-2.7572687085101E-25"
        ixz="-1.10290748340403E-24"
        iyy="4.25424005173618E-08"
        iyz="1.37863435425504E-24"
        izz="4.25424005173618E-08" />
    </inertial>
    <visual>
      <origin
        xyz="0 0 0"
        rpy="0 0 0" />
      <geometry>
        <mesh
          filename="package://try11/meshes/sec13.STL" />
      </geometry>
      <material
        name="">
        <color
          rgba="0.792156862745098 0.819607843137255 0.933333333333333 1" />
      </material>
    </visual>
    <collision>
      <origin
        xyz="0 0 0"
        rpy="0 0 0" />
      <geometry>
        <mesh
          filename="package://try11/meshes/sec13.STL" />
      </geometry>
    </collision>
  </link>
  <joint
    name="joint13"
    type="revolute">
    <origin
      xyz="0.01 0 0"
      rpy="0 0 0" />
    <parent
      link="sec12" />
    <child
      link="sec13" />
    <axis
      xyz="0 0 0" />
    <limit
      lower="-1.571"
      upper="1.571"
      effort="100"
      velocity="0" />
  </joint>
  <link
    name="sec14">
    <inertial>
      <origin
        xyz="0.0025 0 1.73472347597681E-18"
        rpy="0 0 0" />
      <mass
        value="0.0015707963267949" />
      <inertia
        ixx="7.85398163397448E-08"
        ixy="2.75726870851011E-25"
        ixz="1.10290748340403E-24"
        iyy="4.25424005173618E-08"
        iyz="1.37863435425504E-24"
        izz="4.25424005173618E-08" />
    </inertial>
    <visual>
      <origin
        xyz="0 0 0"
        rpy="0 0 0" />
      <geometry>
        <mesh
          filename="package://try11/meshes/sec14.STL" />
      </geometry>
      <material
        name="">
        <color
          rgba="0.792156862745098 0.819607843137255 0.933333333333333 1" />
      </material>
    </visual>
    <collision>
      <origin
        xyz="0 0 0"
        rpy="0 0 0" />
      <geometry>
        <mesh
          filename="package://try11/meshes/sec14.STL" />
      </geometry>
    </collision>
  </link>
  <joint
    name="joint14"
    type="revolute">
    <origin
      xyz="0.01 0 0"
      rpy="0 0 0" />
    <parent
      link="sec13" />
    <child
      link="sec14" />
    <axis
      xyz="0 0 0" />
    <limit
      lower="-1.571"
      upper="1.571"
      effort="100"
      velocity="0" />
  </joint>
  <link
    name="sec15">
    <inertial>
      <origin
        xyz="0.0025 0 0"
        rpy="0 0 0" />
      <mass
        value="0.0015707963267949" />
      <inertia
        ixx="7.85398163397448E-08"
        ixy="-2.7572687085101E-25"
        ixz="-1.10290748340403E-24"
        iyy="4.25424005173618E-08"
        iyz="1.37863435425504E-24"
        izz="4.25424005173618E-08" />
    </inertial>
    <visual>
      <origin
        xyz="0 0 0"
        rpy="0 0 0" />
      <geometry>
        <mesh
          filename="package://try11/meshes/sec15.STL" />
      </geometry>
      <material
        name="">
        <color
          rgba="0.792156862745098 0.819607843137255 0.933333333333333 1" />
      </material>
    </visual>
    <collision>
      <origin
        xyz="0 0 0"
        rpy="0 0 0" />
      <geometry>
        <mesh
          filename="package://try11/meshes/sec15.STL" />
      </geometry>
    </collision>
  </link>
  <joint
    name="joint15"
    type="revolute">
    <origin
      xyz="0.01 0 0"
      rpy="0 0 0" />
    <parent
      link="sec14" />
    <child
      link="sec15" />
    <axis
      xyz="0 0 0" />
    <limit
      lower="-1.571"
      upper="1.571"
      effort="100"
      velocity="0" />
  </joint>
  <link
    name="sec16">
    <inertial>
      <origin
        xyz="0.0025 0 1.73472347597681E-18"
        rpy="0 0 0" />
      <mass
        value="0.0015707963267949" />
      <inertia
        ixx="7.85398163397448E-08"
        ixy="2.7572687085101E-25"
        ixz="1.10290748340403E-24"
        iyy="4.25424005173618E-08"
        iyz="1.37863435425504E-24"
        izz="4.25424005173618E-08" />
    </inertial>
    <visual>
      <origin
        xyz="0 0 0"
        rpy="0 0 0" />
      <geometry>
        <mesh
          filename="package://try11/meshes/sec16.STL" />
      </geometry>
      <material
        name="">
        <color
          rgba="0.792156862745098 0.819607843137255 0.933333333333333 1" />
      </material>
    </visual>
    <collision>
      <origin
        xyz="0 0 0"
        rpy="0 0 0" />
      <geometry>
        <mesh
          filename="package://try11/meshes/sec16.STL" />
      </geometry>
    </collision>
  </link>
  <joint
    name="joint16"
    type="revolute">
    <origin
      xyz="0.01 0 0"
      rpy="0 0 0" />
    <parent
      link="sec15" />
    <child
      link="sec16" />
    <axis
      xyz="0 0 0" />
    <limit
      lower="-1.571"
      upper="1.571"
      effort="100"
      velocity="0" />
  </joint>
  <link
    name="sec17">
    <inertial>
      <origin
        xyz="0.0025 -1.73472347597681E-18 1.73472347597681E-18"
        rpy="0 0 0" />
      <mass
        value="0.0015707963267949" />
      <inertia
        ixx="7.85398163397449E-08"
        ixy="8.96831017167883E-41"
        ixz="3.58732406867153E-40"
        iyy="4.25424005173618E-08"
        iyz="2.67110406136915E-24"
        izz="4.25424005173619E-08" />
    </inertial>
    <visual>
      <origin
        xyz="0 0 0"
        rpy="0 0 0" />
      <geometry>
        <mesh
          filename="package://try11/meshes/sec17.STL" />
      </geometry>
      <material
        name="">
        <color
          rgba="0.792156862745098 0.819607843137255 0.933333333333333 1" />
      </material>
    </visual>
    <collision>
      <origin
        xyz="0 0 0"
        rpy="0 0 0" />
      <geometry>
        <mesh
          filename="package://try11/meshes/sec17.STL" />
      </geometry>
    </collision>
  </link>
  <joint
    name="joint17"
    type="revolute">
    <origin
      xyz="0.00999999999999999 0 0"
      rpy="0 0 0" />
    <parent
      link="sec16" />
    <child
      link="sec17" />
    <axis
      xyz="0 0 0" />
    <limit
      lower="-1.571"
      upper="1.571"
      effort="100"
      velocity="0" />
  </joint>
  <link
    name="sec18">
    <inertial>
      <origin
        xyz="0.0025 -1.73472347597681E-18 1.73472347597681E-18"
        rpy="0 0 0" />
      <mass
        value="0.0015707963267949" />
      <inertia
        ixx="7.85398163397449E-08"
        ixy="8.96831017167883E-41"
        ixz="2.86985925493723E-40"
        iyy="4.25424005173618E-08"
        iyz="2.67110406136915E-24"
        izz="4.25424005173619E-08" />
    </inertial>
    <visual>
      <origin
        xyz="0 0 0"
        rpy="0 0 0" />
      <geometry>
        <mesh
          filename="package://try11/meshes/sec18.STL" />
      </geometry>
      <material
        name="">
        <color
          rgba="0.792156862745098 0.819607843137255 0.933333333333333 1" />
      </material>
    </visual>
    <collision>
      <origin
        xyz="0 0 0"
        rpy="0 0 0" />
      <geometry>
        <mesh
          filename="package://try11/meshes/sec18.STL" />
      </geometry>
    </collision>
  </link>
  <joint
    name="joint18"
    type="revolute">
    <origin
      xyz="0.01 0 0"
      rpy="0 0 0" />
    <parent
      link="sec17" />
    <child
      link="sec18" />
    <axis
      xyz="0 1 0" />
    <limit
      lower="-1.571"
      upper="1.571"
      effort="100"
      velocity="0" />
  </joint>
  <link
    name="sec19">
    <inertial>
      <origin
        xyz="0.0025 -1.73472347597681E-18 1.73472347597681E-18"
        rpy="0 0 0" />
      <mass
        value="0.0015707963267949" />
      <inertia
        ixx="7.85398163397449E-08"
        ixy="8.96831017167883E-41"
        ixz="3.58732406867153E-40"
        iyy="4.25424005173618E-08"
        iyz="2.67110406136915E-24"
        izz="4.25424005173619E-08" />
    </inertial>
    <visual>
      <origin
        xyz="0 0 0"
        rpy="0 0 0" />
      <geometry>
        <mesh
          filename="package://try11/meshes/sec19.STL" />
      </geometry>
      <material
        name="">
        <color
          rgba="0.792156862745098 0.819607843137255 0.933333333333333 1" />
      </material>
    </visual>
    <collision>
      <origin
        xyz="0 0 0"
        rpy="0 0 0" />
      <geometry>
        <mesh
          filename="package://try11/meshes/sec19.STL" />
      </geometry>
    </collision>
  </link>
  <joint
    name="joint19"
    type="revolute">
    <origin
      xyz="0.01 0 0"
      rpy="0 0 0" />
    <parent
      link="sec18" />
    <child
      link="sec19" />
    <axis
      xyz="0 1 0" />
    <limit
      lower="-1.571"
      upper="1.571"
      effort="100"
      velocity="0" />
  </joint>
  <link
    name="sec20">
    <inertial>
      <origin
        xyz="0.0025 -1.73472347597681E-18 1.73472347597681E-18"
        rpy="0 0 0" />
      <mass
        value="0.0015707963267949" />
      <inertia
        ixx="7.85398163397449E-08"
        ixy="8.96831017167883E-41"
        ixz="3.58732406867153E-40"
        iyy="4.25424005173618E-08"
        iyz="2.67110406136915E-24"
        izz="4.25424005173619E-08" />
    </inertial>
    <visual>
      <origin
        xyz="0 0 0"
        rpy="0 0 0" />
      <geometry>
        <mesh
          filename="package://try11/meshes/sec20.STL" />
      </geometry>
      <material
        name="">
        <color
          rgba="0.792156862745098 0.819607843137255 0.933333333333333 1" />
      </material>
    </visual>
    <collision>
      <origin
        xyz="0 0 0"
        rpy="0 0 0" />
      <geometry>
        <mesh
          filename="package://try11/meshes/sec20.STL" />
      </geometry>
    </collision>
  </link>
  <joint
    name="joint20"
    type="revolute">
    <origin
      xyz="0.01 0 0"
      rpy="0 0 0" />
    <parent
      link="sec19" />
    <child
      link="sec20" />
    <axis
      xyz="0 1 0" />
    <limit
      lower="-1.571"
      upper="1.571"
      effort="100"
      velocity="0" />
  </joint>
  <link
    name="sec21">
    <inertial>
      <origin
        xyz="-0.0025 1.73472347597681E-18 -1.73472347597681E-18"
        rpy="0 0 0" />
      <mass
        value="0.0015707963267949" />
      <inertia
        ixx="7.85398163397449E-08"
        ixy="-2.87974185872985E-40"
        ixz="-2.53870077365949E-40"
        iyy="4.25424005173618E-08"
        iyz="-8.27180612553027E-25"
        izz="4.25424005173618E-08" />
    </inertial>
    <visual>
      <origin
        xyz="0 0 0"
        rpy="0 0 0" />
      <geometry>
        <mesh
          filename="package://try11/meshes/sec21.STL" />
      </geometry>
      <material
        name="">
        <color
          rgba="0.792156862745098 0.819607843137255 0.933333333333333 1" />
      </material>
    </visual>
    <collision>
      <origin
        xyz="0 0 0"
        rpy="0 0 0" />
      <geometry>
        <mesh
          filename="package://try11/meshes/sec21.STL" />
      </geometry>
    </collision>
  </link>
  <joint
    name="joint21"
    type="revolute">
    <origin
      xyz="-0.011 -0.005 0"
      rpy="0 0 0" />
    <parent
      link="base_link" />
    <child
      link="sec21" />
    <axis
      xyz="1 0 0" />
    <limit
      lower="-1.571"
      upper="1.571"
      effort="100"
      velocity="0" />
  </joint>
  <link
    name="sec22">
    <inertial>
      <origin
        xyz="-0.0025 1.73472347597681E-18 -1.73472347597681E-18"
        rpy="0 0 0" />
      <mass
        value="0.0015707963267949" />
      <inertia
        ixx="7.85398163397449E-08"
        ixy="4.54592135954334E-40"
        ixz="-1.10290748340404E-24"
        iyy="4.25424005173618E-08"
        iyz="-8.27180612553027E-25"
        izz="4.25424005173618E-08" />
    </inertial>
    <visual>
      <origin
        xyz="0 0 0"
        rpy="0 0 0" />
      <geometry>
        <mesh
          filename="package://try11/meshes/sec22.STL" />
      </geometry>
      <material
        name="">
        <color
          rgba="0.792156862745098 0.819607843137255 0.933333333333333 1" />
      </material>
    </visual>
    <collision>
      <origin
        xyz="0 0 0"
        rpy="0 0 0" />
      <geometry>
        <mesh
          filename="package://try11/meshes/sec22.STL" />
      </geometry>
    </collision>
  </link>
  <joint
    name="joint22"
    type="revolute">
    <origin
      xyz="-0.01 0 0"
      rpy="0 0 0" />
    <parent
      link="sec21" />
    <child
      link="sec22" />
    <axis
      xyz="0 0 0" />
    <limit
      lower="-1.571"
      upper="1.571"
      effort="100"
      velocity="0" />
  </joint>
  <link
    name="sec23">
    <inertial>
      <origin
        xyz="-0.0025 0 -1.73472347597681E-18"
        rpy="0 0 0" />
      <mass
        value="0.0015707963267949" />
      <inertia
        ixx="7.85398163397448E-08"
        ixy="-2.75726870851008E-25"
        ixz="-1.10290748340404E-24"
        iyy="4.25424005173618E-08"
        iyz="-8.27180612553026E-25"
        izz="4.25424005173618E-08" />
    </inertial>
    <visual>
      <origin
        xyz="0 0 0"
        rpy="0 0 0" />
      <geometry>
        <mesh
          filename="package://try11/meshes/sec23.STL" />
      </geometry>
      <material
        name="">
        <color
          rgba="0.792156862745098 0.819607843137255 0.933333333333333 1" />
      </material>
    </visual>
    <collision>
      <origin
        xyz="0 0 0"
        rpy="0 0 0" />
      <geometry>
        <mesh
          filename="package://try11/meshes/sec23.STL" />
      </geometry>
    </collision>
  </link>
  <joint
    name="joint23"
    type="revolute">
    <origin
      xyz="-0.01 0 0"
      rpy="0 0 0" />
    <parent
      link="sec22" />
    <child
      link="sec23" />
    <axis
      xyz="0 0 0" />
    <limit
      lower="-1.571"
      upper="1.571"
      effort="100"
      velocity="0" />
  </joint>
  <link
    name="sec24">
    <inertial>
      <origin
        xyz="-0.0025 0 -1.73472347597681E-18"
        rpy="0 0 0" />
      <mass
        value="0.0015707963267949" />
      <inertia
        ixx="7.85398163397448E-08"
        ixy="-2.75726870851008E-25"
        ixz="-1.10290748340404E-24"
        iyy="4.25424005173618E-08"
        iyz="-8.27180612553026E-25"
        izz="4.25424005173618E-08" />
    </inertial>
    <visual>
      <origin
        xyz="0 0 0"
        rpy="0 0 0" />
      <geometry>
        <mesh
          filename="package://try11/meshes/sec24.STL" />
      </geometry>
      <material
        name="">
        <color
          rgba="0.792156862745098 0.819607843137255 0.933333333333333 1" />
      </material>
    </visual>
    <collision>
      <origin
        xyz="0 0 0"
        rpy="0 0 0" />
      <geometry>
        <mesh
          filename="package://try11/meshes/sec24.STL" />
      </geometry>
    </collision>
  </link>
  <joint
    name="joint24"
    type="revolute">
    <origin
      xyz="-0.01 0 0"
      rpy="0 0 0" />
    <parent
      link="sec23" />
    <child
      link="sec24" />
    <axis
      xyz="0 0 0" />
    <limit
      lower="-1.571"
      upper="1.571"
      effort="100"
      velocity="0" />
  </joint>
  <link
    name="sec25">
    <inertial>
      <origin
        xyz="-0.0025 0 -1.73472347597681E-18"
        rpy="0 0 0" />
      <mass
        value="0.0015707963267949" />
      <inertia
        ixx="7.85398163397448E-08"
        ixy="-2.75726870851008E-25"
        ixz="-1.10290748340404E-24"
        iyy="4.25424005173618E-08"
        iyz="-8.27180612553026E-25"
        izz="4.25424005173618E-08" />
    </inertial>
    <visual>
      <origin
        xyz="0 0 0"
        rpy="0 0 0" />
      <geometry>
        <mesh
          filename="package://try11/meshes/sec25.STL" />
      </geometry>
      <material
        name="">
        <color
          rgba="0.792156862745098 0.819607843137255 0.933333333333333 1" />
      </material>
    </visual>
    <collision>
      <origin
        xyz="0 0 0"
        rpy="0 0 0" />
      <geometry>
        <mesh
          filename="package://try11/meshes/sec25.STL" />
      </geometry>
    </collision>
  </link>
  <joint
    name="joint25"
    type="revolute">
    <origin
      xyz="-0.01 0 0"
      rpy="0 0 0" />
    <parent
      link="sec24" />
    <child
      link="sec25" />
    <axis
      xyz="0 0 0" />
    <limit
      lower="-1.571"
      upper="1.571"
      effort="100"
      velocity="0" />
  </joint>
  <link
    name="sec26">
    <inertial>
      <origin
        xyz="-0.0025 0 -1.73472347597681E-18"
        rpy="0 0 0" />
      <mass
        value="0.0015707963267949" />
      <inertia
        ixx="7.85398163397449E-08"
        ixy="0"
        ixz="7.17464813734306E-41"
        iyy="4.25424005173618E-08"
        iyz="4.65289094561078E-25"
        izz="4.25424005173619E-08" />
    </inertial>
    <visual>
      <origin
        xyz="0 0 0"
        rpy="0 0 0" />
      <geometry>
        <mesh
          filename="package://try11/meshes/sec26.STL" />
      </geometry>
      <material
        name="">
        <color
          rgba="0.792156862745098 0.819607843137255 0.933333333333333 1" />
      </material>
    </visual>
    <collision>
      <origin
        xyz="0 0 0"
        rpy="0 0 0" />
      <geometry>
        <mesh
          filename="package://try11/meshes/sec26.STL" />
      </geometry>
    </collision>
  </link>
  <joint
    name="joint26"
    type="revolute">
    <origin
      xyz="-0.01 0 0"
      rpy="0 0 0" />
    <parent
      link="sec25" />
    <child
      link="sec26" />
    <axis
      xyz="0 0 0" />
    <limit
      lower="-1.571"
      upper="1.571"
      effort="100"
      velocity="0" />
  </joint>
  <link
    name="sec27">
    <inertial>
      <origin
        xyz="-0.00249999999999999 0 -1.73472347597681E-18"
        rpy="0 0 0" />
      <mass
        value="0.0015707963267949" />
      <inertia
        ixx="7.85398163397449E-08"
        ixy="0"
        ixz="8.96831017167883E-41"
        iyy="4.25424005173618E-08"
        iyz="4.65289094561078E-25"
        izz="4.25424005173619E-08" />
    </inertial>
    <visual>
      <origin
        xyz="0 0 0"
        rpy="0 0 0" />
      <geometry>
        <mesh
          filename="package://try11/meshes/sec27.STL" />
      </geometry>
      <material
        name="">
        <color
          rgba="0.792156862745098 0.819607843137255 0.933333333333333 1" />
      </material>
    </visual>
    <collision>
      <origin
        xyz="0 0 0"
        rpy="0 0 0" />
      <geometry>
        <mesh
          filename="package://try11/meshes/sec27.STL" />
      </geometry>
    </collision>
  </link>
  <joint
    name="joint27"
    type="revolute">
    <origin
      xyz="-0.01 0 0"
      rpy="0 0 0" />
    <parent
      link="sec26" />
    <child
      link="sec27" />
    <axis
      xyz="0 0 0" />
    <limit
      lower="-1.571"
      upper="1.571"
      effort="100"
      velocity="0" />
  </joint>
  <link
    name="sec28">
    <inertial>
      <origin
        xyz="-0.00250000000000002 0 -1.73472347597681E-18"
        rpy="0 0 0" />
      <mass
        value="0.0015707963267949" />
      <inertia
        ixx="7.85398163397449E-08"
        ixy="0"
        ixz="7.17464813734306E-41"
        iyy="4.25424005173618E-08"
        iyz="4.65289094561078E-25"
        izz="4.25424005173619E-08" />
    </inertial>
    <visual>
      <origin
        xyz="0 0 0"
        rpy="0 0 0" />
      <geometry>
        <mesh
          filename="package://try11/meshes/sec28.STL" />
      </geometry>
      <material
        name="">
        <color
          rgba="0.792156862745098 0.819607843137255 0.933333333333333 1" />
      </material>
    </visual>
    <collision>
      <origin
        xyz="0 0 0"
        rpy="0 0 0" />
      <geometry>
        <mesh
          filename="package://try11/meshes/sec28.STL" />
      </geometry>
    </collision>
  </link>
  <joint
    name="joint28"
    type="revolute">
    <origin
      xyz="-0.01 0 0"
      rpy="0 0 0" />
    <parent
      link="sec27" />
    <child
      link="sec28" />
    <axis
      xyz="0 0 0" />
    <limit
      lower="-1.571"
      upper="1.571"
      effort="100"
      velocity="0" />
  </joint>
  <link
    name="sec29">
    <inertial>
      <origin
        xyz="-0.00250000000000002 0 -1.73472347597681E-18"
        rpy="0 0 0" />
      <mass
        value="0.0015707963267949" />
      <inertia
        ixx="7.85398163397449E-08"
        ixy="0"
        ixz="8.96831017167883E-41"
        iyy="4.25424005173618E-08"
        iyz="4.65289094561078E-25"
        izz="4.25424005173619E-08" />
    </inertial>
    <visual>
      <origin
        xyz="0 0 0"
        rpy="0 0 0" />
      <geometry>
        <mesh
          filename="package://try11/meshes/sec29.STL" />
      </geometry>
      <material
        name="">
        <color
          rgba="0.792156862745098 0.819607843137255 0.933333333333333 1" />
      </material>
    </visual>
    <collision>
      <origin
        xyz="0 0 0"
        rpy="0 0 0" />
      <geometry>
        <mesh
          filename="package://try11/meshes/sec29.STL" />
      </geometry>
    </collision>
  </link>
  <joint
    name="joint29"
    type="revolute">
    <origin
      xyz="-0.01 0 0"
      rpy="0 0 0" />
    <parent
      link="sec28" />
    <child
      link="sec29" />
    <axis
      xyz="0 0 0" />
    <limit
      lower="-1.571"
      upper="1.571"
      effort="100"
      velocity="0" />
  </joint>
  <link
    name="sec30">
    <inertial>
      <origin
        xyz="-0.00249999999999999 0 -1.73472347597681E-18"
        rpy="0 0 0" />
      <mass
        value="0.0015707963267949" />
      <inertia
        ixx="7.85398163397449E-08"
        ixy="0"
        ixz="7.17464813734306E-41"
        iyy="4.25424005173618E-08"
        iyz="4.65289094561078E-25"
        izz="4.25424005173619E-08" />
    </inertial>
    <visual>
      <origin
        xyz="0 0 0"
        rpy="0 0 0" />
      <geometry>
        <mesh
          filename="package://try11/meshes/sec30.STL" />
      </geometry>
      <material
        name="">
        <color
          rgba="0.792156862745098 0.819607843137255 0.933333333333333 1" />
      </material>
    </visual>
    <collision>
      <origin
        xyz="0 0 0"
        rpy="0 0 0" />
      <geometry>
        <mesh
          filename="package://try11/meshes/sec30.STL" />
      </geometry>
    </collision>
  </link>
  <joint
    name="joint30"
    type="revolute">
    <origin
      xyz="-0.01 0 0"
      rpy="0 0 0" />
    <parent
      link="sec29" />
    <child
      link="sec30" />
    <axis
      xyz="0 0 0" />
    <limit
      lower="-1.571"
      upper="1.571"
      effort="100"
      velocity="0" />
  </joint>
  <link
    name="sec31">
    <inertial>
      <origin
        xyz="0.0025 0 0"
        rpy="0 0 0" />
      <mass
        value="0.0015707963267949" />
      <inertia
        ixx="7.85398163397449E-08"
        ixy="-1.61515983115699E-24"
        ixz="1.35423264498193E-23"
        iyy="4.25424005173618E-08"
        iyz="-4.41162993361615E-24"
        izz="4.25424005173618E-08" />
    </inertial>
    <visual>
      <origin
        xyz="0 0 0"
        rpy="0 0 0" />
      <geometry>
        <mesh
          filename="package://try11/meshes/sec31.STL" />
      </geometry>
      <material
        name="">
        <color
          rgba="0.792156862745098 0.819607843137255 0.933333333333333 1" />
      </material>
    </visual>
    <collision>
      <origin
        xyz="0 0 0"
        rpy="0 0 0" />
      <geometry>
        <mesh
          filename="package://try11/meshes/sec31.STL" />
      </geometry>
    </collision>
  </link>
  <joint
    name="joint31"
    type="revolute">
    <origin
      xyz="0.011 0.1 0"
      rpy="0 0 0" />
    <parent
      link="base_link" />
    <child
      link="sec31" />
    <axis
      xyz="1 0 0" />
    <limit
      lower="-1.571"
      upper="1.571"
      effort="100"
      velocity="0" />
  </joint>
  <link
    name="sec32">
    <inertial>
      <origin
        xyz="0.0025 1.38777878078145E-17 0"
        rpy="0 0 0" />
      <mass
        value="0.0015707963267949" />
      <inertia
        ixx="7.85398163397449E-08"
        ixy="-1.61515983115699E-24"
        ixz="1.35423264498193E-23"
        iyy="4.25424005173618E-08"
        iyz="-5.70409964073026E-24"
        izz="4.25424005173618E-08" />
    </inertial>
    <visual>
      <origin
        xyz="0 0 0"
        rpy="0 0 0" />
      <geometry>
        <mesh
          filename="package://try11/meshes/sec32.STL" />
      </geometry>
      <material
        name="">
        <color
          rgba="0.792156862745098 0.819607843137255 0.933333333333333 1" />
      </material>
    </visual>
    <collision>
      <origin
        xyz="0 0 0"
        rpy="0 0 0" />
      <geometry>
        <mesh
          filename="package://try11/meshes/sec32.STL" />
      </geometry>
    </collision>
  </link>
  <joint
    name="joint32"
    type="revolute">
    <origin
      xyz="0.01 0 0"
      rpy="0 0 0" />
    <parent
      link="sec31" />
    <child
      link="sec32" />
    <axis
      xyz="0 0 0" />
    <limit
      lower="-1.571"
      upper="1.571"
      effort="100"
      velocity="0" />
  </joint>
  <link
    name="sec33">
    <inertial>
      <origin
        xyz="0.0025 1.38777878078145E-17 -6.93889390390723E-18"
        rpy="0 0 0" />
      <mass
        value="0.0015707963267949" />
      <inertia
        ixx="7.85398163397448E-08"
        ixy="-1.06370608945497E-24"
        ixz="1.38180533206703E-23"
        iyy="4.25424005173618E-08"
        iyz="-5.70409964073025E-24"
        izz="4.25424005173618E-08" />
    </inertial>
    <visual>
      <origin
        xyz="0 0 0"
        rpy="0 0 0" />
      <geometry>
        <mesh
          filename="package://try11/meshes/sec33.STL" />
      </geometry>
      <material
        name="">
        <color
          rgba="0.792156862745098 0.819607843137255 0.933333333333333 1" />
      </material>
    </visual>
    <collision>
      <origin
        xyz="0 0 0"
        rpy="0 0 0" />
      <geometry>
        <mesh
          filename="package://try11/meshes/sec33.STL" />
      </geometry>
    </collision>
  </link>
  <joint
    name="joint33"
    type="revolute">
    <origin
      xyz="0.01 0 0"
      rpy="0 0 0" />
    <parent
      link="sec32" />
    <child
      link="sec33" />
    <axis
      xyz="0 0 0" />
    <limit
      lower="-1.571"
      upper="1.571"
      effort="100"
      velocity="0" />
  </joint>
  <link
    name="sec34">
    <inertial>
      <origin
        xyz="0.00249999999999999 0 -6.93889390390723E-18"
        rpy="0 0 0" />
      <mass
        value="0.0015707963267949" />
      <inertia
        ixx="7.85398163397448E-08"
        ixy="-1.06370608945497E-24"
        ixz="1.38180533206703E-23"
        iyy="4.25424005173618E-08"
        iyz="-5.70409964073025E-24"
        izz="4.25424005173618E-08" />
    </inertial>
    <visual>
      <origin
        xyz="0 0 0"
        rpy="0 0 0" />
      <geometry>
        <mesh
          filename="package://try11/meshes/sec34.STL" />
      </geometry>
      <material
        name="">
        <color
          rgba="0.792156862745098 0.819607843137255 0.933333333333333 1" />
      </material>
    </visual>
    <collision>
      <origin
        xyz="0 0 0"
        rpy="0 0 0" />
      <geometry>
        <mesh
          filename="package://try11/meshes/sec34.STL" />
      </geometry>
    </collision>
  </link>
  <joint
    name="joint34"
    type="revolute">
    <origin
      xyz="0.01 0 0"
      rpy="0 0 0" />
    <parent
      link="sec33" />
    <child
      link="sec34" />
    <axis
      xyz="0 0 0" />
    <limit
      lower="-1.571"
      upper="1.571"
      effort="100"
      velocity="0" />
  </joint>
  <link
    name="sec35">
    <inertial>
      <origin
        xyz="0.0025 1.38777878078145E-17 -6.93889390390723E-18"
        rpy="0 0 0" />
      <mass
        value="0.0015707963267949" />
      <inertia
        ixx="7.85398163397448E-08"
        ixy="-1.615159831157E-24"
        ixz="1.40937801915213E-23"
        iyy="4.25424005173618E-08"
        iyz="-5.70409964073025E-24"
        izz="4.25424005173618E-08" />
    </inertial>
    <visual>
      <origin
        xyz="0 0 0"
        rpy="0 0 0" />
      <geometry>
        <mesh
          filename="package://try11/meshes/sec35.STL" />
      </geometry>
      <material
        name="">
        <color
          rgba="0.792156862745098 0.819607843137255 0.933333333333333 1" />
      </material>
    </visual>
    <collision>
      <origin
        xyz="0 0 0"
        rpy="0 0 0" />
      <geometry>
        <mesh
          filename="package://try11/meshes/sec35.STL" />
      </geometry>
    </collision>
  </link>
  <joint
    name="joint35"
    type="revolute">
    <origin
      xyz="0.01 0 0"
      rpy="0 0 0" />
    <parent
      link="sec34" />
    <child
      link="sec35" />
    <axis
      xyz="0 0 0" />
    <limit
      lower="-1.571"
      upper="1.571"
      effort="100"
      velocity="0" />
  </joint>
  <link
    name="sec36">
    <inertial>
      <origin
        xyz="0.0025 0 -5.20417042793042E-18"
        rpy="0 0 0" />
      <mass
        value="0.0015707963267949" />
      <inertia
        ixx="7.85398163397449E-08"
        ixy="-1.61515983115699E-24"
        ixz="1.38180533206703E-23"
        iyy="4.25424005173619E-08"
        iyz="-5.70409964073026E-24"
        izz="4.25424005173619E-08" />
    </inertial>
    <visual>
      <origin
        xyz="0 0 0"
        rpy="0 0 0" />
      <geometry>
        <mesh
          filename="package://try11/meshes/sec36.STL" />
      </geometry>
      <material
        name="">
        <color
          rgba="0.792156862745098 0.819607843137255 0.933333333333333 1" />
      </material>
    </visual>
    <collision>
      <origin
        xyz="0 0 0"
        rpy="0 0 0" />
      <geometry>
        <mesh
          filename="package://try11/meshes/sec36.STL" />
      </geometry>
    </collision>
  </link>
  <joint
    name="joint36"
    type="revolute">
    <origin
      xyz="0.01 0 0"
      rpy="0 0 0" />
    <parent
      link="sec35" />
    <child
      link="sec36" />
    <axis
      xyz="0 0 0" />
    <limit
      lower="-1.571"
      upper="1.571"
      effort="100"
      velocity="0" />
  </joint>
  <link
    name="sec37">
    <inertial>
      <origin
        xyz="0.0025 0 -6.93889390390723E-18"
        rpy="0 0 0" />
      <mass
        value="0.0015707963267949" />
      <inertia
        ixx="7.85398163397449E-08"
        ixy="-1.61515983115699E-24"
        ixz="1.38180533206703E-23"
        iyy="4.25424005173619E-08"
        iyz="-5.70409964073026E-24"
        izz="4.25424005173619E-08" />
    </inertial>
    <visual>
      <origin
        xyz="0 0 0"
        rpy="0 0 0" />
      <geometry>
        <mesh
          filename="package://try11/meshes/sec37.STL" />
      </geometry>
      <material
        name="">
        <color
          rgba="0.792156862745098 0.819607843137255 0.933333333333333 1" />
      </material>
    </visual>
    <collision>
      <origin
        xyz="0 0 0"
        rpy="0 0 0" />
      <geometry>
        <mesh
          filename="package://try11/meshes/sec37.STL" />
      </geometry>
    </collision>
  </link>
  <joint
    name="joint37"
    type="revolute">
    <origin
      xyz="0.01 0 0"
      rpy="0 0 0" />
    <parent
      link="sec36" />
    <child
      link="sec37" />
    <axis
      xyz="0 0 0" />
    <limit
      lower="-1.571"
      upper="1.571"
      effort="100"
      velocity="0" />
  </joint>
  <link
    name="sec38">
    <inertial>
      <origin
        xyz="0.0025 0 -5.20417042793042E-18"
        rpy="0 0 0" />
      <mass
        value="0.0015707963267949" />
      <inertia
        ixx="7.85398163397449E-08"
        ixy="-1.61515983115699E-24"
        ixz="1.40937801915213E-23"
        iyy="4.25424005173619E-08"
        iyz="-5.70409964073026E-24"
        izz="4.25424005173619E-08" />
    </inertial>
    <visual>
      <origin
        xyz="0 0 0"
        rpy="0 0 0" />
      <geometry>
        <mesh
          filename="package://try11/meshes/sec38.STL" />
      </geometry>
      <material
        name="">
        <color
          rgba="0.792156862745098 0.819607843137255 0.933333333333333 1" />
      </material>
    </visual>
    <collision>
      <origin
        xyz="0 0 0"
        rpy="0 0 0" />
      <geometry>
        <mesh
          filename="package://try11/meshes/sec38.STL" />
      </geometry>
    </collision>
  </link>
  <joint
    name="joint38"
    type="revolute">
    <origin
      xyz="0.01 0 0"
      rpy="0 0 0" />
    <parent
      link="sec37" />
    <child
      link="sec38" />
    <axis
      xyz="0 0 0" />
    <limit
      lower="-1.571"
      upper="1.571"
      effort="100"
      velocity="0" />
  </joint>
  <link
    name="sec39">
    <inertial>
      <origin
        xyz="0.0025 0 -5.20417042793042E-18"
        rpy="0 0 0" />
      <mass
        value="0.0015707963267949" />
      <inertia
        ixx="7.85398163397449E-08"
        ixy="-1.61515983115699E-24"
        ixz="1.38180533206703E-23"
        iyy="4.25424005173619E-08"
        iyz="-5.70409964073026E-24"
        izz="4.25424005173619E-08" />
    </inertial>
    <visual>
      <origin
        xyz="0 0 0"
        rpy="0 0 0" />
      <geometry>
        <mesh
          filename="package://try11/meshes/sec39.STL" />
      </geometry>
      <material
        name="">
        <color
          rgba="0.792156862745098 0.819607843137255 0.933333333333333 1" />
      </material>
    </visual>
    <collision>
      <origin
        xyz="0 0 0"
        rpy="0 0 0" />
      <geometry>
        <mesh
          filename="package://try11/meshes/sec39.STL" />
      </geometry>
    </collision>
  </link>
  <joint
    name="joint39"
    type="revolute">
    <origin
      xyz="0.01 0 0"
      rpy="0 0 0" />
    <parent
      link="sec38" />
    <child
      link="sec39" />
    <axis
      xyz="0 0 0" />
    <limit
      lower="-1.571"
      upper="1.571"
      effort="100"
      velocity="0" />
  </joint>
  <link
    name="sec40">
    <inertial>
      <origin
        xyz="0.0025 0 -6.93889390390723E-18"
        rpy="0 0 0" />
      <mass
        value="0.0015707963267949" />
      <inertia
        ixx="7.85398163397449E-08"
        ixy="-1.61515983115699E-24"
        ixz="1.38180533206703E-23"
        iyy="4.25424005173619E-08"
        iyz="-5.70409964073025E-24"
        izz="4.25424005173618E-08" />
    </inertial>
    <visual>
      <origin
        xyz="0 0 0"
        rpy="0 0 0" />
      <geometry>
        <mesh
          filename="package://try11/meshes/sec40.STL" />
      </geometry>
      <material
        name="">
        <color
          rgba="0.792156862745098 0.819607843137255 0.933333333333333 1" />
      </material>
    </visual>
    <collision>
      <origin
        xyz="0 0 0"
        rpy="0 0 0" />
      <geometry>
        <mesh
          filename="package://try11/meshes/sec40.STL" />
      </geometry>
    </collision>
  </link>
  <joint
    name="joint40"
    type="revolute">
    <origin
      xyz="0.01 0 0"
      rpy="0 0 0" />
    <parent
      link="sec39" />
    <child
      link="sec40" />
    <axis
      xyz="0 0 0" />
    <limit
      lower="-1.571"
      upper="1.571"
      effort="100"
      velocity="0" />
  </joint>
  <link
    name="sec41">
    <inertial>
      <origin
        xyz="-0.0025 0 0"
        rpy="0 0 0" />
      <mass
        value="0.0015707963267949" />
      <inertia
        ixx="7.85398163397449E-08"
        ixy="3.97357526418547E-26"
        ixz="-3.9175318306672E-24"
        iyy="4.25424005173618E-08"
        iyz="1.82669051938794E-24"
        izz="4.25424005173618E-08" />
    </inertial>
    <visual>
      <origin
        xyz="0 0 0"
        rpy="0 0 0" />
      <geometry>
        <mesh
          filename="package://try11/meshes/sec41.STL" />
      </geometry>
      <material
        name="">
        <color
          rgba="0.792156862745098 0.819607843137255 0.933333333333333 1" />
      </material>
    </visual>
    <collision>
      <origin
        xyz="0 0 0"
        rpy="0 0 0" />
      <geometry>
        <mesh
          filename="package://try11/meshes/sec41.STL" />
      </geometry>
    </collision>
  </link>
  <joint
    name="joint41"
    type="revolute">
    <origin
      xyz="-0.011 0.1 0"
      rpy="0 0 0" />
    <parent
      link="base_link" />
    <child
      link="sec41" />
    <axis
      xyz="1 0 0" />
    <limit
      lower="-1.571"
      upper="1.571"
      effort="100"
      velocity="0" />
  </joint>
  <link
    name="sec42">
    <inertial>
      <origin
        xyz="-0.0025 1.38777878078145E-17 -5.20417042793042E-18"
        rpy="0 0 0" />
      <mass
        value="0.0015707963267949" />
      <inertia
        ixx="7.85398163397449E-08"
        ixy="3.97357526418553E-26"
        ixz="-3.9175318306672E-24"
        iyy="4.25424005173618E-08"
        iyz="-4.23930063933427E-24"
        izz="4.25424005173618E-08" />
    </inertial>
    <visual>
      <origin
        xyz="0 0 0"
        rpy="0 0 0" />
      <geometry>
        <mesh
          filename="package://try11/meshes/sec42.STL" />
      </geometry>
      <material
        name="">
        <color
          rgba="0.792156862745098 0.819607843137255 0.933333333333333 1" />
      </material>
    </visual>
    <collision>
      <origin
        xyz="0 0 0"
        rpy="0 0 0" />
      <geometry>
        <mesh
          filename="package://try11/meshes/sec42.STL" />
      </geometry>
    </collision>
  </link>
  <joint
    name="joint42"
    type="revolute">
    <origin
      xyz="-0.01 0 0"
      rpy="0 0 0" />
    <parent
      link="sec41" />
    <child
      link="sec42" />
    <axis
      xyz="0 0 0" />
    <limit
      lower="-1.571"
      upper="1.571"
      effort="100"
      velocity="0" />
  </joint>
  <link
    name="sec43">
    <inertial>
      <origin
        xyz="-0.0025 1.38777878078145E-17 -6.93889390390723E-18"
        rpy="0 0 0" />
      <mass
        value="0.00157079632679489" />
      <inertia
        ixx="7.85398163397448E-08"
        ixy="5.91189494343873E-25"
        ixz="-5.02043931407123E-24"
        iyy="4.25424005173618E-08"
        iyz="-1.20630505997316E-24"
        izz="4.25424005173617E-08" />
    </inertial>
    <visual>
      <origin
        xyz="0 0 0"
        rpy="0 0 0" />
      <geometry>
        <mesh
          filename="package://try11/meshes/sec43.STL" />
      </geometry>
      <material
        name="">
        <color
          rgba="0.792156862745098 0.819607843137255 0.933333333333333 1" />
      </material>
    </visual>
    <collision>
      <origin
        xyz="0 0 0"
        rpy="0 0 0" />
      <geometry>
        <mesh
          filename="package://try11/meshes/sec43.STL" />
      </geometry>
    </collision>
  </link>
  <joint
    name="joint43"
    type="revolute">
    <origin
      xyz="-0.01 0 0"
      rpy="0 0 0" />
    <parent
      link="sec42" />
    <child
      link="sec43" />
    <axis
      xyz="0 0 0" />
    <limit
      lower="-1.571"
      upper="1.571"
      effort="100"
      velocity="0" />
  </joint>
  <link
    name="sec44">
    <inertial>
      <origin
        xyz="-0.0025 0 -5.20417042793042E-18"
        rpy="0 0 0" />
      <mass
        value="0.0015707963267949" />
      <inertia
        ixx="7.85398163397448E-08"
        ixy="3.15462623492864E-25"
        ixz="-4.46898557236922E-24"
        iyy="4.25424005173618E-08"
        iyz="1.82669051938794E-24"
        izz="4.25424005173618E-08" />
    </inertial>
    <visual>
      <origin
        xyz="0 0 0"
        rpy="0 0 0" />
      <geometry>
        <mesh
          filename="package://try11/meshes/sec44.STL" />
      </geometry>
      <material
        name="">
        <color
          rgba="0.792156862745098 0.819607843137255 0.933333333333333 1" />
      </material>
    </visual>
    <collision>
      <origin
        xyz="0 0 0"
        rpy="0 0 0" />
      <geometry>
        <mesh
          filename="package://try11/meshes/sec44.STL" />
      </geometry>
    </collision>
  </link>
  <joint
    name="joint44"
    type="revolute">
    <origin
      xyz="-0.01 0 0"
      rpy="0 0 0" />
    <parent
      link="sec43" />
    <child
      link="sec44" />
    <axis
      xyz="0 0 0" />
    <limit
      lower="-1.571"
      upper="1.571"
      effort="100"
      velocity="0" />
  </joint>
  <link
    name="sec45">
    <inertial>
      <origin
        xyz="-0.0025 0 -5.20417042793042E-18"
        rpy="0 0 0" />
      <mass
        value="0.0015707963267949" />
      <inertia
        ixx="7.85398163397448E-08"
        ixy="3.15462623492863E-25"
        ixz="-4.46898557236921E-24"
        iyy="4.25424005173618E-08"
        iyz="-4.23930063933427E-24"
        izz="4.25424005173618E-08" />
    </inertial>
    <visual>
      <origin
        xyz="0 0 0"
        rpy="0 0 0" />
      <geometry>
        <mesh
          filename="package://try11/meshes/sec45.STL" />
      </geometry>
      <material
        name="">
        <color
          rgba="0.792156862745098 0.819607843137255 0.933333333333333 1" />
      </material>
    </visual>
    <collision>
      <origin
        xyz="0 0 0"
        rpy="0 0 0" />
      <geometry>
        <mesh
          filename="package://try11/meshes/sec45.STL" />
      </geometry>
    </collision>
  </link>
  <joint
    name="joint45"
    type="revolute">
    <origin
      xyz="-0.01 0 0"
      rpy="0 0 0" />
    <parent
      link="sec44" />
    <child
      link="sec45" />
    <axis
      xyz="0 0 0" />
    <limit
      lower="-1.571"
      upper="1.571"
      effort="100"
      velocity="0" />
  </joint>
  <link
    name="sec46">
    <inertial>
      <origin
        xyz="-0.0025 0 -5.20417042793042E-18"
        rpy="0 0 0" />
      <mass
        value="0.0015707963267949" />
      <inertia
        ixx="7.85398163397448E-08"
        ixy="3.15462623492866E-25"
        ixz="-5.02043931407124E-24"
        iyy="4.25424005173618E-08"
        iyz="-1.20630505997317E-24"
        izz="4.25424005173618E-08" />
    </inertial>
    <visual>
      <origin
        xyz="0 0 0"
        rpy="0 0 0" />
      <geometry>
        <mesh
          filename="package://try11/meshes/sec46.STL" />
      </geometry>
      <material
        name="">
        <color
          rgba="0.792156862745098 0.819607843137255 0.933333333333333 1" />
      </material>
    </visual>
    <collision>
      <origin
        xyz="0 0 0"
        rpy="0 0 0" />
      <geometry>
        <mesh
          filename="package://try11/meshes/sec46.STL" />
      </geometry>
    </collision>
  </link>
  <joint
    name="joint46"
    type="revolute">
    <origin
      xyz="-0.01 0 0"
      rpy="0 0 0" />
    <parent
      link="sec45" />
    <child
      link="sec46" />
    <axis
      xyz="0 0 0" />
    <limit
      lower="-1.571"
      upper="1.571"
      effort="100"
      velocity="0" />
  </joint>
  <link
    name="sec47">
    <inertial>
      <origin
        xyz="-0.0025 -1.38777878078145E-17 -5.20417042793042E-18"
        rpy="0 0 0" />
      <mass
        value="0.0015707963267949" />
      <inertia
        ixx="7.85398163397449E-08"
        ixy="3.15462623492865E-25"
        ixz="-3.9175318306672E-24"
        iyy="4.25424005173618E-08"
        iyz="5.34220812273837E-25"
        izz="4.25424005173618E-08" />
    </inertial>
    <visual>
      <origin
        xyz="0 0 0"
        rpy="0 0 0" />
      <geometry>
        <mesh
          filename="package://try11/meshes/sec47.STL" />
      </geometry>
      <material
        name="">
        <color
          rgba="0.792156862745098 0.819607843137255 0.933333333333333 1" />
      </material>
    </visual>
    <collision>
      <origin
        xyz="0 0 0"
        rpy="0 0 0" />
      <geometry>
        <mesh
          filename="package://try11/meshes/sec47.STL" />
      </geometry>
    </collision>
  </link>
  <joint
    name="joint47"
    type="revolute">
    <origin
      xyz="-0.01 0 0"
      rpy="0 0 0" />
    <parent
      link="sec46" />
    <child
      link="sec47" />
    <axis
      xyz="0 0 0" />
    <limit
      lower="-1.571"
      upper="1.571"
      effort="100"
      velocity="0" />
  </joint>
  <link
    name="sec48">
    <inertial>
      <origin
        xyz="-0.00250000000000002 0 -5.20417042793042E-18"
        rpy="0 0 0" />
      <mass
        value="0.0015707963267949" />
      <inertia
        ixx="7.85398163397449E-08"
        ixy="3.97357526418564E-26"
        ixz="-3.91753183066721E-24"
        iyy="4.25424005173618E-08"
        iyz="-5.53177034644838E-24"
        izz="4.25424005173618E-08" />
    </inertial>
    <visual>
      <origin
        xyz="0 0 0"
        rpy="0 0 0" />
      <geometry>
        <mesh
          filename="package://try11/meshes/sec48.STL" />
      </geometry>
      <material
        name="">
        <color
          rgba="0.792156862745098 0.819607843137255 0.933333333333333 1" />
      </material>
    </visual>
    <collision>
      <origin
        xyz="0 0 0"
        rpy="0 0 0" />
      <geometry>
        <mesh
          filename="package://try11/meshes/sec48.STL" />
      </geometry>
    </collision>
  </link>
  <joint
    name="joint48"
    type="revolute">
    <origin
      xyz="-0.01 0 0"
      rpy="0 0 0" />
    <parent
      link="sec47" />
    <child
      link="sec48" />
    <axis
      xyz="0 0 0" />
    <limit
      lower="-1.571"
      upper="1.571"
      effort="100"
      velocity="0" />
  </joint>
  <link
    name="sec49">
    <inertial>
      <origin
        xyz="-0.00250000000000002 -1.38777878078145E-17 -5.20417042793042E-18"
        rpy="0 0 0" />
      <mass
        value="0.0015707963267949" />
      <inertia
        ixx="7.85398163397449E-08"
        ixy="3.15462623492866E-25"
        ixz="-4.46898557236923E-24"
        iyy="4.25424005173618E-08"
        iyz="-2.49877476708727E-24"
        izz="4.25424005173618E-08" />
    </inertial>
    <visual>
      <origin
        xyz="0 0 0"
        rpy="0 0 0" />
      <geometry>
        <mesh
          filename="package://try11/meshes/sec49.STL" />
      </geometry>
      <material
        name="">
        <color
          rgba="0.792156862745098 0.819607843137255 0.933333333333333 1" />
      </material>
    </visual>
    <collision>
      <origin
        xyz="0 0 0"
        rpy="0 0 0" />
      <geometry>
        <mesh
          filename="package://try11/meshes/sec49.STL" />
      </geometry>
    </collision>
  </link>
  <joint
    name="joint49"
    type="revolute">
    <origin
      xyz="-0.01 0 0"
      rpy="0 0 0" />
    <parent
      link="sec48" />
    <child
      link="sec49" />
    <axis
      xyz="0 0 0" />
    <limit
      lower="-1.571"
      upper="1.571"
      effort="100"
      velocity="0" />
  </joint>
  <link
    name="sec50">
    <inertial>
      <origin
        xyz="-0.00249999999999999 -1.38777878078145E-17 -6.93889390390723E-18"
        rpy="0 0 0" />
      <mass
        value="0.0015707963267949" />
      <inertia
        ixx="7.85398163397449E-08"
        ixy="3.15462623492865E-25"
        ixz="-3.9175318306672E-24"
        iyy="4.25424005173618E-08"
        iyz="5.34220812273837E-25"
        izz="4.25424005173618E-08" />
    </inertial>
    <visual>
      <origin
        xyz="0 0 0"
        rpy="0 0 0" />
      <geometry>
        <mesh
          filename="package://try11/meshes/sec50.STL" />
      </geometry>
      <material
        name="">
        <color
          rgba="0.792156862745098 0.819607843137255 0.933333333333333 1" />
      </material>
    </visual>
    <collision>
      <origin
        xyz="0 0 0"
        rpy="0 0 0" />
      <geometry>
        <mesh
          filename="package://try11/meshes/sec50.STL" />
      </geometry>
    </collision>
  </link>
  <joint
    name="joint50"
    type="revolute">
    <origin
      xyz="-0.01 0 0"
      rpy="0 0 0" />
    <parent
      link="sec49" />
    <child
      link="sec50" />
    <axis
      xyz="0 0 0" />
    <limit
      lower="-1.571"
      upper="1.571"
      effort="100"
      velocity="0" />
  </joint>

<!--transmission definition -->
<transmission name="tran01">
    <type>transmission_interface/SimpleTransmission</type>
    <joint name="joint01">
      <hardwareInterface>hardware_interface/EffortJointInterface</hardwareInterface>
    </joint>
    <actuator name="motor01">
      <hardwareInterface>hardware_interface/EffortJointInterface</hardwareInterface>
      <mechanicalReduction>1</mechanicalReduction>
    </actuator>
  </transmission>
  
  <transmission name="tran02">
    <type>transmission_interface/SimpleTransmission</type>
    <joint name="joint02">
      <hardwareInterface>hardware_interface/EffortJointInterface</hardwareInterface>
    </joint>
    <actuator name="motor02">
      <hardwareInterface>hardware_interface/EffortJointInterface</hardwareInterface>
      <mechanicalReduction>1</mechanicalReduction>
    </actuator>
  </transmission>
  
  <transmission name="tran03">
    <type>transmission_interface/SimpleTransmission</type>
    <joint name="joint03">
      <hardwareInterface>hardware_interface/EffortJointInterface</hardwareInterface>
    </joint>
    <actuator name="motor03">
      <hardwareInterface>hardware_interface/EffortJointInterface</hardwareInterface>
      <mechanicalReduction>1</mechanicalReduction>
    </actuator>
  </transmission>
  
  <transmission name="tran04">
    <type>transmission_interface/SimpleTransmission</type>
    <joint name="joint04">
      <hardwareInterface>hardware_interface/EffortJointInterface</hardwareInterface>
    </joint>
    <actuator name="motor04">
      <hardwareInterface>hardware_interface/EffortJointInterface</hardwareInterface>
      <mechanicalReduction>1</mechanicalReduction>
    </actuator>
  </transmission>
  
  <transmission name="tran05">
    <type>transmission_interface/SimpleTransmission</type>
    <joint name="joint05">
      <hardwareInterface>hardware_interface/EffortJointInterface</hardwareInterface>
    </joint>
    <actuator name="motor05">
      <hardwareInterface>hardware_interface/EffortJointInterface</hardwareInterface>
      <mechanicalReduction>1</mechanicalReduction>
    </actuator>
  </transmission>
  
  <transmission name="tran06">
    <type>transmission_interface/SimpleTransmission</type>
    <joint name="joint06">
      <hardwareInterface>hardware_interface/EffortJointInterface</hardwareInterface>
    </joint>
    <actuator name="motor06">
      <hardwareInterface>hardware_interface/EffortJointInterface</hardwareInterface>
      <mechanicalReduction>1</mechanicalReduction>
    </actuator>
  </transmission>
  
  <transmission name="tran07">
    <type>transmission_interface/SimpleTransmission</type>
    <joint name="joint07">
      <hardwareInterface>hardware_interface/EffortJointInterface</hardwareInterface>
    </joint>
    <actuator name="motor07">
      <hardwareInterface>hardware_interface/EffortJointInterface</hardwareInterface>
      <mechanicalReduction>1</mechanicalReduction>
    </actuator>
  </transmission>
  
  <transmission name="tran08">
    <type>transmission_interface/SimpleTransmission</type>
    <joint name="joint08">
      <hardwareInterface>hardware_interface/EffortJointInterface</hardwareInterface>
    </joint>
    <actuator name="motor08">
      <hardwareInterface>hardware_interface/EffortJointInterface</hardwareInterface>
      <mechanicalReduction>1</mechanicalReduction>
    </actuator>
  </transmission>

  <transmission name="tran09">
    <type>transmission_interface/SimpleTransmission</type>
    <joint name="joint09">
      <hardwareInterface>hardware_interface/EffortJointInterface</hardwareInterface>
    </joint>
    <actuator name="motor09">
      <hardwareInterface>hardware_interface/EffortJointInterface</hardwareInterface>
      <mechanicalReduction>1</mechanicalReduction>
    </actuator>
  </transmission>

  <transmission name="tran10">
    <type>transmission_interface/SimpleTransmission</type>
    <joint name="joint10">
      <hardwareInterface>hardware_interface/EffortJointInterface</hardwareInterface>
    </joint>
    <actuator name="motor10">
      <hardwareInterface>hardware_interface/EffortJointInterface</hardwareInterface>
      <mechanicalReduction>1</mechanicalReduction>
    </actuator>
  </transmission>

<transmission name="tran11">
    <type>transmission_interface/SimpleTransmission</type>
    <joint name="joint11">
      <hardwareInterface>hardware_interface/EffortJointInterface</hardwareInterface>
    </joint>
    <actuator name="motor11">
      <hardwareInterface>hardware_interface/EffortJointInterface</hardwareInterface>
      <mechanicalReduction>1</mechanicalReduction>
    </actuator>
  </transmission>
  
  <transmission name="tran12">
    <type>transmission_interface/SimpleTransmission</type>
    <joint name="joint12">
      <hardwareInterface>hardware_interface/EffortJointInterface</hardwareInterface>
    </joint>
    <actuator name="motor12">
      <hardwareInterface>hardware_interface/EffortJointInterface</hardwareInterface>
      <mechanicalReduction>1</mechanicalReduction>
    </actuator>
  </transmission>
  
  <transmission name="tran13">
    <type>transmission_interface/SimpleTransmission</type>
    <joint name="joint13">
      <hardwareInterface>hardware_interface/EffortJointInterface</hardwareInterface>
    </joint>
    <actuator name="motor13">
      <hardwareInterface>hardware_interface/EffortJointInterface</hardwareInterface>
      <mechanicalReduction>1</mechanicalReduction>
    </actuator>
  </transmission>
  
  <transmission name="tran14">
    <type>transmission_interface/SimpleTransmission</type>
    <joint name="joint14">
      <hardwareInterface>hardware_interface/EffortJointInterface</hardwareInterface>
    </joint>
    <actuator name="motor14">
      <hardwareInterface>hardware_interface/EffortJointInterface</hardwareInterface>
      <mechanicalReduction>1</mechanicalReduction>
    </actuator>
  </transmission>
  
  <transmission name="tran15">
    <type>transmission_interface/SimpleTransmission</type>
    <joint name="joint15">
      <hardwareInterface>hardware_interface/EffortJointInterface</hardwareInterface>
    </joint>
    <actuator name="motor15">
      <hardwareInterface>hardware_interface/EffortJointInterface</hardwareInterface>
      <mechanicalReduction>1</mechanicalReduction>
    </actuator>
  </transmission>
  
  <transmission name="tran16">
    <type>transmission_interface/SimpleTransmission</type>
    <joint name="joint16">
      <hardwareInterface>hardware_interface/EffortJointInterface</hardwareInterface>
    </joint>
    <actuator name="motor16">
      <hardwareInterface>hardware_interface/EffortJointInterface</hardwareInterface>
      <mechanicalReduction>1</mechanicalReduction>
    </actuator>
  </transmission>
  
  <transmission name="tran17">
    <type>transmission_interface/SimpleTransmission</type>
    <joint name="joint17">
      <hardwareInterface>hardware_interface/EffortJointInterface</hardwareInterface>
    </joint>
    <actuator name="motor17">
      <hardwareInterface>hardware_interface/EffortJointInterface</hardwareInterface>
      <mechanicalReduction>1</mechanicalReduction>
    </actuator>
  </transmission>
  
  <transmission name="tran18">
    <type>transmission_interface/SimpleTransmission</type>
    <joint name="joint18">
      <hardwareInterface>hardware_interface/EffortJointInterface</hardwareInterface>
    </joint>
    <actuator name="motor18">
      <hardwareInterface>hardware_interface/EffortJointInterface</hardwareInterface>
      <mechanicalReduction>1</mechanicalReduction>
    </actuator>
  </transmission>

  <transmission name="tran19">
    <type>transmission_interface/SimpleTransmission</type>
    <joint name="joint19">
      <hardwareInterface>hardware_interface/EffortJointInterface</hardwareInterface>
    </joint>
    <actuator name="motor19">
      <hardwareInterface>hardware_interface/EffortJointInterface</hardwareInterface>
      <mechanicalReduction>1</mechanicalReduction>
    </actuator>
  </transmission>

  <transmission name="tran20">
    <type>transmission_interface/SimpleTransmission</type>
    <joint name="joint20">
      <hardwareInterface>hardware_interface/EffortJointInterface</hardwareInterface>
    </joint>
    <actuator name="motor20">
      <hardwareInterface>hardware_interface/EffortJointInterface</hardwareInterface>
      <mechanicalReduction>1</mechanicalReduction>
    </actuator>
  </transmission>

<transmission name="tran21">
    <type>transmission_interface/SimpleTransmission</type>
    <joint name="joint21">
      <hardwareInterface>hardware_interface/EffortJointInterface</hardwareInterface>
    </joint>
    <actuator name="motor21">
      <hardwareInterface>hardware_interface/EffortJointInterface</hardwareInterface>
      <mechanicalReduction>1</mechanicalReduction>
    </actuator>
  </transmission>
  
  <transmission name="tran22">
    <type>transmission_interface/SimpleTransmission</type>
    <joint name="joint22">
      <hardwareInterface>hardware_interface/EffortJointInterface</hardwareInterface>
    </joint>
    <actuator name="motor22">
      <hardwareInterface>hardware_interface/EffortJointInterface</hardwareInterface>
      <mechanicalReduction>1</mechanicalReduction>
    </actuator>
  </transmission>
  
  <transmission name="tran23">
    <type>transmission_interface/SimpleTransmission</type>
    <joint name="joint23">
      <hardwareInterface>hardware_interface/EffortJointInterface</hardwareInterface>
    </joint>
    <actuator name="motor23">
      <hardwareInterface>hardware_interface/EffortJointInterface</hardwareInterface>
      <mechanicalReduction>1</mechanicalReduction>
    </actuator>
  </transmission>
  
  <transmission name="tran24">
    <type>transmission_interface/SimpleTransmission</type>
    <joint name="joint24">
      <hardwareInterface>hardware_interface/EffortJointInterface</hardwareInterface>
    </joint>
    <actuator name="motor24">
      <hardwareInterface>hardware_interface/EffortJointInterface</hardwareInterface>
      <mechanicalReduction>1</mechanicalReduction>
    </actuator>
  </transmission>
  
  <transmission name="tran25">
    <type>transmission_interface/SimpleTransmission</type>
    <joint name="joint25">
      <hardwareInterface>hardware_interface/EffortJointInterface</hardwareInterface>
    </joint>
    <actuator name="motor25">
      <hardwareInterface>hardware_interface/EffortJointInterface</hardwareInterface>
      <mechanicalReduction>1</mechanicalReduction>
    </actuator>
  </transmission>
  
  <transmission name="tran26">
    <type>transmission_interface/SimpleTransmission</type>
    <joint name="joint26">
      <hardwareInterface>hardware_interface/EffortJointInterface</hardwareInterface>
    </joint>
    <actuator name="motor26">
      <hardwareInterface>hardware_interface/EffortJointInterface</hardwareInterface>
      <mechanicalReduction>1</mechanicalReduction>
    </actuator>
  </transmission>
  
  <transmission name="tran27">
    <type>transmission_interface/SimpleTransmission</type>
    <joint name="joint27">
      <hardwareInterface>hardware_interface/EffortJointInterface</hardwareInterface>
    </joint>
    <actuator name="motor27">
      <hardwareInterface>hardware_interface/EffortJointInterface</hardwareInterface>
      <mechanicalReduction>1</mechanicalReduction>
    </actuator>
  </transmission>
  
  <transmission name="tran28">
    <type>transmission_interface/SimpleTransmission</type>
    <joint name="joint28">
      <hardwareInterface>hardware_interface/EffortJointInterface</hardwareInterface>
    </joint>
    <actuator name="motor28">
      <hardwareInterface>hardware_interface/EffortJointInterface</hardwareInterface>
      <mechanicalReduction>1</mechanicalReduction>
    </actuator>
  </transmission>

  <transmission name="tran29">
    <type>transmission_interface/SimpleTransmission</type>
    <joint name="joint29">
      <hardwareInterface>hardware_interface/EffortJointInterface</hardwareInterface>
    </joint>
    <actuator name="motor29">
      <hardwareInterface>hardware_interface/EffortJointInterface</hardwareInterface>
      <mechanicalReduction>1</mechanicalReduction>
    </actuator>
  </transmission>

  <transmission name="tran30">
    <type>transmission_interface/SimpleTransmission</type>
    <joint name="joint30">
      <hardwareInterface>hardware_interface/EffortJointInterface</hardwareInterface>
    </joint>
    <actuator name="motor30">
      <hardwareInterface>hardware_interface/EffortJointInterface</hardwareInterface>
      <mechanicalReduction>1</mechanicalReduction>
    </actuator>
  </transmission>

<transmission name="tran41">
    <type>transmission_interface/SimpleTransmission</type>
    <joint name="joint41">
      <hardwareInterface>hardware_interface/EffortJointInterface</hardwareInterface>
    </joint>
    <actuator name="motor41">
      <hardwareInterface>hardware_interface/EffortJointInterface</hardwareInterface>
      <mechanicalReduction>1</mechanicalReduction>
    </actuator>
  </transmission>
  
  <transmission name="tran42">
    <type>transmission_interface/SimpleTransmission</type>
    <joint name="joint42">
      <hardwareInterface>hardware_interface/EffortJointInterface</hardwareInterface>
    </joint>
    <actuator name="motor42">
      <hardwareInterface>hardware_interface/EffortJointInterface</hardwareInterface>
      <mechanicalReduction>1</mechanicalReduction>
    </actuator>
  </transmission>
  
  <transmission name="tran43">
    <type>transmission_interface/SimpleTransmission</type>
    <joint name="joint43">
      <hardwareInterface>hardware_interface/EffortJointInterface</hardwareInterface>
    </joint>
    <actuator name="motor43">
      <hardwareInterface>hardware_interface/EffortJointInterface</hardwareInterface>
      <mechanicalReduction>1</mechanicalReduction>
    </actuator>
  </transmission>
  
  <transmission name="tran44">
    <type>transmission_interface/SimpleTransmission</type>
    <joint name="joint44">
      <hardwareInterface>hardware_interface/EffortJointInterface</hardwareInterface>
    </joint>
    <actuator name="motor44">
      <hardwareInterface>hardware_interface/EffortJointInterface</hardwareInterface>
      <mechanicalReduction>1</mechanicalReduction>
    </actuator>
  </transmission>
  
  <transmission name="tran45">
    <type>transmission_interface/SimpleTransmission</type>
    <joint name="joint45">
      <hardwareInterface>hardware_interface/EffortJointInterface</hardwareInterface>
    </joint>
    <actuator name="motor45">
      <hardwareInterface>hardware_interface/EffortJointInterface</hardwareInterface>
      <mechanicalReduction>1</mechanicalReduction>
    </actuator>
  </transmission>
  
  <transmission name="tran46">
    <type>transmission_interface/SimpleTransmission</type>
    <joint name="joint46">
      <hardwareInterface>hardware_interface/EffortJointInterface</hardwareInterface>
    </joint>
    <actuator name="motor46">
      <hardwareInterface>hardware_interface/EffortJointInterface</hardwareInterface>
      <mechanicalReduction>1</mechanicalReduction>
    </actuator>
  </transmission>
  
  <transmission name="tran47">
    <type>transmission_interface/SimpleTransmission</type>
    <joint name="joint47">
      <hardwareInterface>hardware_interface/EffortJointInterface</hardwareInterface>
    </joint>
    <actuator name="motor47">
      <hardwareInterface>hardware_interface/EffortJointInterface</hardwareInterface>
      <mechanicalReduction>1</mechanicalReduction>
    </actuator>
  </transmission>
  
  <transmission name="tran48">
    <type>transmission_interface/SimpleTransmission</type>
    <joint name="joint48">
      <hardwareInterface>hardware_interface/EffortJointInterface</hardwareInterface>
    </joint>
    <actuator name="motor48">
      <hardwareInterface>hardware_interface/EffortJointInterface</hardwareInterface>
      <mechanicalReduction>1</mechanicalReduction>
    </actuator>
  </transmission>

  <transmission name="tran49">
    <type>transmission_interface/SimpleTransmission</type>
    <joint name="joint49">
      <hardwareInterface>hardware_interface/EffortJointInterface</hardwareInterface>
    </joint>
    <actuator name="motor49">
      <hardwareInterface>hardware_interface/EffortJointInterface</hardwareInterface>
      <mechanicalReduction>1</mechanicalReduction>
    </actuator>
  </transmission>

  <transmission name="tran50">
    <type>transmission_interface/SimpleTransmission</type>
    <joint name="joint50">
      <hardwareInterface>hardware_interface/EffortJointInterface</hardwareInterface>
    </joint>
    <actuator name="motor50">
      <hardwareInterface>hardware_interface/EffortJointInterface</hardwareInterface>
      <mechanicalReduction>1</mechanicalReduction>
    </actuator>
  </transmission>


<!--cointrol pluging -->
  <gazebo>
  <plugin name="gazebo_ros_control" filename="libgazebo_ros_control.so">

  </plugin>
</gazebo>

<!--
<gazebo reference="sec01">
   <turnGravityOff>true</turnGravityOff>
</gazebo>

<gazebo reference="sec02">
   <turnGravityOff>true</turnGravityOff>
</gazebo>

<gazebo reference="sec03">
   <turnGravityOff>true</turnGravityOff>
</gazebo>

<gazebo reference="sec04">
   <turnGravityOff>true</turnGravityOff>
</gazebo>

<gazebo reference="sec05">
   <turnGravityOff>true</turnGravityOff>
</gazebo>

<gazebo reference="sec06">
   <turnGravityOff>true</turnGravityOff>
</gazebo>

<gazebo reference="sec07">
   <turnGravityOff>true</turnGravityOff>
</gazebo>

<gazebo reference="sec08">
   <turnGravityOff>true</turnGravityOff>
</gazebo>

<gazebo reference="sec09">
   <turnGravityOff>true</turnGravityOff>
</gazebo>

<gazebo reference="sec10">
   <turnGravityOff>true</turnGravityOff>
</gazebo>

<gazebo reference="sec11">
   <turnGravityOff>true</turnGravityOff>
</gazebo>

<gazebo reference="sec12">
   <turnGravityOff>true</turnGravityOff>
</gazebo>

<gazebo reference="sec13">
   <turnGravityOff>true</turnGravityOff>
</gazebo>

<gazebo reference="sec14">
   <turnGravityOff>true</turnGravityOff>
</gazebo>

<gazebo reference="sec15">
   <turnGravityOff>true</turnGravityOff>
</gazebo>

<gazebo reference="sec16">
   <turnGravityOff>true</turnGravityOff>
</gazebo>

<gazebo reference="sec17">
   <turnGravityOff>true</turnGravityOff>
</gazebo>

<gazebo reference="sec18">
   <turnGravityOff>true</turnGravityOff>
</gazebo>

<gazebo reference="sec19">
   <turnGravityOff>true</turnGravityOff>
</gazebo>

<gazebo reference="sec20">
   <turnGravityOff>true</turnGravityOff>
</gazebo>

<gazebo reference="sec21">
   <turnGravityOff>true</turnGravityOff>
</gazebo>

<gazebo reference="sec22">
   <turnGravityOff>true</turnGravityOff>
</gazebo>

<gazebo reference="sec23">
   <turnGravityOff>true</turnGravityOff>
</gazebo>

<gazebo reference="sec24">
   <turnGravityOff>true</turnGravityOff>
</gazebo>

<gazebo reference="sec25">
   <turnGravityOff>true</turnGravityOff>
</gazebo>

<gazebo reference="sec26">
   <turnGravityOff>true</turnGravityOff>
</gazebo>

<gazebo reference="sec27">
   <turnGravityOff>true</turnGravityOff>
</gazebo>

<gazebo reference="sec28">
   <turnGravityOff>true</turnGravityOff>
</gazebo>

<gazebo reference="sec29">
   <turnGravityOff>true</turnGravityOff>
</gazebo>

<gazebo reference="sec30">
   <turnGravityOff>true</turnGravityOff>
</gazebo>

<gazebo reference="sec31">
   <turnGravityOff>true</turnGravityOff>
</gazebo>

<gazebo reference="sec32">
   <turnGravityOff>true</turnGravityOff>
</gazebo>

<gazebo reference="sec33">
   <turnGravityOff>true</turnGravityOff>
</gazebo>

<gazebo reference="sec034">
   <turnGravityOff>true</turnGravityOff>
</gazebo>

<gazebo reference="sec35">
   <turnGravityOff>true</turnGravityOff>
</gazebo>

<gazebo reference="sec36">
   <turnGravityOff>true</turnGravityOff>
</gazebo>

<gazebo reference="sec37">
   <turnGravityOff>true</turnGravityOff>
</gazebo>

<gazebo reference="sec38">
   <turnGravityOff>true</turnGravityOff>
</gazebo>

<gazebo reference="sec39">
   <turnGravityOff>true</turnGravityOff>
</gazebo>

<gazebo reference="sec40">
   <turnGravityOff>true</turnGravityOff>
</gazebo>

<gazebo reference="sec41">
   <turnGravityOff>true</turnGravityOff>
</gazebo>

<gazebo reference="sec42">
   <turnGravityOff>true</turnGravityOff>
</gazebo>

<gazebo reference="sec43">
   <turnGravityOff>true</turnGravityOff>
</gazebo>

<gazebo reference="sec44">
   <turnGravityOff>true</turnGravityOff>
</gazebo>

<gazebo reference="sec45">
   <turnGravityOff>true</turnGravityOff>
</gazebo>

<gazebo reference="sec46">
   <turnGravityOff>true</turnGravityOff>
</gazebo>

<gazebo reference="sec47">
   <turnGravityOff>true</turnGravityOff>
</gazebo>

<gazebo reference="sec48">
   <turnGravityOff>true</turnGravityOff>
</gazebo>

<gazebo reference="sec49">
   <turnGravityOff>true</turnGravityOff>
</gazebo>

<gazebo reference="sec50">
   <turnGravityOff>true</turnGravityOff>
</gazebo>

-->

</robot>