<?xml version="1.0" encoding="utf-8"?>
<!-- This URDF was automatically created by SolidWorks to URDF Exporter! Originally created by Stephen Brawner (brawner@gmail.com) 
     Commit Version: 1.6.0-4-g7f85cfe  Build Version: 1.6.7995.38578
     For more information, please see http://wiki.ros.org/sw_urdf_exporter -->
<robot
  name="tripod">
  <link
    name="base_link">
    <inertial>
      <origin
        xyz="-0.00270335216481961 0.0427484175864133 -0.0187131450927378"
        rpy="0 0 0" />
      <mass
        value="4.94527215790382" />
      <inertia
        ixx="0.0216096734231236"
        ixy="-3.17234256778802E-07"
        ixz="-1.89142226728924E-13"
        iyy="0.0356919850335974"
        iyz="2.07476617614103E-17"
        izz="0.0216096734261006" />
    </inertial>
    <visual>
      <origin
        xyz="0 0 0"
        rpy="0 0 0" />
      <geometry>
        <mesh
          filename="package://tripod/meshes/base_link.STL" />
      </geometry>
      <material
        name="">
        <color
          rgba="0.898039215686275 0.917647058823529 0.929411764705882 1" />
      </material>
    </visual>
    <collision>
      <origin
        xyz="0 0 0"
        rpy="0 0 0" />
      <geometry>
        <mesh
          filename="package://tripod/meshes/base_link.STL" />
      </geometry>
    </collision>
  </link>
  <link
    name="sec01">
    <inertial>
      <origin
        xyz="-0.094705 -0.052468 -0.093525"
        rpy="0 0 0" />
      <mass
        value="2.7579" />
      <inertia
        ixx="0.014805"
        ixy="0.00022048"
        ixz="0.00045793"
        iyy="0.0096104"
        iyz="-0.0045843"
        izz="0.005584" />
    </inertial>
    <visual>
      <origin
        xyz="0 0 0"
        rpy="0 0 0" />
      <geometry>
        <mesh
          filename="package://tripod/meshes/sec01.STL" />
      </geometry>
      <material
        name="">
        <color
          rgba="0.79216 0.81961 0.93333 1" />
      </material>
    </visual>
    <collision>
      <origin
        xyz="0 0 0"
        rpy="0 0 0" />
      <geometry>
        <mesh
          filename="package://tripod/meshes/sec01.STL" />
      </geometry>
    </collision>
  </link>
  <joint
    name="joint01"
    type="revolute">
    <origin
      xyz="0.098178 -0.27841 0.03456"
      rpy="0 0 0" />
    <parent
      link="base_link" />
    <child
      link="sec01" />
    <axis
      xyz="-0.99881 0 -0.048681" />
    <limit
      lower="-1.571"
      upper="1.571"
      effort="100"
      velocity="100" />
  </joint>
  <link
    name="sec02">
    <inertial>
      <origin
        xyz="-0.0985182182283333 -0.0398308537647168 -0.0960286676395726"
        rpy="0 0 0" />
      <mass
        value="2.75788789744611" />
      <inertia
        ixx="0.0148272065372122"
        ixy="2.20998730259361E-05"
        ixz="7.59922459832986E-05"
        iyy="0.0107833819100957"
        iyz="-0.00385947138150121"
        izz="0.00438894970023682" />
    </inertial>
    <visual>
      <origin
        xyz="0 0 0"
        rpy="0 0 0" />
      <geometry>
        <mesh
          filename="package://tripod/meshes/sec02.STL" />
      </geometry>
      <material
        name="">
        <color
          rgba="0.792156862745098 0.819607843137255 0.933333333333333 1" />
      </material>
    </visual>
    <collision>
      <origin
        xyz="0 0 0"
        rpy="0 0 0" />
      <geometry>
        <mesh
          filename="package://tripod/meshes/sec02.STL" />
      </geometry>
    </collision>
  </link>
  <joint
    name="joint02"
    type="revolute">
    <origin
      xyz="0.20411 0.25474 0.030305"
      rpy="0 0 2.0944" />
    <parent
      link="base_link" />
    <child
      link="sec02" />
    <axis
      xyz="-0.99998 0 -0.0065576" />
    <limit
      lower="-1.571"
      upper="1.571"
      effort="100"
      velocity="100" />
  </joint>
  <link
    name="sec03">
    <inertial>
      <origin
        xyz="-0.0929626300476873 -0.0421957803001139 -0.100335497327203"
        rpy="0 0 0" />
      <mass
        value="2.75486605609328" />
      <inertia
        ixx="0.0147858265246152"
        ixy="0.000250824516184273"
        ixz="0.000653588727171103"
        iyy="0.0105842646532273"
        iyz="-0.00400935356636405"
        izz="0.00462917101397312" />
    </inertial>
    <visual>
      <origin
        xyz="0 0 0"
        rpy="0 0 0" />
      <geometry>
        <mesh
          filename="package://tripod/meshes/sec03.STL" />
      </geometry>
      <material
        name="">
        <color
          rgba="0.792156862745098 0.819607843137255 0.933333333333333 1" />
      </material>
    </visual>
    <collision>
      <origin
        xyz="0 0 0"
        rpy="0 0 0" />
      <geometry>
        <mesh
          filename="package://tripod/meshes/sec03.STL" />
      </geometry>
    </collision>
  </link>
  <joint
    name="joint03"
    type="revolute">
    <origin
      xyz="-0.31042 0.079981 0.036029"
      rpy="0 0 -2.0944" />
    <parent
      link="base_link" />
    <child
      link="sec03" />
    <axis
      xyz="-0.998 0 -0.063223" />
    <limit
      lower="-1.571"
      upper="1.571"
      effort="100"
      velocity="100" />
  </joint>
</robot>