<?xml version="1.0" encoding="utf-8"?>
<!-- This URDF was automatically created by SolidWorks to URDF Exporter! Originally created by Stephen Brawner (brawner@gmail.com) 
     Commit Version: 1.6.0-4-g7f85cfe  Build Version: 1.6.7995.38578
     For more information, please see http://wiki.ros.org/sw_urdf_exporter -->
<robot
  name="virtualnewref">
  <link
    name="base_link">
    <inertial>
      <origin
        xyz="0.00255227024020099 0 0.0352078548457962"
        rpy="0 0 0" />
      <mass
        value="0.960332741228718" />
      <inertia
        ixx="0.00977577773789365"
        ixy="1.42988412284507E-19"
        ixz="-0.000928977867051056"
        iyy="0.00864442039964913"
        iyz="-2.48014911552149E-18"
        izz="0.00488912432140511" />
    </inertial>
    <visual>
      <origin
        xyz="0 0 0"
        rpy="0 0 0" />
      <geometry>
        <mesh
          filename="package://virtualnewref/meshes/base_link.STL" />
      </geometry>
      <material
        name="">
        <color
          rgba="0.792156862745098 0.819607843137255 0.933333333333333 1" />
      </material>
    </visual>
    <collision>
      <origin
        xyz="0 0 0"
        rpy="0 0 0" />
      <geometry>
        <mesh
          filename="package://virtualnewref/meshes/base_link.STL" />
      </geometry>
    </collision>
  </link>
  <link
    name="sec01">
    <inertial>
      <origin
        xyz="0 0 0.00500000000000006"
        rpy="0 0 0" />
      <mass
        value="0.0196349540849362" />
      <inertia
        ixx="3.23158619314575E-06"
        ixy="0"
        ixz="6.44898432852067E-39"
        iyy="3.23158619314575E-06"
        iyz="-4.74299031266813E-39"
        izz="6.13592315154257E-06" />
    </inertial>
    <visual>
      <origin
        xyz="0 0 0"
        rpy="0 0 0" />
      <geometry>
        <mesh
          filename="package://virtualnewref/meshes/sec01.STL" />
      </geometry>
      <material
        name="">
        <color
          rgba="0.792156862745098 0.819607843137255 0.933333333333333 1" />
      </material>
    </visual>
    <collision>
      <origin
        xyz="0 0 0"
        rpy="0 0 0" />
      <geometry>
        <mesh
          filename="package://virtualnewref/meshes/sec01.STL" />
      </geometry>
    </collision>
  </link>

  <!--
    <link name="dummy" type="fixed"/>  
	<joint name="dummy_to_base_link=" type="fixed">  
	<origin
        xyz="0 0 0"
        rpy="0 0 0" />
    	<parent link="dummy"/>  
     	<child link="base_link"/>  
	</joint>
    </link>
	-->

  <joint
    name="joint01"
    type="revolute">
    <origin
      xyz="0.080717 0 0.4"
      rpy="0 0 0" />
    <parent
      link="base_link" />
    <child
      link="sec01" />
    <axis
      xyz="0 0 0" />
	<dynamics damping="0.01" friction="0.1"/>
    <limit
      lower="-1.571"
      upper="1.571"
      effort="100"
      velocity="0" />
  </joint>
  <link
    name="sec02">
    <inertial>
      <origin
        xyz="0 0 0.005"
        rpy="0 0 0" />
      <mass
        value="0.0196349540849362" />
      <inertia
        ixx="3.23158619314575E-06"
        ixy="0"
        ixz="6.44898432852067E-39"
        iyy="3.23158619314575E-06"
        iyz="-4.74299031266813E-39"
        izz="6.13592315154257E-06" />
    </inertial>
    <visual>
      <origin
        xyz="0 0 0"
        rpy="0 0 0" />
      <geometry>
        <mesh
          filename="package://virtualnewref/meshes/sec02.STL" />
      </geometry>
      <material
        name="">
        <color
          rgba="0.792156862745098 0.819607843137255 0.933333333333333 1" />
      </material>
    </visual>
    <collision>
      <origin
        xyz="0 0 0"
        rpy="0 0 0" />
      <geometry>
        <mesh
          filename="package://virtualnewref/meshes/sec02.STL" />
      </geometry>
    </collision>
  </link>
  <joint
    name="joint02"
    type="revolute">
    <origin
      xyz="0 0 -0.02"
      rpy="0 0 0" />
    <parent
      link="sec01" />
    <child
      link="sec02" />
    <axis
      xyz="0 0 0" />
	<dynamics damping="0.01" friction="0.1"/>
    <limit
      lower="-1.571"
      upper="1.571"
      effort="100"
      velocity="0" />
  </joint>
  <link
    name="sec03">
    <inertial>
      <origin
        xyz="0 0 0.005"
        rpy="0 0 0" />
      <mass
        value="0.0196349540849362" />
      <inertia
        ixx="3.23158619314575E-06"
        ixy="0"
        ixz="6.44898432852067E-39"
        iyy="3.23158619314575E-06"
        iyz="-4.74299031266813E-39"
        izz="6.13592315154257E-06" />
    </inertial>
    <visual>
      <origin
        xyz="0 0 0"
        rpy="0 0 0" />
      <geometry>
        <mesh
          filename="package://virtualnewref/meshes/sec03.STL" />
      </geometry>
      <material
        name="">
        <color
          rgba="0.792156862745098 0.819607843137255 0.933333333333333 1" />
      </material>
    </visual>
    <collision>
      <origin
        xyz="0 0 0"
        rpy="0 0 0" />
      <geometry>
        <mesh
          filename="package://virtualnewref/meshes/sec03.STL" />
      </geometry>
    </collision>
  </link>
  <joint
    name="joint03"
    type="revolute">
    <origin
      xyz="0 0 -0.02"
      rpy="0 0 0" />
    <parent
      link="sec02" />
    <child
      link="sec03" />
    <axis
      xyz="0 0 0" />
	<dynamics damping="0.01" friction="0.1"/>
    <limit
      lower="-1.571"
      upper="1.571"
      effort="100"
      velocity="0" />
  </joint>
  <link
    name="sec04">
    <inertial>
      <origin
        xyz="0 0 0.005"
        rpy="0 0 0" />
      <mass
        value="0.019635" />
      <inertia
        ixx="3.2316E-06"
        ixy="0"
        ixz="6.449E-39"
        iyy="3.2316E-06"
        iyz="-4.743E-39"
        izz="6.1359E-06" />
    </inertial>
    <visual>
      <origin
        xyz="0 0 0"
        rpy="0 0 0" />
      <geometry>
        <mesh
          filename="package://virtualnewref/meshes/sec04.STL" />
      </geometry>
      <material
        name="">
        <color
          rgba="0.79216 0.81961 0.93333 1" />
      </material>
    </visual>
    <collision>
      <origin
        xyz="0 0 0"
        rpy="0 0 0" />
      <geometry>
        <mesh
          filename="package://virtualnewref/meshes/sec04.STL" />
      </geometry>
    </collision>
  </link>
  <joint
    name="joint04"
    type="revolute">
    <origin
      xyz="0 0 -0.02"
      rpy="0 0 0" />
    <parent
      link="sec03" />
    <child
      link="sec04" />
    <axis
      xyz="0 0 0" />
	<dynamics damping="0.01" friction="0.1"/>
    <limit
      lower="-1.571"
      upper="1.571"
      effort="100"
      velocity="0" />
  </joint>
  <link
    name="sec05">
    <inertial>
      <origin
        xyz="0 0 0.00499999999999995"
        rpy="0 0 0" />
      <mass
        value="0.0196349540849362" />
      <inertia
        ixx="3.23158619314575E-06"
        ixy="0"
        ixz="6.44898432852067E-39"
        iyy="3.23158619314575E-06"
        iyz="-4.74299031266813E-39"
        izz="6.13592315154257E-06" />
    </inertial>
    <visual>
      <origin
        xyz="0 0 0"
        rpy="0 0 0" />
      <geometry>
        <mesh
          filename="package://virtualnewref/meshes/sec05.STL" />
      </geometry>
      <material
        name="">
        <color
          rgba="0.792156862745098 0.819607843137255 0.933333333333333 1" />
      </material>
    </visual>
    <collision>
      <origin
        xyz="0 0 0"
        rpy="0 0 0" />
      <geometry>
        <mesh
          filename="package://virtualnewref/meshes/sec05.STL" />
      </geometry>
    </collision>
  </link>
  <joint
    name="joint05"
    type="revolute">
    <origin
      xyz="0 0 -0.02"
      rpy="0 0 0" />
    <parent
      link="sec04" />
    <child
      link="sec05" />
    <axis
      xyz="0 0 0" />
	<dynamics damping="0.01" friction="0.1"/>
    <limit
      lower="-1.571"
      upper="1.571"
      effort="100"
      velocity="0" />
  </joint>
  <link
    name="sec06">
    <inertial>
      <origin
        xyz="0 0 0.005"
        rpy="0 0 0" />
      <mass
        value="0.0196349540849362" />
      <inertia
        ixx="3.23158619314575E-06"
        ixy="0"
        ixz="6.44898432852067E-39"
        iyy="3.23158619314575E-06"
        iyz="-4.74299031266813E-39"
        izz="6.13592315154257E-06" />
    </inertial>
    <visual>
      <origin
        xyz="0 0 0"
        rpy="0 0 0" />
      <geometry>
        <mesh
          filename="package://virtualnewref/meshes/sec06.STL" />
      </geometry>
      <material
        name="">
        <color
          rgba="0.792156862745098 0.819607843137255 0.933333333333333 1" />
      </material>
    </visual>
    <collision>
      <origin
        xyz="0 0 0"
        rpy="0 0 0" />
      <geometry>
        <mesh
          filename="package://virtualnewref/meshes/sec06.STL" />
      </geometry>
    </collision>
  </link>
  <joint
    name="joint06"
    type="revolute">
    <origin
      xyz="0 0 -0.02"
      rpy="0 0 0" />
    <parent
      link="sec05" />
    <child
      link="sec06" />
    <axis
      xyz="0 0 0" />
	<dynamics damping="0.01" friction="0.1"/>
    <limit
      lower="-1.571"
      upper="1.571"
      effort="100"
      velocity="0" />
  </joint>
  <link
    name="sec07">
    <inertial>
      <origin
        xyz="0 0 0.005"
        rpy="0 0 0" />
      <mass
        value="0.019635" />
      <inertia
        ixx="3.2316E-06"
        ixy="0"
        ixz="6.449E-39"
        iyy="3.2316E-06"
        iyz="-4.743E-39"
        izz="6.1359E-06" />
    </inertial>
    <visual>
      <origin
        xyz="0 0 0"
        rpy="0 0 0" />
      <geometry>
        <mesh
          filename="package://virtualnewref/meshes/sec07.STL" />
      </geometry>
      <material
        name="">
        <color
          rgba="0.79216 0.81961 0.93333 1" />
      </material>
    </visual>
    <collision>
      <origin
        xyz="0 0 0"
        rpy="0 0 0" />
      <geometry>
        <mesh
          filename="package://virtualnewref/meshes/sec07.STL" />
      </geometry>
    </collision>
  </link>
  <joint
    name="joint07"
    type="revolute">
    <origin
      xyz="0 0 -0.02"
      rpy="0 0 0" />
    <parent
      link="sec06" />
    <child
      link="sec07" />
    <axis
      xyz="0 0 0" />
	<dynamics damping="0.01" friction="0.1"/>
    <limit
      lower="-1.571"
      upper="1.571"
      effort="100"
      velocity="0" />
  </joint>
  <link
    name="sec08">
    <inertial>
      <origin
        xyz="0 0 0.005"
        rpy="0 0 0" />
      <mass
        value="0.0196349540849362" />
      <inertia
        ixx="3.23158619314575E-06"
        ixy="0"
        ixz="6.44898432852067E-39"
        iyy="3.23158619314575E-06"
        iyz="-4.74299031266813E-39"
        izz="6.13592315154257E-06" />
    </inertial>
    <visual>
      <origin
        xyz="0 0 0"
        rpy="0 0 0" />
      <geometry>
        <mesh
          filename="package://virtualnewref/meshes/sec08.STL" />
      </geometry>
      <material
        name="">
        <color
          rgba="0.792156862745098 0.819607843137255 0.933333333333333 1" />
      </material>
    </visual>
    <collision>
      <origin
        xyz="0 0 0"
        rpy="0 0 0" />
      <geometry>
        <mesh
          filename="package://virtualnewref/meshes/sec08.STL" />
      </geometry>
    </collision>
  </link>
  <joint
    name="joint08"
    type="revolute">
    <origin
      xyz="0 0 -0.02"
      rpy="0 0 0" />
    <parent
      link="sec07" />
    <child
      link="sec08" />
    <axis
      xyz="0 0 0" />
	<dynamics damping="0.01" friction="0.1"/>
    <limit
      lower="-1.571"
      upper="1.571"
      effort="100"
      velocity="0" />
  </joint>
  <link
    name="sec09">
    <inertial>
      <origin
        xyz="0 0 0.00499999999999998"
        rpy="0 0 0" />
      <mass
        value="0.0196349540849362" />
      <inertia
        ixx="3.23158619314575E-06"
        ixy="3.3136311751555E-53"
        ixz="-2.22427428810535E-37"
        iyy="3.23158619314574E-06"
        iyz="-4.74299031266811E-39"
        izz="6.13592315154255E-06" />
    </inertial>
    <visual>
      <origin
        xyz="0 0 0"
        rpy="0 0 0" />
      <geometry>
        <mesh
          filename="package://virtualnewref/meshes/sec09.STL" />
      </geometry>
      <material
        name="">
        <color
          rgba="0.792156862745098 0.819607843137255 0.933333333333333 1" />
      </material>
    </visual>
    <collision>
      <origin
        xyz="0 0 0"
        rpy="0 0 0" />
      <geometry>
        <mesh
          filename="package://virtualnewref/meshes/sec09.STL" />
      </geometry>
    </collision>
  </link>
  <joint
    name="joint09"
    type="revolute">
    <origin
      xyz="0 0 -0.02"
      rpy="0 0 0" />
    <parent
      link="sec08" />
    <child
      link="sec09" />
    <axis
      xyz="0 1 0" />
	<dynamics damping="0.01" friction="0.1"/>
    <limit
      lower="-1.571"
      upper="1.571"
      effort="100"
      velocity="0" />
  </joint>
  <link
    name="sec10">
    <inertial>
      <origin
        xyz="0 0 0.00499999999999995"
        rpy="0 0 0" />
      <mass
        value="0.0196349540849362" />
      <inertia
        ixx="3.23158619314575E-06"
        ixy="0"
        ixz="6.44898432852067E-39"
        iyy="3.23158619314575E-06"
        iyz="-4.74299031266813E-39"
        izz="6.13592315154257E-06" />
    </inertial>
    <visual>
      <origin
        xyz="0 0 0"
        rpy="0 0 0" />
      <geometry>
        <mesh
          filename="package://virtualnewref/meshes/sec10.STL" />
      </geometry>
      <material
        name="">
        <color
          rgba="0.792156862745098 0.819607843137255 0.933333333333333 1" />
      </material>
    </visual>
    <collision>
      <origin
        xyz="0 0 0"
        rpy="0 0 0" />
      <geometry>
        <mesh
          filename="package://virtualnewref/meshes/sec10.STL" />
      </geometry>
    </collision>
  </link>
  <joint
    name="joint10"
    type="revolute">
    <origin
      xyz="0 0 -0.02"
      rpy="0 0 0" />
    <parent
      link="sec09" />
    <child
      link="sec10" />
    <axis
      xyz="0 1 0" />
	<dynamics damping="0.01" friction="0.1"/>
    <limit
      lower="-1.571"
      upper="1.571"
      effort="100"
      velocity="0" />
  </joint>

<!--transmission definition -->
<transmission name="tran01">
    <type>transmission_interface/SimpleTransmission</type>
    <joint name="joint01">
      <hardwareInterface>hardware_interface/EffortJointInterface</hardwareInterface>
    </joint>
    <actuator name="motor01">
      <hardwareInterface>hardware_interface/EffortJointInterface</hardwareInterface>
      <mechanicalReduction>1</mechanicalReduction>
    </actuator>
  </transmission>
  
  <transmission name="tran02">
    <type>transmission_interface/SimpleTransmission</type>
    <joint name="joint02">
      <hardwareInterface>hardware_interface/EffortJointInterface</hardwareInterface>
    </joint>
    <actuator name="motor02">
      <hardwareInterface>hardware_interface/EffortJointInterface</hardwareInterface>
      <mechanicalReduction>1</mechanicalReduction>
    </actuator>
  </transmission>
  
  <transmission name="tran03">
    <type>transmission_interface/SimpleTransmission</type>
    <joint name="joint03">
      <hardwareInterface>hardware_interface/EffortJointInterface</hardwareInterface>
    </joint>
    <actuator name="motor03">
      <hardwareInterface>hardware_interface/EffortJointInterface</hardwareInterface>
      <mechanicalReduction>1</mechanicalReduction>
    </actuator>
  </transmission>
  
  <transmission name="tran04">
    <type>transmission_interface/SimpleTransmission</type>
    <joint name="joint04">
      <hardwareInterface>hardware_interface/EffortJointInterface</hardwareInterface>
    </joint>
    <actuator name="motor04">
      <hardwareInterface>hardware_interface/EffortJointInterface</hardwareInterface>
      <mechanicalReduction>1</mechanicalReduction>
    </actuator>
  </transmission>
  
  <transmission name="tran05">
    <type>transmission_interface/SimpleTransmission</type>
    <joint name="joint05">
      <hardwareInterface>hardware_interface/EffortJointInterface</hardwareInterface>
    </joint>
    <actuator name="motor05">
      <hardwareInterface>hardware_interface/EffortJointInterface</hardwareInterface>
      <mechanicalReduction>1</mechanicalReduction>
    </actuator>
  </transmission>
  
  <transmission name="tran06">
    <type>transmission_interface/SimpleTransmission</type>
    <joint name="joint06">
      <hardwareInterface>hardware_interface/EffortJointInterface</hardwareInterface>
    </joint>
    <actuator name="motor06">
      <hardwareInterface>hardware_interface/EffortJointInterface</hardwareInterface>
      <mechanicalReduction>1</mechanicalReduction>
    </actuator>
  </transmission>
  
  <transmission name="tran07">
    <type>transmission_interface/SimpleTransmission</type>
    <joint name="joint07">
      <hardwareInterface>hardware_interface/EffortJointInterface</hardwareInterface>
    </joint>
    <actuator name="motor07">
      <hardwareInterface>hardware_interface/EffortJointInterface</hardwareInterface>
      <mechanicalReduction>1</mechanicalReduction>
    </actuator>
  </transmission>
  
  <transmission name="tran08">
    <type>transmission_interface/SimpleTransmission</type>
    <joint name="joint08">
      <hardwareInterface>hardware_interface/EffortJointInterface</hardwareInterface>
    </joint>
    <actuator name="motor08">
      <hardwareInterface>hardware_interface/EffortJointInterface</hardwareInterface>
      <mechanicalReduction>1</mechanicalReduction>
    </actuator>
  </transmission>

  <transmission name="tran09">
    <type>transmission_interface/SimpleTransmission</type>
    <joint name="joint09">
      <hardwareInterface>hardware_interface/EffortJointInterface</hardwareInterface>
    </joint>
    <actuator name="motor09">
      <hardwareInterface>hardware_interface/EffortJointInterface</hardwareInterface>
      <mechanicalReduction>1</mechanicalReduction>
    </actuator>
  </transmission>

  <transmission name="tran10">
    <type>transmission_interface/SimpleTransmission</type>
    <joint name="joint10">
      <hardwareInterface>hardware_interface/EffortJointInterface</hardwareInterface>
    </joint>
    <actuator name="motor10">
      <hardwareInterface>hardware_interface/EffortJointInterface</hardwareInterface>
      <mechanicalReduction>1</mechanicalReduction>
    </actuator>
  </transmission>


<!--cointrol pluging -->
  <gazebo>
  <plugin name="gazebo_ros_control" filename="libgazebo_ros_control.so">

  </plugin>
</gazebo>

<!--
<gazebo reference="sec01">
   <turnGravityOff>true</turnGravityOff>
</gazebo>

<gazebo reference="sec02">
   <turnGravityOff>true</turnGravityOff>
</gazebo>

<gazebo reference="sec03">
   <turnGravityOff>true</turnGravityOff>
</gazebo>

<gazebo reference="sec04">
   <turnGravityOff>true</turnGravityOff>
</gazebo>

<gazebo reference="sec05">
   <turnGravityOff>true</turnGravityOff>
</gazebo>

<gazebo reference="sec06">
   <turnGravityOff>true</turnGravityOff>
</gazebo>

<gazebo reference="sec07">
   <turnGravityOff>true</turnGravityOff>
</gazebo>

<gazebo reference="sec08">
   <turnGravityOff>true</turnGravityOff>
</gazebo>

<gazebo reference="sec09">
   <turnGravityOff>true</turnGravityOff>
</gazebo>

<gazebo reference="sec10">
   <turnGravityOff>true</turnGravityOff>
</gazebo>

-->
</robot>