<?xml version="1.0" encoding="utf-8"?>
<!-- This URDF was automatically created by SolidWorks to URDF Exporter! Originally created by Stephen Brawner (brawner@gmail.com) 
     Commit Version: 1.6.0-4-g7f85cfe  Build Version: 1.6.7995.38578
     For more information, please see http://wiki.ros.org/sw_urdf_exporter -->
<robot
  name="virtual3">
  <link
    name="base_link">
    <inertial>
      <origin
        xyz="0.00255227024020097 0.0352078548457962 3.46944695195361E-17"
        rpy="0 0 0" />
      <mass
        value="0.960332741228718" />
      <inertia
        ixx="0.00977577773789367"
        ixy="-0.000928977867051058"
        ixz="-1.19338127452496E-19"
        iyy="0.00488912432140511"
        iyz="2.35718986143013E-18"
        izz="0.00864442039964914" />
    </inertial>
    <visual>
      <origin
        xyz="0 0 0"
        rpy="0 0 0" />
      <geometry>
        <mesh
          filename="package://virtual3/meshes/base_link.STL" />
      </geometry>
      <material
        name="">
        <color
          rgba="0.792156862745098 0.819607843137255 0.933333333333333 1" />
      </material>
    </visual>
    <collision>
      <origin
        xyz="0 0 0"
        rpy="0 0 0" />
      <geometry>
        <mesh
          filename="package://virtual3/meshes/base_link.STL" />
      </geometry>
    </collision>
  </link>
  <link
    name="sec01">
    <inertial>
      <origin
        xyz="0 0.0200000000000001 0"
        rpy="0 0 0" />
      <mass
        value="0.0196349540849362" />
      <inertia
        ixx="3.23158619314575E-06"
        ixy="6.44898432852067E-39"
        ixz="0"
        iyy="6.13592315154257E-06"
        iyz="4.74299031266813E-39"
        izz="3.23158619314575E-06" />
    </inertial>
    <visual>
      <origin
        xyz="0 0 0"
        rpy="0 0 0" />
      <geometry>
        <mesh
          filename="package://virtual3/meshes/sec01.STL" />
      </geometry>
      <material
        name="">
        <color
          rgba="0.792156862745098 0.819607843137255 0.933333333333333 1" />
      </material>
    </visual>
    <collision>
      <origin
        xyz="0 0 0"
        rpy="0 0 0" />
      <geometry>
        <mesh
          filename="package://virtual3/meshes/sec01.STL" />
      </geometry>
    </collision>
  </link>
  <joint
    name="joint01"
    type="continuous">
    <origin
      xyz="0.080717 0.385 0"
      rpy="0 0 0" />
    <parent
      link="base_link" />
    <child
      link="sec01" />
    <axis
      xyz="0 1 0" />
    <limit
      lower="-1.571"
      upper="1.571"
      effort="100"
      velocity="0" />
  </joint>
  <link
    name="sec02">
    <inertial>
      <origin
        xyz="0 0.005 0"
        rpy="0 0 0" />
      <mass
        value="0.0196349540849362" />
      <inertia
        ixx="3.23158619314575E-06"
        ixy="6.44898432852067E-39"
        ixz="0"
        iyy="6.13592315154257E-06"
        iyz="4.74299031266813E-39"
        izz="3.23158619314575E-06" />
    </inertial>
    <visual>
      <origin
        xyz="0 0 0"
        rpy="0 0 0" />
      <geometry>
        <mesh
          filename="package://virtual3/meshes/sec02.STL" />
      </geometry>
      <material
        name="">
        <color
          rgba="0.792156862745098 0.819607843137255 0.933333333333333 1" />
      </material>
    </visual>
    <collision>
      <origin
        xyz="0 0 0"
        rpy="0 0 0" />
      <geometry>
        <mesh
          filename="package://virtual3/meshes/sec02.STL" />
      </geometry>
    </collision>
  </link>
  <joint
    name="joint02"
    type="revolute">
    <origin
      xyz="0 -0.02 0"
      rpy="0 0 0" />
    <parent
      link="sec01" />
    <child
      link="sec02" />
    <axis
      xyz="0 0 0" />
    <limit
      lower="-1.571"
      upper="1.571"
      effort="100"
      velocity="0" />
  </joint>
  <link
    name="sec03">
    <inertial>
      <origin
        xyz="0 0.005 0"
        rpy="0 0 0" />
      <mass
        value="0.0196349540849362" />
      <inertia
        ixx="3.23158619314575E-06"
        ixy="6.44898432852067E-39"
        ixz="0"
        iyy="6.13592315154257E-06"
        iyz="4.74299031266813E-39"
        izz="3.23158619314575E-06" />
    </inertial>
    <visual>
      <origin
        xyz="0 0 0"
        rpy="0 0 0" />
      <geometry>
        <mesh
          filename="package://virtual3/meshes/sec03.STL" />
      </geometry>
      <material
        name="">
        <color
          rgba="0.792156862745098 0.819607843137255 0.933333333333333 1" />
      </material>
    </visual>
    <collision>
      <origin
        xyz="0 0 0"
        rpy="0 0 0" />
      <geometry>
        <mesh
          filename="package://virtual3/meshes/sec03.STL" />
      </geometry>
    </collision>
  </link>
  <joint
    name="joint03"
    type="revolute">
    <origin
      xyz="0 -0.02 0"
      rpy="0 0 0" />
    <parent
      link="sec02" />
    <child
      link="sec03" />
    <axis
      xyz="0 0 0" />
    <limit
      lower="-1.571"
      upper="1.571"
      effort="100"
      velocity="0" />
  </joint>
  <link
    name="sec04">
    <inertial>
      <origin
        xyz="0 0.00499999999999995 0"
        rpy="0 0 0" />
      <mass
        value="0.0196349540849362" />
      <inertia
        ixx="3.23158619314575E-06"
        ixy="6.44898432852067E-39"
        ixz="0"
        iyy="6.13592315154257E-06"
        iyz="4.74299031266813E-39"
        izz="3.23158619314575E-06" />
    </inertial>
    <visual>
      <origin
        xyz="0 0 0"
        rpy="0 0 0" />
      <geometry>
        <mesh
          filename="package://virtual3/meshes/sec04.STL" />
      </geometry>
      <material
        name="">
        <color
          rgba="0.792156862745098 0.819607843137255 0.933333333333333 1" />
      </material>
    </visual>
    <collision>
      <origin
        xyz="0 0 0"
        rpy="0 0 0" />
      <geometry>
        <mesh
          filename="package://virtual3/meshes/sec04.STL" />
      </geometry>
    </collision>
  </link>
  <joint
    name="joint04"
    type="revolute">
    <origin
      xyz="0 -0.02 0"
      rpy="0 0 0" />
    <parent
      link="sec03" />
    <child
      link="sec04" />
    <axis
      xyz="0 0 0" />
    <limit
      lower="-1.571"
      upper="1.571"
      effort="100"
      velocity="0" />
  </joint>
  <link
    name="sec05">
    <inertial>
      <origin
        xyz="0 0.00499999999999995 0"
        rpy="0 0 0" />
      <mass
        value="0.0196349540849362" />
      <inertia
        ixx="3.23158619314575E-06"
        ixy="6.44898432852067E-39"
        ixz="0"
        iyy="6.13592315154257E-06"
        iyz="4.74299031266813E-39"
        izz="3.23158619314575E-06" />
    </inertial>
    <visual>
      <origin
        xyz="0 0 0"
        rpy="0 0 0" />
      <geometry>
        <mesh
          filename="package://virtual3/meshes/sec05.STL" />
      </geometry>
      <material
        name="">
        <color
          rgba="0.792156862745098 0.819607843137255 0.933333333333333 1" />
      </material>
    </visual>
    <collision>
      <origin
        xyz="0 0 0"
        rpy="0 0 0" />
      <geometry>
        <mesh
          filename="package://virtual3/meshes/sec05.STL" />
      </geometry>
    </collision>
  </link>
  <joint
    name="joint05"
    type="revolute">
    <origin
      xyz="0 -0.02 0"
      rpy="0 0 0" />
    <parent
      link="sec04" />
    <child
      link="sec05" />
    <axis
      xyz="0 0 0" />
    <limit
      lower="-1.571"
      upper="1.571"
      effort="100"
      velocity="0" />
  </joint>
  <link
    name="sec06">
    <inertial>
      <origin
        xyz="0 0.005 0"
        rpy="0 0 0" />
      <mass
        value="0.0196349540849362" />
      <inertia
        ixx="3.23158619314575E-06"
        ixy="6.44898432852067E-39"
        ixz="0"
        iyy="6.13592315154257E-06"
        iyz="4.74299031266813E-39"
        izz="3.23158619314575E-06" />
    </inertial>
    <visual>
      <origin
        xyz="0 0 0"
        rpy="0 0 0" />
      <geometry>
        <mesh
          filename="package://virtual3/meshes/sec06.STL" />
      </geometry>
      <material
        name="">
        <color
          rgba="0.792156862745098 0.819607843137255 0.933333333333333 1" />
      </material>
    </visual>
    <collision>
      <origin
        xyz="0 0 0"
        rpy="0 0 0" />
      <geometry>
        <mesh
          filename="package://virtual3/meshes/sec06.STL" />
      </geometry>
    </collision>
  </link>
  <joint
    name="joint06"
    type="revolute">
    <origin
      xyz="0 -0.02 0"
      rpy="0 0 0" />
    <parent
      link="sec05" />
    <child
      link="sec06" />
    <axis
      xyz="0 0 0" />
    <limit
      lower="-1.571"
      upper="1.571"
      effort="100"
      velocity="0" />
  </joint>
  <link
    name="sec07">
    <inertial>
      <origin
        xyz="0 0.00499999999999995 0"
        rpy="0 0 0" />
      <mass
        value="0.0196349540849362" />
      <inertia
        ixx="3.23158619314575E-06"
        ixy="6.44898432852067E-39"
        ixz="0"
        iyy="6.13592315154257E-06"
        iyz="4.74299031266813E-39"
        izz="3.23158619314575E-06" />
    </inertial>
    <visual>
      <origin
        xyz="0 0 0"
        rpy="0 0 0" />
      <geometry>
        <mesh
          filename="package://virtual3/meshes/sec07.STL" />
      </geometry>
      <material
        name="">
        <color
          rgba="0.792156862745098 0.819607843137255 0.933333333333333 1" />
      </material>
    </visual>
    <collision>
      <origin
        xyz="0 0 0"
        rpy="0 0 0" />
      <geometry>
        <mesh
          filename="package://virtual3/meshes/sec07.STL" />
      </geometry>
    </collision>
  </link>
  <joint
    name="joint07"
    type="revolute">
    <origin
      xyz="0 -0.02 0"
      rpy="0 0 0" />
    <parent
      link="sec06" />
    <child
      link="sec07" />
    <axis
      xyz="0 0 0" />
    <limit
      lower="-1.571"
      upper="1.571"
      effort="100"
      velocity="0" />
  </joint>
  <link
    name="sec08">
    <inertial>
      <origin
        xyz="0 0.005 0"
        rpy="0 0 0" />
      <mass
        value="0.0196349540849362" />
      <inertia
        ixx="3.23158619314575E-06"
        ixy="6.44898432852067E-39"
        ixz="0"
        iyy="6.13592315154257E-06"
        iyz="4.74299031266813E-39"
        izz="3.23158619314575E-06" />
    </inertial>
    <visual>
      <origin
        xyz="0 0 0"
        rpy="0 0 0" />
      <geometry>
        <mesh
          filename="package://virtual3/meshes/sec08.STL" />
      </geometry>
      <material
        name="">
        <color
          rgba="0.792156862745098 0.819607843137255 0.933333333333333 1" />
      </material>
    </visual>
    <collision>
      <origin
        xyz="0 0 0"
        rpy="0 0 0" />
      <geometry>
        <mesh
          filename="package://virtual3/meshes/sec08.STL" />
      </geometry>
    </collision>
  </link>
  <joint
    name="joint08"
    type="revolute">
    <origin
      xyz="0 -0.02 0"
      rpy="0 0 0" />
    <parent
      link="sec07" />
    <child
      link="sec08" />
    <axis
      xyz="0 0 0" />
    <limit
      lower="-1.571"
      upper="1.571"
      effort="100"
      velocity="0" />
  </joint>
  <link
    name="sec09">
    <inertial>
      <origin
        xyz="0 0.00499999999999998 0"
        rpy="0 0 0" />
      <mass
        value="0.0196349540849362" />
      <inertia
        ixx="3.23158619314575E-06"
        ixy="-2.22427428810535E-37"
        ixz="-3.3136311751555E-53"
        iyy="6.13592315154255E-06"
        iyz="4.74299031266811E-39"
        izz="3.23158619314574E-06" />
    </inertial>
    <visual>
      <origin
        xyz="0 0 0"
        rpy="0 0 0" />
      <geometry>
        <mesh
          filename="package://virtual3/meshes/sec09.STL" />
      </geometry>
      <material
        name="">
        <color
          rgba="0.792156862745098 0.819607843137255 0.933333333333333 1" />
      </material>
    </visual>
    <collision>
      <origin
        xyz="0 0 0"
        rpy="0 0 0" />
      <geometry>
        <mesh
          filename="package://virtual3/meshes/sec09.STL" />
      </geometry>
    </collision>
  </link>
  <joint
    name="joint09"
    type="revolute">
    <origin
      xyz="0 -0.02 0"
      rpy="0 0 0" />
    <parent
      link="sec08" />
    <child
      link="sec09" />
    <axis
      xyz="0 0 0" />
    <limit
      lower="-1.571"
      upper="1.571"
      effort="100"
      velocity="0" />
  </joint>
  <link
    name="sec10">
    <inertial>
      <origin
        xyz="0 0.00499999999999995 0"
        rpy="0 0 0" />
      <mass
        value="0.0196349540849362" />
      <inertia
        ixx="3.23158619314575E-06"
        ixy="6.44898432852067E-39"
        ixz="0"
        iyy="6.13592315154257E-06"
        iyz="4.74299031266813E-39"
        izz="3.23158619314575E-06" />
    </inertial>
    <visual>
      <origin
        xyz="0 0 0"
        rpy="0 0 0" />
      <geometry>
        <mesh
          filename="package://virtual3/meshes/sec10.STL" />
      </geometry>
      <material
        name="">
        <color
          rgba="0.792156862745098 0.819607843137255 0.933333333333333 1" />
      </material>
    </visual>
    <collision>
      <origin
        xyz="0 0 0"
        rpy="0 0 0" />
      <geometry>
        <mesh
          filename="package://virtual3/meshes/sec10.STL" />
      </geometry>
    </collision>
  </link>
  <joint
    name="joint10"
    type="revolute">
    <origin
      xyz="0 -0.02 0"
      rpy="0 0 0" />
    <parent
      link="sec09" />
    <child
      link="sec10" />
    <axis
      xyz="0 0 0" />
    <limit
      lower="-1.571"
      upper="1.571"
      effort="100"
      velocity="0" />
  </joint>
</robot>