<?xml version="1.0" encoding="utf-8"?>
<!-- This URDF was automatically created by SolidWorks to URDF Exporter! Originally created by Stephen Brawner (brawner@gmail.com) 
     Commit Version: 1.6.0-4-g7f85cfe  Build Version: 1.6.7995.38578
     For more information, please see http://wiki.ros.org/sw_urdf_exporter -->
<robot
  name="virtual">
  <link
    name="base_link">
    <inertial>
      <origin
        xyz="-1.21430643318376E-17 0.0721264987789416 -0.311073101363761"
        rpy="0 0 0" />
      <mass
        value="0.285332741228719" />
      <inertia
        ixx="0.00591175895401421"
        ixy="-7.42417332972305E-20"
        ixz="1.96368847316572E-19"
        iyy="0.00597979011652507"
        iyz="0.000797310950266471"
        izz="0.000796200497138781" />
    </inertial>
    <visual>
      <origin
        xyz="0 0 0"
        rpy="0 0 0" />
      <geometry>
        <mesh
          filename="package://virtual/meshes/base_link.STL" />
      </geometry>
      <material
        name="">
        <color
          rgba="0.792156862745098 0.819607843137255 0.933333333333333 1" />
      </material>
    </visual>
    <collision>
      <origin
        xyz="0 0 0"
        rpy="0 0 0" />
      <geometry>
        <mesh
          filename="package://virtual/meshes/base_link.STL" />
      </geometry>
    </collision>
  </link>
  <link
    name="link01">
    <inertial>
      <origin
        xyz="0 0 0.005"
        rpy="0 0 0" />
      <mass
        value="0.019635" />
      <inertia
        ixx="3.2316E-06"
        ixy="1.2745E-54"
        ixz="4.8367E-39"
        iyy="3.2316E-06"
        iyz="-4.743E-39"
        izz="6.1359E-06" />
    </inertial>
    <visual>
      <origin
        xyz="0 0 0"
        rpy="0 0 0" />
      <geometry>
        <mesh
          filename="package://virtual/meshes/link01.STL" />
      </geometry>
      <material
        name="">
        <color
          rgba="0.79216 0.81961 0.93333 1" />
      </material>
    </visual>
    <collision>
      <origin
        xyz="0 0 0"
        rpy="0 0 0" />
      <geometry>
        <mesh
          filename="package://virtual/meshes/link01.STL" />
      </geometry>
    </collision>
  </link>
  <!--
    <link name="dummy" type="fixed"/>  
	<joint name="dummy_to_base_link=" type="fixed">  
	<origin
        xyz="0 0 0"
        rpy="0 0 0" />
    	<parent link="dummy"/>  
     	<child link="base_link"/>  
	</joint>
	-->

  <joint
    name="joint01"
    type="revolute">
    <origin
      xyz="0 0 0"
      rpy="0 0 0" />
    <parent
      link="base_link" />
    <child
      link="link01" />
    <axis
      xyz="0 1 0" />
      <dynamics damping="0.001" friction="0.01"/>
    <limit
      lower="-1.571"
      upper="1.571"
      effort="100"
      velocity="0" />
  </joint>
  <link
    name="link02">
    <inertial>
      <origin
        xyz="0 0 0.005"
        rpy="0 0 0" />
      <mass
        value="0.0196349540849362" />
      <inertia
        ixx="3.23158619314575E-06"
        ixy="-3.82342058671789E-54"
        ixz="3.24386360874411E-38"
        iyy="3.23158619314575E-06"
        iyz="-4.74299031266812E-39"
        izz="6.13592315154257E-06" />
    </inertial>
    <visual>
      <origin
        xyz="0 0 0"
        rpy="0 0 0" />
      <geometry>
        <mesh
          filename="package://virtual/meshes/link02.STL" />
      </geometry>
      <material
        name="">
        <color
          rgba="0.792156862745098 0.819607843137255 0.933333333333333 1" />
      </material>
    </visual>
    <collision>
      <origin
        xyz="0 0 0"
        rpy="0 0 0" />
      <geometry>
        <mesh
          filename="package://virtual/meshes/link02.STL" />
      </geometry>
    </collision>
  </link>
  <joint
    name="joint02"
    type="revolute">
    <origin
      xyz="0 0 -0.03"
      rpy="0 0 0" />
    <parent
      link="link01" />
    <child
      link="link02" />
    <axis
      xyz="0 1 0" />
      <dynamics damping="0.001" friction="0.01"/>
    <limit
      lower="-1.571"
      upper="1.571"
      effort="100"
      velocity="0" />
  </joint>
  <link
    name="link03">
    <inertial>
      <origin
        xyz="0 0 0.00499999999999999"
        rpy="0 0 0" />
      <mass
        value="0.0196349540849362" />
      <inertia
        ixx="3.23158619314575E-06"
        ixy="7.64684117343577E-54"
        ixz="-4.38212158847711E-38"
        iyy="3.23158619314575E-06"
        iyz="-4.74299031266813E-39"
        izz="6.13592315154257E-06" />
    </inertial>
    <visual>
      <origin
        xyz="0 0 0"
        rpy="0 0 0" />
      <geometry>
        <mesh
          filename="package://virtual/meshes/link03.STL" />
      </geometry>
      <material
        name="">
        <color
          rgba="0.792156862745098 0.819607843137255 0.933333333333333 1" />
      </material>
    </visual>
    <collision>
      <origin
        xyz="0 0 0"
        rpy="0 0 0" />
      <geometry>
        <mesh
          filename="package://virtual/meshes/link03.STL" />
      </geometry>
    </collision>
  </link>
  <joint
    name="joint03"
    type="revolute">
    <origin
      xyz="0 0 -0.03"
      rpy="0 0 0" />
    <parent
      link="link02" />
    <child
      link="link03" />
    <axis
      xyz="0 1 0" />
      <dynamics damping="0.001" friction="0.01"/>
    <limit
      lower="-1.571"
      upper="1.571"
      effort="100"
      velocity="0" />
  </joint>
  <link
    name="link04">
    <inertial>
      <origin
        xyz="0 0 0.00499999999999999"
        rpy="0 0 0" />
      <mass
        value="0.0196349540849362" />
      <inertia
        ixx="3.23158619314575E-06"
        ixy="-1.65681558757775E-53"
        ixz="1.11213714405267E-37"
        iyy="3.23158619314575E-06"
        iyz="-4.74299031266812E-39"
        izz="6.13592315154256E-06" />
    </inertial>
    <visual>
      <origin
        xyz="0 0 0"
        rpy="0 0 0" />
      <geometry>
        <mesh
          filename="package://virtual/meshes/link04.STL" />
      </geometry>
      <material
        name="">
        <color
          rgba="0.792156862745098 0.819607843137255 0.933333333333333 1" />
      </material>
    </visual>
    <collision>
      <origin
        xyz="0 0 0"
        rpy="0 0 0" />
      <geometry>
        <mesh
          filename="package://virtual/meshes/link04.STL" />
      </geometry>
    </collision>
  </link>
  <joint
    name="joint04"
    type="revolute">
    <origin
      xyz="0 0 -0.03"
      rpy="0 0 0" />
    <parent
      link="link03" />
    <child
      link="link04" />
    <axis
      xyz="0 1 0" />
      <dynamics damping="0.001" friction="0.01"/>
    <limit
      lower="-1.571"
      upper="1.571"
      effort="100"
      velocity="0" />
  </joint>
  <link
    name="link05">
    <inertial>
      <origin
        xyz="0 0 0.00500000000000002"
        rpy="0 0 0" />
      <mass
        value="0.0196349540849362" />
      <inertia
        ixx="3.23158619314575E-06"
        ixy="-1.65681558757775E-53"
        ixz="1.11213714405267E-37"
        iyy="3.23158619314575E-06"
        iyz="-4.74299031266812E-39"
        izz="6.13592315154256E-06" />
    </inertial>
    <visual>
      <origin
        xyz="0 0 0"
        rpy="0 0 0" />
      <geometry>
        <mesh
          filename="package://virtual/meshes/link05.STL" />
      </geometry>
      <material
        name="">
        <color
          rgba="0.792156862745098 0.819607843137255 0.933333333333333 1" />
      </material>
    </visual>
    <collision>
      <origin
        xyz="0 0 0"
        rpy="0 0 0" />
      <geometry>
        <mesh
          filename="package://virtual/meshes/link05.STL" />
      </geometry>
    </collision>
  </link>
  <joint
    name="joint05"
    type="revolute">
    <origin
      xyz="0 0 -0.03"
      rpy="0 0 0" />
    <parent
      link="link04" />
    <child
      link="link05" />
    <axis
      xyz="0 1 0" />
      <dynamics damping="0.001" friction="0.01"/>
    <limit
      lower="-1.571"
      upper="1.571"
      effort="100"
      velocity="0" />
  </joint>
  <link
    name="link06">
    <inertial>
      <origin
        xyz="0 0 0.005"
        rpy="0 0 0" />
      <mass
        value="0.0196349540849362" />
      <inertia
        ixx="3.23158619314575E-06"
        ixy="0"
        ixz="6.44898432852067E-39"
        iyy="3.23158619314575E-06"
        iyz="-4.74299031266813E-39"
        izz="6.13592315154257E-06" />
    </inertial>
    <visual>
      <origin
        xyz="0 0 0"
        rpy="0 0 0" />
      <geometry>
        <mesh
          filename="package://virtual/meshes/link06.STL" />
      </geometry>
      <material
        name="">
        <color
          rgba="0.792156862745098 0.819607843137255 0.933333333333333 1" />
      </material>
    </visual>
    <collision>
      <origin
        xyz="0 0 0"
        rpy="0 0 0" />
      <geometry>
        <mesh
          filename="package://virtual/meshes/link06.STL" />
      </geometry>
    </collision>
  </link>
  <joint
    name="joint06"
    type="revolute">
    <origin
      xyz="0 0 -0.03"
      rpy="0 0 0" />
    <parent
      link="link05" />
    <child
      link="link06" />
    <axis
      xyz="0 1 0" />
      <dynamics damping="0.001" friction="0.01"/>
    <limit
      lower="-1.571"
      upper="1.571"
      effort="100"
      velocity="0" />
  </joint>
  <link
    name="link07">
    <inertial>
      <origin
        xyz="0 0 0.005"
        rpy="0 0 0" />
      <mass
        value="0.0196349540849362" />
      <inertia
        ixx="3.23158619314575E-06"
        ixy="0"
        ixz="6.44898432852067E-39"
        iyy="3.23158619314575E-06"
        iyz="-4.74299031266813E-39"
        izz="6.13592315154257E-06" />
    </inertial>
    <visual>
      <origin
        xyz="0 0 0"
        rpy="0 0 0" />
      <geometry>
        <mesh
          filename="package://virtual/meshes/link07.STL" />
      </geometry>
      <material
        name="">
        <color
          rgba="0.792156862745098 0.819607843137255 0.933333333333333 1" />
      </material>
    </visual>
    <collision>
      <origin
        xyz="0 0 0"
        rpy="0 0 0" />
      <geometry>
        <mesh
          filename="package://virtual/meshes/link07.STL" />
      </geometry>
    </collision>
  </link>
  <joint
    name="joint07"
    type="revolute">
    <origin
      xyz="0 0 -0.03"
      rpy="0 0 0" />
    <parent
      link="link06" />
    <child
      link="link07" />
    <axis
      xyz="0 1 0" />
      <dynamics damping="0.001" friction="0.01"/>
    <limit
      lower="-1.571"
      upper="1.571"
      effort="100"
      velocity="0" />
  </joint>
  <link
    name="link08">
    <inertial>
      <origin
        xyz="0 0 0.00499999999999998"
        rpy="0 0 0" />
      <mass
        value="0.0196349540849362" />
      <inertia
        ixx="3.23158619314575E-06"
        ixy="0"
        ixz="6.44898432852067E-39"
        iyy="3.23158619314575E-06"
        iyz="-4.74299031266813E-39"
        izz="6.13592315154257E-06" />
    </inertial>
    <visual>
      <origin
        xyz="0 0 0"
        rpy="0 0 0" />
      <geometry>
        <mesh
          filename="package://virtual/meshes/link08.STL" />
      </geometry>
      <material
        name="">
        <color
          rgba="0.792156862745098 0.819607843137255 0.933333333333333 1" />
      </material>
    </visual>
    <collision>
      <origin
        xyz="0 0 0"
        rpy="0 0 0" />
      <geometry>
        <mesh
          filename="package://virtual/meshes/link08.STL" />
      </geometry>
    </collision>
  </link>
  <joint
    name="joint08"
    type="revolute">
    <origin
      xyz="0 0 -0.03"
      rpy="0 0 0" />
    <parent
      link="link07" />
    <child
      link="link08" />
    <axis
      xyz="0 1 0" />
      <dynamics damping="0.001" friction="0.01"/>
    <limit
      lower="-1.571"
      upper="1.571"
      effort="100"
      velocity="0" />
  </joint>



<!--transmission definition -->
<transmission name="tran01">
    <type>transmission_interface/SimpleTransmission</type>
    <joint name="joint01">
      <hardwareInterface>hardware_interface/EffortJointInterface</hardwareInterface>
    </joint>
    <actuator name="motor01">
      <hardwareInterface>hardware_interface/EffortJointInterface</hardwareInterface>
      <mechanicalReduction>1</mechanicalReduction>
    </actuator>
  </transmission>
  
  <transmission name="tran02">
    <type>transmission_interface/SimpleTransmission</type>
    <joint name="joint02">
      <hardwareInterface>hardware_interface/EffortJointInterface</hardwareInterface>
    </joint>
    <actuator name="motor02">
      <hardwareInterface>hardware_interface/EffortJointInterface</hardwareInterface>
      <mechanicalReduction>1</mechanicalReduction>
    </actuator>
  </transmission>
  
  <transmission name="tran03">
    <type>transmission_interface/SimpleTransmission</type>
    <joint name="joint03">
      <hardwareInterface>hardware_interface/EffortJointInterface</hardwareInterface>
    </joint>
    <actuator name="motor03">
      <hardwareInterface>hardware_interface/EffortJointInterface</hardwareInterface>
      <mechanicalReduction>1</mechanicalReduction>
    </actuator>
  </transmission>
  
  <transmission name="tran04">
    <type>transmission_interface/SimpleTransmission</type>
    <joint name="joint04">
      <hardwareInterface>hardware_interface/EffortJointInterface</hardwareInterface>
    </joint>
    <actuator name="motor04">
      <hardwareInterface>hardware_interface/EffortJointInterface</hardwareInterface>
      <mechanicalReduction>1</mechanicalReduction>
    </actuator>
  </transmission>
  
  <transmission name="tran05">
    <type>transmission_interface/SimpleTransmission</type>
    <joint name="joint05">
      <hardwareInterface>hardware_interface/EffortJointInterface</hardwareInterface>
    </joint>
    <actuator name="motor05">
      <hardwareInterface>hardware_interface/EffortJointInterface</hardwareInterface>
      <mechanicalReduction>1</mechanicalReduction>
    </actuator>
  </transmission>
  
  <transmission name="tran06">
    <type>transmission_interface/SimpleTransmission</type>
    <joint name="joint06">
      <hardwareInterface>hardware_interface/EffortJointInterface</hardwareInterface>
    </joint>
    <actuator name="motor06">
      <hardwareInterface>hardware_interface/EffortJointInterface</hardwareInterface>
      <mechanicalReduction>1</mechanicalReduction>
    </actuator>
  </transmission>
  
  <transmission name="tran07">
    <type>transmission_interface/SimpleTransmission</type>
    <joint name="joint07">
      <hardwareInterface>hardware_interface/EffortJointInterface</hardwareInterface>
    </joint>
    <actuator name="motor07">
      <hardwareInterface>hardware_interface/EffortJointInterface</hardwareInterface>
      <mechanicalReduction>1</mechanicalReduction>
    </actuator>
  </transmission>
  
  <transmission name="tran08">
    <type>transmission_interface/SimpleTransmission</type>
    <joint name="joint08">
      <hardwareInterface>hardware_interface/EffortJointInterface</hardwareInterface>
    </joint>
    <actuator name="motor08">
      <hardwareInterface>hardware_interface/EffortJointInterface</hardwareInterface>
      <mechanicalReduction>1</mechanicalReduction>
    </actuator>
  </transmission>


<!--cointrol pluging -->
  <gazebo>
  <plugin name="gazebo_ros_control" filename="libgazebo_ros_control.so">

  </plugin>
</gazebo>

<!--
<gazebo reference="link01">
   <turnGravityOff>true</turnGravityOff>
</gazebo>

<gazebo reference="link02">
   <turnGravityOff>true</turnGravityOff>
</gazebo>

<gazebo reference="link03">
   <turnGravityOff>true</turnGravityOff>
</gazebo>

<gazebo reference="link04">
   <turnGravityOff>true</turnGravityOff>
</gazebo>

<gazebo reference="link05">
   <turnGravityOff>true</turnGravityOff>
</gazebo>

<gazebo reference="link06">
   <turnGravityOff>true</turnGravityOff>
</gazebo>

<gazebo reference="link07">
   <turnGravityOff>true</turnGravityOff>
</gazebo>

<gazebo reference="link08">
   <turnGravityOff>true</turnGravityOff>
</gazebo>

-->
</robot>