<?xml version="1.0" encoding="utf-8"?>
<!-- This URDF was automatically created by SolidWorks to URDF Exporter! Originally created by Stephen Brawner (brawner@gmail.com) 
     Commit Version: 1.6.0-4-g7f85cfe  Build Version: 1.6.7995.38578
     For more information, please see http://wiki.ros.org/sw_urdf_exporter -->
<robot
  name="tripod9">
  <link
    name="base_link">
    <inertial>
      <origin
        xyz="-0.00312905634710786 0.0203968059548864 0.0257846213394461"
        rpy="0 0 0" />
      <mass
        value="11.3724307419957" />
      <inertia
        ixx="0.0406073269056664"
        ixy="0.010264439474814"
        ixz="-4.0857509947383E-07"
        iyy="0.0528919898826588"
        iyz="-5.215426614709E-08"
        izz="0.0710445423135388" />
    </inertial>
    <visual>
      <origin
        xyz="0 0 0"
        rpy="0 0 0" />
      <geometry>
        <mesh
          filename="package://tripod9/meshes/base_link.STL" />
      </geometry>
      <material
        name="">
        <color
          rgba="0.898039215686275 0.917647058823529 0.929411764705882 1" />
      </material>
    </visual>
    <collision>
      <origin
        xyz="0 0 0"
        rpy="0 0 0" />
      <geometry>
        <mesh
          filename="package://tripod9/meshes/base_link.STL" />
      </geometry>
    </collision>
  </link>
  <link
    name="sec01">
    <inertial>
      <origin
        xyz="0.00048653 0.015913 -3.1489E-05"
        rpy="0 0 0" />
      <mass
        value="0.69712" />
      <inertia
        ixx="0.0011428"
        ixy="-9.0045E-05"
        ixz="-4.1383E-07"
        iyy="0.0011939"
        iyz="-4.9367E-19"
        izz="0.00095487" />
    </inertial>
    <visual>
      <origin
        xyz="0 0 0"
        rpy="0 0 0" />
      <geometry>
        <mesh
          filename="package://tripod9/meshes/sec01.STL" />
      </geometry>
      <material
        name="">
        <color
          rgba="0.79216 0.81961 0.93333 1" />
      </material>
    </visual>
    <collision>
      <origin
        xyz="0 0 0"
        rpy="0 0 0" />
      <geometry>
        <mesh
          filename="package://tripod9/meshes/sec01.STL" />
      </geometry>
    </collision>
  </link>
  <joint
    name="leg01"
    type="revolute">
    <origin
      xyz="-0.00270211669405697 -0.198920451815278 0.0296429977991011"
      rpy="0 0 -1.5707963267949" />
    <parent
      link="base_link" />
    <child
      link="sec01" />
    <axis
      xyz="1 0 0" />
    <limit
      lower="-1.571"
      upper="1.571"
      effort="10000"
      velocity="10000" />
  </joint>
  <link
    name="hsec01">
    <inertial>
      <origin
        xyz="-0.085802207284442 -0.0586652892981549 -0.00128195126910836"
        rpy="0 0 0" />
      <mass
        value="2.59385289729097" />
      <inertia
        ixx="0.0132813286063691"
        ixy="2.30713341803904E-07"
        ixz="7.37838868928084E-06"
        iyy="0.00186263080107763"
        iyz="1.88984474958543E-06"
        izz="0.0117381218254458" />
    </inertial>
    <visual>
      <origin
        xyz="0 0 0"
        rpy="0 0 0" />
      <geometry>
        <mesh
          filename="package://tripod9/meshes/hsec01.STL" />
      </geometry>
      <material
        name="">
        <color
          rgba="0.792156862745098 0.819607843137255 0.933333333333333 1" />
      </material>
    </visual>
    <collision>
      <origin
        xyz="0 0 0"
        rpy="0 0 0" />
      <geometry>
        <mesh
          filename="package://tripod9/meshes/hsec01.STL" />
      </geometry>
    </collision>
  </link>
  <joint
    name="high01"
    type="revolute">
    <origin
      xyz="0.0788064380992387 0.0895000000000011 0"
      rpy="0 0 1.5707963267949" />
    <parent
      link="sec01" />
    <child
      link="hsec01" />
    <axis
      xyz="-1 0 0" />
    <limit
      lower="-1.571"
      upper="1.571"
      effort="10000"
      velocity="10000" />
  </joint>
  <link
    name="lsec01">
    <inertial>
      <origin
        xyz="-0.00741155948002789 -0.0534070820824174 -2.19114356162647E-07"
        rpy="0 0 0" />
      <mass
        value="0.292019066527945" />
      <inertia
        ixx="0.000681104991544854"
        ixy="3.03504858996814E-10"
        ixz="-6.21574686540396E-10"
        iyy="8.62621908768414E-05"
        iyz="-1.16761217815233E-09"
        izz="0.0006157104656343" />
    </inertial>
    <visual>
      <origin
        xyz="0 0 0"
        rpy="0 0 0" />
      <geometry>
        <mesh
          filename="package://tripod9/meshes/lsec01.STL" />
      </geometry>
      <material
        name="">
        <color
          rgba="0.792156862745098 0.819607843137255 0.933333333333333 1" />
      </material>
    </visual>
    <collision>
      <origin
        xyz="0 0 0"
        rpy="0 0 0" />
      <geometry>
        <mesh
          filename="package://tripod9/meshes/lsec01.STL" />
      </geometry>
    </collision>
  </link>
  <joint
    name="low01"
    type="revolute">
    <origin
      xyz="-0.10655 -0.269643561900764 -0.0021000000000095"
      rpy="0 0 0" />
    <parent
      link="hsec01" />
    <child
      link="lsec01" />
    <axis
      xyz="-1 0 0" />
    <limit
      lower="-1.571"
      upper="1.571"
      effort="10000"
      velocity="10000" />
  </joint>
  <link
    name="sec02">
    <inertial>
      <origin
        xyz="0.00048653 0.015913 -3.1489E-05"
        rpy="0 0 0" />
      <mass
        value="0.69712" />
      <inertia
        ixx="0.0011428"
        ixy="-9.0045E-05"
        ixz="-4.1383E-07"
        iyy="0.0011939"
        iyz="-6.2858E-19"
        izz="0.00095487" />
    </inertial>
    <visual>
      <origin
        xyz="0 0 0"
        rpy="0 0 0" />
      <geometry>
        <mesh
          filename="package://tripod9/meshes/sec02.STL" />
      </geometry>
      <material
        name="">
        <color
          rgba="0.79216 0.81961 0.93333 1" />
      </material>
    </visual>
    <collision>
      <origin
        xyz="0 0 0"
        rpy="0 0 0" />
      <geometry>
        <mesh
          filename="package://tripod9/meshes/sec02.STL" />
      </geometry>
    </collision>
  </link>
  <joint
    name="leg02"
    type="revolute">
    <origin
      xyz="0.185774106959521 0.127529943539013 0.0296429977991011"
      rpy="0 0 0.523598775598251" />
    <parent
      link="base_link" />
    <child
      link="sec02" />
    <axis
      xyz="1 0 0" />
    <limit
      lower="-1.571"
      upper="1.571"
      effort="10000"
      velocity="10000" />
  </joint>
  <link
    name="hsec02">
    <inertial>
      <origin
        xyz="-0.0936880803892596 0.0449324326469038 -0.00132320363478538"
        rpy="0 0 0" />
      <mass
        value="2.58967801426391" />
      <inertia
        ixx="0.00471738722941004"
        ixy="-0.00494456996283436"
        ixz="5.32584938980878E-06"
        iyy="0.0104263520174632"
        iyz="-5.44494872557977E-06"
        izz="0.0117379962530972" />
    </inertial>
    <visual>
      <origin
        xyz="0 0 0"
        rpy="0 0 0" />
      <geometry>
        <mesh
          filename="package://tripod9/meshes/hsec02.STL" />
      </geometry>
      <material
        name="">
        <color
          rgba="0.792156862745098 0.819607843137255 0.933333333333333 1" />
      </material>
    </visual>
    <collision>
      <origin
        xyz="0 0 0"
        rpy="0 0 0" />
      <geometry>
        <mesh
          filename="package://tripod9/meshes/hsec02.STL" />
      </geometry>
    </collision>
  </link>
  <joint
    name="high02"
    type="revolute">
    <origin
      xyz="0.0788064380992388 0.0895000000000011 0"
      rpy="0 0 2.61799387799154" />
    <parent
      link="sec02" />
    <child
      link="hsec02" />
    <axis
      xyz="-0.499999999999959 0.866025403784462 0" />
    <limit
      lower="-1.571"
      upper="1.571"
      effort="10000"
      velocity="10000" />
  </joint>
  <link
    name="lsec02">
    <inertial>
      <origin
        xyz="-0.049957669765295 -0.0202849427339908 -2.19055842902438E-07"
        rpy="0 0 0" />
      <mass
        value="0.292019079957839" />
      <inertia
        ixx="0.00023497254123623"
        ixy="-0.000257573690181134"
        ixz="-1.32698808700612E-09"
        iyy="0.000532392318918855"
        iyz="-3.69713850193408E-11"
        izz="0.000615708168370942" />
    </inertial>
    <visual>
      <origin
        xyz="0 0 0"
        rpy="0 0 0" />
      <geometry>
        <mesh
          filename="package://tripod9/meshes/lsec02.STL" />
      </geometry>
      <material
        name="">
        <color
          rgba="0.792156862745098 0.819607843137255 0.933333333333333 1" />
      </material>
    </visual>
    <collision>
      <origin
        xyz="0 0 0"
        rpy="0 0 0" />
      <geometry>
        <mesh
          filename="package://tripod9/meshes/lsec02.STL" />
      </geometry>
    </collision>
  </link>
  <joint
    name="low02"
    type="revolute">
    <origin
      xyz="-0.286793174572986 -0.0425467741771368 -0.00210000000000763"
      rpy="0 0 0" />
    <parent
      link="hsec02" />
    <child
      link="lsec02" />
    <axis
      xyz="-0.49999999999996 0.866025403784462 0" />
    <limit
      lower="-1.571"
      upper="1.571"
      effort="10000"
      velocity="10000" />
  </joint>
  <link
    name="sec03">
    <inertial>
      <origin
        xyz="0.00048653 0.015913 -3.1489E-05"
        rpy="0 0 0" />
      <mass
        value="0.69712" />
      <inertia
        ixx="0.0011428"
        ixy="-9.0045E-05"
        ixz="-4.1383E-07"
        iyy="0.0011939"
        iyz="-1.7005E-17"
        izz="0.00095487" />
    </inertial>
    <visual>
      <origin
        xyz="0 0 0"
        rpy="0 0 0" />
      <geometry>
        <mesh
          filename="package://tripod9/meshes/sec03.STL" />
      </geometry>
      <material
        name="">
        <color
          rgba="0.79216 0.81961 0.93333 1" />
      </material>
    </visual>
    <collision>
      <origin
        xyz="0 0 0"
        rpy="0 0 0" />
      <geometry>
        <mesh
          filename="package://tripod9/meshes/sec03.STL" />
      </geometry>
    </collision>
  </link>
  <joint
    name="leg03"
    type="revolute">
    <origin
      xyz="-0.19118 0.12753 0.029643"
      rpy="0 0 2.618" />
    <parent
      link="base_link" />
    <child
      link="sec03" />
    <axis
      xyz="1 0 0" />
    <limit
      lower="-1.571"
      upper="1.571"
      effort="10000"
      velocity="10000" />
  </joint>
  <link
    name="hsec03">
    <inertial>
      <origin
        xyz="-0.0079045 0.10364 -0.001282"
        rpy="0 0 0" />
      <mass
        value="2.5939" />
      <inertia
        ixx="0.0047171"
        ixy="0.0049443"
        ixz="-2.0525E-06"
        iyy="0.010427"
        iyz="-7.3348E-06"
        izz="0.011738" />
    </inertial>
    <visual>
      <origin
        xyz="0 0 0"
        rpy="0 0 0" />
      <geometry>
        <mesh
          filename="package://tripod9/meshes/hsec03.STL" />
      </geometry>
      <material
        name="">
        <color
          rgba="0.79216 0.81961 0.93333 1" />
      </material>
    </visual>
    <collision>
      <origin
        xyz="0 0 0"
        rpy="0 0 0" />
      <geometry>
        <mesh
          filename="package://tripod9/meshes/hsec03.STL" />
      </geometry>
    </collision>
  </link>
  <joint
    name="high03"
    type="revolute">
    <origin
      xyz="0.078806 0.0895 0"
      rpy="0 0 -2.618" />
    <parent
      link="sec03" />
    <child
      link="hsec03" />
    <axis
      xyz="0.5 0.86603 0" />
    <limit
      lower="-1.571"
      upper="1.571"
      effort="10000"
      velocity="10000" />
  </joint>
  <link
    name="lsec03">
    <inertial>
      <origin
        xyz="-0.042546 0.033122 -2.1905E-07"
        rpy="0 0 0" />
      <mass
        value="0.29202" />
      <inertia
        ixx="0.00023497"
        ixy="0.00025757"
        ixz="-6.9589E-10"
        iyy="0.00053239"
        iyz="1.1309E-09"
        izz="0.00061571" />
    </inertial>
    <visual>
      <origin
        xyz="0 0 0"
        rpy="0 0 0" />
      <geometry>
        <mesh
          filename="package://tripod9/meshes/lsec03.STL" />
      </geometry>
      <material
        name="">
        <color
          rgba="0.89804 0.91765 0.92941 1" />
      </material>
    </visual>
    <collision>
      <origin
        xyz="0 0 0"
        rpy="0 0 0" />
      <geometry>
        <mesh
          filename="package://tripod9/meshes/lsec03.STL" />
      </geometry>
    </collision>
  </link>
  <joint
    name="low03"
    type="revolute">
    <origin
      xyz="-0.18024 0.2271 -0.0021"
      rpy="0 0 0" />
    <parent
      link="hsec03" />
    <child
      link="lsec03" />
    <axis
      xyz="0.5 0.86603 0" />
    <limit
      lower="-1.571"
      upper="1.571"
      effort="10000"
      velocity="10000" />
  </joint>

<!--transmission definition -->
<transmission name="tran01">
    <type>transmission_interface/SimpleTransmission</type>
    <joint name="leg01">
      <hardwareInterface>hardware_interface/EffortJointInterface</hardwareInterface>
    </joint>
    <actuator name="motor01">
      <hardwareInterface>hardware_interface/EffortJointInterface</hardwareInterface>
      <mechanicalReduction>1</mechanicalReduction>
    </actuator>
  </transmission>
  
  <transmission name="tran02">
    <type>transmission_interface/SimpleTransmission</type>
    <joint name="high01">
      <hardwareInterface>hardware_interface/EffortJointInterface</hardwareInterface>
    </joint>
    <actuator name="motor02">
      <hardwareInterface>hardware_interface/EffortJointInterface</hardwareInterface>
      <mechanicalReduction>1</mechanicalReduction>
    </actuator>
  </transmission>
  
  <transmission name="tran03">
    <type>transmission_interface/SimpleTransmission</type>
    <joint name="low01">
      <hardwareInterface>hardware_interface/EffortJointInterface</hardwareInterface>
    </joint>
    <actuator name="motor03">
      <hardwareInterface>hardware_interface/EffortJointInterface</hardwareInterface>
      <mechanicalReduction>1</mechanicalReduction>
    </actuator>
  </transmission>
  
  <transmission name="tran04">
    <type>transmission_interface/SimpleTransmission</type>
    <joint name="leg02">
      <hardwareInterface>hardware_interface/EffortJointInterface</hardwareInterface>
    </joint>
    <actuator name="motor04">
      <hardwareInterface>hardware_interface/EffortJointInterface</hardwareInterface>
      <mechanicalReduction>1</mechanicalReduction>
    </actuator>
  </transmission>
  
  <transmission name="tran05">
    <type>transmission_interface/SimpleTransmission</type>
    <joint name="high02">
      <hardwareInterface>hardware_interface/EffortJointInterface</hardwareInterface>
    </joint>
    <actuator name="motor05">
      <hardwareInterface>hardware_interface/EffortJointInterface</hardwareInterface>
      <mechanicalReduction>1</mechanicalReduction>
    </actuator>
  </transmission>
  
  <transmission name="tran06">
    <type>transmission_interface/SimpleTransmission</type>
    <joint name="low02">
      <hardwareInterface>hardware_interface/EffortJointInterface</hardwareInterface>
    </joint>
    <actuator name="motor06">
      <hardwareInterface>hardware_interface/EffortJointInterface</hardwareInterface>
      <mechanicalReduction>1</mechanicalReduction>
    </actuator>
  </transmission>
  
  <transmission name="tran07">
    <type>transmission_interface/SimpleTransmission</type>
    <joint name="leg03">
      <hardwareInterface>hardware_interface/EffortJointInterface</hardwareInterface>
    </joint>
    <actuator name="motor07">
      <hardwareInterface>hardware_interface/EffortJointInterface</hardwareInterface>
      <mechanicalReduction>1</mechanicalReduction>
    </actuator>
  </transmission>
  
  <transmission name="tran08">
    <type>transmission_interface/SimpleTransmission</type>
    <joint name="high03">
      <hardwareInterface>hardware_interface/EffortJointInterface</hardwareInterface>
    </joint>
    <actuator name="motor08">
      <hardwareInterface>hardware_interface/EffortJointInterface</hardwareInterface>
      <mechanicalReduction>1</mechanicalReduction>
    </actuator>
  </transmission>
  
  <transmission name="tran09">
    <type>transmission_interface/SimpleTransmission</type>
    <joint name="low03">
      <hardwareInterface>hardware_interface/EffortJointInterface</hardwareInterface>
    </joint>
    <actuator name="motor09">
      <hardwareInterface>hardware_interface/EffortJointInterface</hardwareInterface>
      <mechanicalReduction>1</mechanicalReduction>
    </actuator>
  </transmission>
  
      <!--cointrol pluging -->
  <gazebo>
  <plugin name="gazebo_ros_control" filename="libgazebo_ros_control.so">

  </plugin>
</gazebo>

<!--
<gazebo reference="sec01">
   <turnGravityOff>true</turnGravityOff>
</gazebo>

<gazebo reference="sec02">
   <turnGravityOff>true</turnGravityOff>
</gazebo>

<gazebo reference="sec03">
   <turnGravityOff>true</turnGravityOff>
</gazebo>

<gazebo reference="sec04">
   <turnGravityOff>true</turnGravityOff>
</gazebo>

<gazebo reference="sec05">
   <turnGravityOff>true</turnGravityOff>
</gazebo>

<gazebo reference="sec06">
   <turnGravityOff>true</turnGravityOff>
</gazebo>

<gazebo reference="sec07">
   <turnGravityOff>true</turnGravityOff>
</gazebo>

<gazebo reference="sec08">
   <turnGravityOff>true</turnGravityOff>
</gazebo>

<gazebo reference="sec09">
   <turnGravityOff>true</turnGravityOff>
</gazebo>

<gazebo reference="sec10">
   <turnGravityOff>true</turnGravityOff>
</gazebo>

<gazebo reference="sec11">
   <turnGravityOff>true</turnGravityOff>
</gazebo>

-->
</robot>