<?xml version="1.0" encoding="utf-8"?>
<!-- This URDF was automatically created by SolidWorks to URDF Exporter! Originally created by Stephen Brawner (brawner@gmail.com) 
     Commit Version: 1.6.0-4-g7f85cfe  Build Version: 1.6.7995.38578
     For more information, please see http://wiki.ros.org/sw_urdf_exporter -->
<robot
  name="tripod6">
  <link
    name="base_link">
    <inertial>
      <origin
        xyz="-0.00325506602262156 0.0204763017132949 0.0257468978154951"
        rpy="0 0 0" />
      <mass
        value="11.3762827967786" />
      <inertia
        ixx="0.0406078012200441"
        ixy="0.0102641818605393"
        ixz="-3.94854534274407E-07"
        iyy="0.0528921667296946"
        iyz="-2.83895501119624E-08"
        izz="0.0710451640958759" />
    </inertial>
    <visual>
      <origin
        xyz="0 0 0"
        rpy="0 0 0" />
      <geometry>
        <mesh
          filename="package://tripod6/meshes/base_link.STL" />
      </geometry>
      <material
        name="">
        <color
          rgba="0.898039215686275 0.917647058823529 0.929411764705882 1" />
      </material>
    </visual>
    <collision>
      <origin
        xyz="0 0 0"
        rpy="0 0 0" />
      <geometry>
        <mesh
          filename="package://tripod6/meshes/base_link.STL" />
      </geometry>
    </collision>
  </link>
  <link
    name="sec01">
    <inertial>
      <origin
        xyz="0.00048653 0.015913 -3.1489E-05"
        rpy="0 0 0" />
      <mass
        value="0.69712" />
      <inertia
        ixx="0.0011428"
        ixy="-9.0045E-05"
        ixz="-4.1383E-07"
        iyy="0.0011939"
        iyz="-4.932E-19"
        izz="0.00095487" />
    </inertial>
    <visual>
      <origin
        xyz="0 0 0"
        rpy="0 0 0" />
      <geometry>
        <mesh
          filename="package://tripod6/meshes/sec01.STL" />
      </geometry>
      <material
        name="">
        <color
          rgba="0.79216 0.81961 0.93333 1" />
      </material>
    </visual>
    <collision>
      <origin
        xyz="0 0 0"
        rpy="0 0 0" />
      <geometry>
        <mesh
          filename="package://tripod6/meshes/sec01.STL" />
      </geometry>
    </collision>
  </link>
  <joint
    name="leg01"
    type="revolute">
    <origin
      xyz="-0.0027021 -0.19892 0.029643"
      rpy="0 0 -1.5708" />
    <parent
      link="base_link" />
    <child
      link="sec01" />
    <axis
      xyz="1 0 0" />
    <limit
      lower="-1.571"
      upper="1.571"
      effort="100000"
      velocity="10000" />
  </joint>
  <link
    name="hsec01">
    <inertial>
      <origin
        xyz="-0.0858021916032918 -0.0356038115553252 -0.0478130457045351"
        rpy="0 0 0" />
      <mass
        value="2.59385150429137" />
      <inertia
        ixx="0.0132813268489571"
        ixy="1.03375570286498E-07"
        ixz="7.13532302168331E-06"
        iyy="0.00811205669431778"
        iyz="-0.00473111556439252"
        izz="0.00548869413504745" />
    </inertial>
    <visual>
      <origin
        xyz="0 0 0"
        rpy="0 0 0" />
      <geometry>
        <mesh
          filename="package://tripod6/meshes/hsec01.STL" />
      </geometry>
      <material
        name="">
        <color
          rgba="0.792156862745098 0.819607843137255 0.933333333333333 1" />
      </material>
    </visual>
    <collision>
      <origin
        xyz="0 0 0"
        rpy="0 0 0" />
      <geometry>
        <mesh
          filename="package://tripod6/meshes/hsec01.STL" />
      </geometry>
    </collision>
  </link>
  <joint
    name="high01"
    type="revolute">
    <origin
      xyz="0.0788064380992387 0.0895000000000011 0"
      rpy="0 0 1.5707963267949" />
    <parent
      link="sec01" />
    <child
      link="hsec01" />
    <axis
      xyz="-1 0 0" />
    <limit
      lower="-1.571"
      upper="1.571"
      effort="100000"
      velocity="10000" />
  </joint>
  <link
    name="lsec01">
    <inertial>
      <origin
        xyz="-0.00741155567241021 -0.00127192326916403 -0.0533920056192748"
        rpy="0 0 0" />
      <mass
        value="0.292019107167018" />
      <inertia
        ixx="0.000681102636560165"
        ixy="7.38104870478283E-10"
        ixz="-9.0996591265309E-11"
        iyy="0.000615407778319895"
        iyz="-1.26066070763318E-05"
        izz="8.65624197807898E-05" />
    </inertial>
    <visual>
      <origin
        xyz="0 0 0"
        rpy="0 0 0" />
      <geometry>
        <mesh
          filename="package://tripod6/meshes/lsec01.STL" />
      </geometry>
      <material
        name="">
        <color
          rgba="0.792156862745098 0.819607843137255 0.933333333333333 1" />
      </material>
    </visual>
    <collision>
      <origin
        xyz="0 0 0"
        rpy="0 0 0" />
      <geometry>
        <mesh
          filename="package://tripod6/meshes/lsec01.STL" />
      </geometry>
    </collision>
  </link>
  <joint
    name="low01"
    type="revolute">
    <origin
      xyz="-0.10655 -0.162849136784516 -0.216842702161685"
      rpy="0 0 0" />
    <parent
      link="hsec01" />
    <child
      link="lsec01" />
    <axis
      xyz="-1 0 0" />
    <limit
      lower="-1.571"
      upper="1.571"
      effort="100000"
      velocity="10000" />
  </joint>
  <link
    name="sec02">
    <inertial>
      <origin
        xyz="0.00048653 0.015902 -0.00057944"
        rpy="0 0 0" />
      <mass
        value="0.69712" />
      <inertia
        ixx="0.0011428"
        ixy="-9.0005E-05"
        ixz="2.6872E-06"
        iyy="0.0011936"
        iyz="-8.2262E-06"
        izz="0.00095515" />
    </inertial>
    <visual>
      <origin
        xyz="0 0 0"
        rpy="0 0 0" />
      <geometry>
        <mesh
          filename="package://tripod6/meshes/sec02.STL" />
      </geometry>
      <material
        name="">
        <color
          rgba="0.79216 0.81961 0.93333 1" />
      </material>
    </visual>
    <collision>
      <origin
        xyz="0 0 0"
        rpy="0 0 0" />
      <geometry>
        <mesh
          filename="package://tripod6/meshes/sec02.STL" />
      </geometry>
    </collision>
  </link>
  <joint
    name="leg02"
    type="revolute">
    <origin
      xyz="0.18577 0.12753 0.029643"
      rpy="0 0 0.5236" />
    <parent
      link="base_link" />
    <child
      link="sec02" />
    <axis
      xyz="1 0 0" />
    <limit
      lower="-1.571"
      upper="1.571"
      effort="100000"
      velocity="10000" />
  </joint>
  <link
    name="hsec02">
    <inertial>
      <origin
        xyz="0.0335085717729542 -0.085756652923112 -0.0493355728010134"
        rpy="0 0 0" />
      <mass
        value="2.5896766478431" />
      <inertia
        ixx="0.0085198262787041"
        ixy="-1.03390021082483E-07"
        ixz="0.00459661998532711"
        iyy="0.0132812323187152"
        iyz="7.12185204419002E-06"
        izz="0.00508067346034401" />
    </inertial>
    <visual>
      <origin
        xyz="0 0 0"
        rpy="0 0 0" />
      <geometry>
        <mesh
          filename="package://tripod6/meshes/hsec02.STL" />
      </geometry>
      <material
        name="">
        <color
          rgba="0.792156862745098 0.819607843137255 0.933333333333333 1" />
      </material>
    </visual>
    <collision>
      <origin
        xyz="0 0 0"
        rpy="0 0 0" />
      <geometry>
        <mesh
          filename="package://tripod6/meshes/hsec02.STL" />
      </geometry>
    </collision>
  </link>
  <joint
    name="high02"
    type="revolute">
    <origin
      xyz="0.0788064380992388 0.0894469172453881 -0.00308204401280986"
      rpy="-0.0344430556533543 0 0" />
    <parent
      link="sec02" />
    <child
      link="hsec02" />
    <axis
      xyz="0 -1 0" />
    <limit
      lower="-1.571"
      upper="1.571"
      effort="100000"
      velocity="10000" />
  </joint>
  <link
    name="lsec02">
    <inertial>
      <origin
        xyz="-0.00106185200526404 -0.00741156475670043 -0.05339660055728"
        rpy="0 0 0" />
      <mass
        value="0.292019102742486" />
      <inertia
        ixx="0.0006155001532679"
        ixy="-7.36355502695954E-10"
        ixz="-1.05232958011785E-05"
        iyy="0.00068110389430123"
        iyz="-4.62761016689675E-10"
        izz="8.64713392775338E-05" />
    </inertial>
    <visual>
      <origin
        xyz="0 0 0"
        rpy="0 0 0" />
      <geometry>
        <mesh
          filename="package://tripod6/meshes/lsec02.STL" />
      </geometry>
      <material
        name="">
        <color
          rgba="0.792156862745098 0.819607843137255 0.933333333333333 1" />
      </material>
    </visual>
    <collision>
      <origin
        xyz="0 0 0"
        rpy="0 0 0" />
      <geometry>
        <mesh
          filename="package://tripod6/meshes/lsec02.STL" />
      </geometry>
    </collision>
  </link>
  <joint
    name="low02"
    type="revolute">
    <origin
      xyz="0.153312406197674 -0.10655 -0.223737141910982"
      rpy="0 0 0" />
    <parent
      link="hsec02" />
    <child
      link="lsec02" />
    <axis
      xyz="0 -1 0" />
    <limit
      lower="-1.571"
      upper="1.571"
      effort="100000"
      velocity="10000" />
  </joint>
  <link
    name="sec03">
    <inertial>
      <origin
        xyz="0.00048653 0.015897 0.00070173"
        rpy="0 0 0" />
      <mass
        value="0.69712" />
      <inertia
        ixx="0.0011428"
        ixy="-8.993E-05"
        ixz="-4.5622E-06"
        iyy="0.0011934"
        iyz="1.1001E-05"
        izz="0.00095538" />
    </inertial>
    <visual>
      <origin
        xyz="0 0 0"
        rpy="0 0 0" />
      <geometry>
        <mesh
          filename="package://tripod6/meshes/sec03.STL" />
      </geometry>
      <material
        name="">
        <color
          rgba="0.79216 0.81961 0.93333 1" />
      </material>
    </visual>
    <collision>
      <origin
        xyz="0 0 0"
        rpy="0 0 0" />
      <geometry>
        <mesh
          filename="package://tripod6/meshes/sec03.STL" />
      </geometry>
    </collision>
  </link>
  <joint
    name="leg03"
    type="revolute">
    <origin
      xyz="-0.19118 0.12753 0.029643"
      rpy="0 0 2.618" />
    <parent
      link="base_link" />
    <child
      link="sec03" />
    <axis
      xyz="1 0 0" />
    <limit
      lower="-1.571"
      upper="1.571"
      effort="100000"
      velocity="10000" />
  </joint>
  <link
    name="hsec03">
    <inertial>
      <origin
        xyz="0.033218 -0.085802 -0.049531"
        rpy="0 0 0" />
      <mass
        value="2.5939" />
      <inertia
        ixx="0.0085815"
        ixy="-1.0345E-07"
        ixz="0.0045728"
        iyy="0.013281"
        iyz="7.1198E-06"
        izz="0.0050192" />
    </inertial>
    <visual>
      <origin
        xyz="0 0 0"
        rpy="0 0 0" />
      <geometry>
        <mesh
          filename="package://tripod6/meshes/hsec03.STL" />
      </geometry>
      <material
        name="">
        <color
          rgba="0.79216 0.81961 0.93333 1" />
      </material>
    </visual>
    <collision>
      <origin
        xyz="0 0 0"
        rpy="0 0 0" />
      <geometry>
        <mesh
          filename="package://tripod6/meshes/hsec03.STL" />
      </geometry>
    </collision>
  </link>
  <joint
    name="high03"
    type="revolute">
    <origin
      xyz="0.078806 0.089405 0.0041238"
      rpy="0.046092 0 0" />
    <parent
      link="sec03" />
    <child
      link="hsec03" />
    <axis
      xyz="0 -1 0" />
    <limit
      lower="-1.571"
      upper="1.571"
      effort="100000"
      velocity="10000" />
  </joint>
  <link
    name="lsec03">
    <inertial>
      <origin
        xyz="-0.0014205 -0.0074116 -0.053388"
        rpy="0 0 0" />
      <mass
        value="0.29202" />
      <inertia
        ixx="0.00061533"
        ixy="-7.2533E-10"
        ixz="-1.4075E-05"
        iyy="0.0006811"
        iyz="-1.0164E-10"
        izz="8.6637E-05" />
    </inertial>
    <visual>
      <origin
        xyz="0 0 0"
        rpy="0 0 0" />
      <geometry>
        <mesh
          filename="package://tripod6/meshes/lsec03.STL" />
      </geometry>
      <material
        name="">
        <color
          rgba="0.89804 0.91765 0.92941 1" />
      </material>
    </visual>
    <collision>
      <origin
        xyz="0 0 0"
        rpy="0 0 0" />
      <geometry>
        <mesh
          filename="package://tripod6/meshes/lsec03.STL" />
      </geometry>
    </collision>
  </link>
  <joint
    name="low03"
    type="revolute">
    <origin
      xyz="0.15182 -0.10655 -0.22476"
      rpy="0 0 0" />
    <parent
      link="hsec03" />
    <child
      link="lsec03" />
    <axis
      xyz="0 -1 0" />
    <limit
      lower="-1.571"
      upper="1.571"
      effort="100000"
      velocity="10000" />
  </joint>

  <!--transmission definition -->
<transmission name="tran01">
    <type>transmission_interface/SimpleTransmission</type>
    <joint name="leg01">
      <hardwareInterface>hardware_interface/EffortJointInterface</hardwareInterface>
    </joint>
    <actuator name="motor01">
      <hardwareInterface>hardware_interface/EffortJointInterface</hardwareInterface>
      <mechanicalReduction>1</mechanicalReduction>
    </actuator>
  </transmission>
  
  <transmission name="tran02">
    <type>transmission_interface/SimpleTransmission</type>
    <joint name="high01">
      <hardwareInterface>hardware_interface/EffortJointInterface</hardwareInterface>
    </joint>
    <actuator name="motor02">
      <hardwareInterface>hardware_interface/EffortJointInterface</hardwareInterface>
      <mechanicalReduction>1</mechanicalReduction>
    </actuator>
  </transmission>
  
  <transmission name="tran03">
    <type>transmission_interface/SimpleTransmission</type>
    <joint name="low01">
      <hardwareInterface>hardware_interface/EffortJointInterface</hardwareInterface>
    </joint>
    <actuator name="motor03">
      <hardwareInterface>hardware_interface/EffortJointInterface</hardwareInterface>
      <mechanicalReduction>1</mechanicalReduction>
    </actuator>
  </transmission>
  
  <transmission name="tran04">
    <type>transmission_interface/SimpleTransmission</type>
    <joint name="leg02">
      <hardwareInterface>hardware_interface/EffortJointInterface</hardwareInterface>
    </joint>
    <actuator name="motor04">
      <hardwareInterface>hardware_interface/EffortJointInterface</hardwareInterface>
      <mechanicalReduction>1</mechanicalReduction>
    </actuator>
  </transmission>
  
  <transmission name="tran05">
    <type>transmission_interface/SimpleTransmission</type>
    <joint name="high02">
      <hardwareInterface>hardware_interface/EffortJointInterface</hardwareInterface>
    </joint>
    <actuator name="motor05">
      <hardwareInterface>hardware_interface/EffortJointInterface</hardwareInterface>
      <mechanicalReduction>1</mechanicalReduction>
    </actuator>
  </transmission>
  
  <transmission name="tran06">
    <type>transmission_interface/SimpleTransmission</type>
    <joint name="low02">
      <hardwareInterface>hardware_interface/EffortJointInterface</hardwareInterface>
    </joint>
    <actuator name="motor06">
      <hardwareInterface>hardware_interface/EffortJointInterface</hardwareInterface>
      <mechanicalReduction>1</mechanicalReduction>
    </actuator>
  </transmission>
  
  <transmission name="tran07">
    <type>transmission_interface/SimpleTransmission</type>
    <joint name="leg03">
      <hardwareInterface>hardware_interface/EffortJointInterface</hardwareInterface>
    </joint>
    <actuator name="motor07">
      <hardwareInterface>hardware_interface/EffortJointInterface</hardwareInterface>
      <mechanicalReduction>1</mechanicalReduction>
    </actuator>
  </transmission>
  
  <transmission name="tran08">
    <type>transmission_interface/SimpleTransmission</type>
    <joint name="high03">
      <hardwareInterface>hardware_interface/EffortJointInterface</hardwareInterface>
    </joint>
    <actuator name="motor08">
      <hardwareInterface>hardware_interface/EffortJointInterface</hardwareInterface>
      <mechanicalReduction>1</mechanicalReduction>
    </actuator>
  </transmission>
  
  <transmission name="tran09">
    <type>transmission_interface/SimpleTransmission</type>
    <joint name="low03">
      <hardwareInterface>hardware_interface/EffortJointInterface</hardwareInterface>
    </joint>
    <actuator name="motor09">
      <hardwareInterface>hardware_interface/EffortJointInterface</hardwareInterface>
      <mechanicalReduction>1</mechanicalReduction>
    </actuator>
  </transmission>
  
      <!--cointrol pluging -->
  <gazebo>
  <plugin name="gazebo_ros_control" filename="libgazebo_ros_control.so">

  </plugin>
</gazebo>

<!--
<gazebo reference="sec01">
   <turnGravityOff>true</turnGravityOff>
</gazebo>

<gazebo reference="sec02">
   <turnGravityOff>true</turnGravityOff>
</gazebo>

<gazebo reference="sec03">
   <turnGravityOff>true</turnGravityOff>
</gazebo>

<gazebo reference="sec04">
   <turnGravityOff>true</turnGravityOff>
</gazebo>

<gazebo reference="sec05">
   <turnGravityOff>true</turnGravityOff>
</gazebo>

<gazebo reference="sec06">
   <turnGravityOff>true</turnGravityOff>
</gazebo>

<gazebo reference="sec07">
   <turnGravityOff>true</turnGravityOff>
</gazebo>

<gazebo reference="sec08">
   <turnGravityOff>true</turnGravityOff>
</gazebo>

<gazebo reference="sec09">
   <turnGravityOff>true</turnGravityOff>
</gazebo>

<gazebo reference="sec10">
   <turnGravityOff>true</turnGravityOff>
</gazebo>

<gazebo reference="sec11">
   <turnGravityOff>true</turnGravityOff>
</gazebo>

-->
</robot>